{
    "registryname": "Atomic_resetter",
	"localizedname": "§6[ARS] §d原子重构机",
    "requires-blueprint": false,
    "parts": [
        {
            "x": 2,
            "y": 2,
            "z": 1,
            "elements": [
                "botania:quartztypemana@2"
            ]
        },
        {
            "x": 4,
            "y": 4,
            "z": 2,
            "elements": [
                "ic2:resource@13"
            ]
        },
        {
            "x": -10,
            "y": 4,
            "z": 18,
            "elements": [
                "nuclearcraft:tritium_lamp@0"
            ]
        },
        {
            "x": -5,
            "y": 0,
            "z": 0,
            "elements": [
                "modularmachinery:blockoutputbus@6"
            ]
        },
        {
            "x": -11,
            "y": 0,
            "z": 16,
            "elements": [
                "botania:storage@2"
            ]
        },
        {
            "x": 5,
            "y": 4,
            "z": 18,
            "elements": [
                "nuclearcraft:tritium_lamp@0"
            ]
        },
        {
            "x": -9,
            "y": 5,
            "z": 2,
            "elements": [
                "tconstruct:metal@0"
            ]
        },
        {
            "x": -8,
            "y": 3,
            "z": 1,
            "elements": [
                "mekanism:reinforcedplasticblock@15"
            ]
        },
        {
            "x": 6,
            "y": 0,
            "z": 16,
            "elements": [
                "botania:storage@2"
            ]
        },
        {
            "x": -7,
            "y": 3,
            "z": 1,
            "elements": [
                "appliedenergistics2:quartz_pillar@1"
            ]
        },
        {
            "x": -6,
            "y": 3,
            "z": 1,
            "elements": [
                "mekanism:reinforcedplasticblock@15"
            ]
        },
        {
            "x": -5,
            "y": 3,
            "z": 1,
            "elements": [
                "thermalfoundation:storage_alloy@7"
            ]
        },
        {
            "x": -5,
            "y": 1,
            "z": 0,
            "elements": [
                "modularmachinery:blockfluidoutputhatch@7"
            ]
        },
        {
            "x": 0,
            "y": 3,
            "z": 1,
            "elements": [
                "thermalfoundation:storage_alloy@7"
            ]
        },
        {
            "x": 1,
            "y": 3,
            "z": 1,
            "elements": [
                "mekanism:reinforcedplasticblock@15"
            ]
        },
        {
            "x": 0,
            "y": 1,
            "z": 0,
            "elements": [
                "modularmachinery:blockinputbus@6"
            ]
        },
        {
            "x": 2,
            "y": 3,
            "z": 1,
            "elements": [
                "botania:quartztypemana@2"
            ]
        },
        {
            "x": 4,
            "y": 5,
            "z": 2,
            "elements": [
                "tconstruct:metal@0"
            ]
        },
        {
            "x": 3,
            "y": 3,
            "z": 1,
            "elements": [
                "mekanism:reinforcedplasticblock@15"
            ]
        },
        {
            "x": -11,
            "y": 3,
            "z": 17,
            "elements": [
                "mekanism:reinforcedplasticblock@15"
            ]
        },
        {
            "x": -10,
            "y": 5,
            "z": 18,
            "elements": [
                "tconstruct:metal@0"
            ]
        },
        {
            "x": -5,
            "y": 3,
            "z": 17,
            "elements": [
                "botania:storage@1"
            ]
        },
        {
            "x": 0,
            "y": 3,
            "z": 17,
            "elements": [
                "botania:storage@1"
            ]
        },
        {
            "x": 5,
            "y": 5,
            "z": 18,
            "elements": [
                "tconstruct:metal@0"
            ]
        },
        {
            "x": 6,
            "y": 3,
            "z": 17,
            "elements": [
                "mekanism:reinforcedplasticblock@15"
            ]
        },
        {
            "x": -8,
            "y": 4,
            "z": 1,
            "elements": [
                "ic2:resource@13"
            ]
        },
        {
            "x": -7,
            "y": 4,
            "z": 1,
            "elements": [
                "nuclearcraft:tritium_lamp@0"
            ]
        },
        {
            "x": -6,
            "y": 4,
            "z": 1,
            "elements": [
                "ic2:resource@13"
            ]
        },
        {
            "x": -5,
            "y": 2,
            "z": 0,
            "elements": [
                "enderio:block_alloy_endergy@3"
            ]
        },
        {
            "x": 1,
            "y": 4,
            "z": 1,
            "elements": [
                "ic2:resource@13"
            ]
        },
        {
            "x": 0,
            "y": 2,
            "z": 0,
            "elements": [
                "modularmachinery:blockenergyinputhatch@7"
            ]
        },
        {
            "x": 2,
            "y": 4,
            "z": 1,
            "elements": [
                "nuclearcraft:tritium_lamp@0"
            ]
        },
        {
            "x": 3,
            "y": 4,
            "z": 1,
            "elements": [
                "ic2:resource@13"
            ]
        },
        {
            "x": -11,
            "y": 4,
            "z": 17,
            "elements": [
                "ic2:resource@13"
            ]
        },
        {
            "x": -12,
            "y": 0,
            "z": 15,
            "elements": [
                "botania:storage@2"
            ]
        },
        {
            "x": 6,
            "y": 4,
            "z": 17,
            "elements": [
                "ic2:resource@13"
            ]
        },
        {
            "x": -8,
            "y": 5,
            "z": 1,
            "elements": [
                "tconstruct:metal@0"
            ]
        },
        {
            "x": -7,
            "y": 5,
            "z": 1,
            "elements": [
                "tconstruct:metal@0"
            ]
        },
        {
            "x": -6,
            "y": 5,
            "z": 1,
            "elements": [
                "tconstruct:metal@0"
            ]
        },
        {
            "x": 7,
            "y": 0,
            "z": 15,
            "elements": [
                "botania:storage@2"
            ]
        },
        {
            "x": -5,
            "y": 3,
            "z": 0,
            "elements": [
                "enderio:block_alloy_endergy@3"
            ]
        },
        {
            "x": 1,
            "y": 5,
            "z": 1,
            "elements": [
                "tconstruct:metal@0"
            ]
        },
        {
            "x": 0,
            "y": 3,
            "z": 0,
            "elements": [
                "modularmachinery:blockfluidinputhatch@7"
            ]
        },
        {
            "x": 2,
            "y": 5,
            "z": 1,
            "elements": [
                "tconstruct:metal@0"
            ]
        },
        {
            "x": 3,
            "y": 5,
            "z": 1,
            "elements": [
                "tconstruct:metal@0"
            ]
        },
        {
            "x": -12,
            "y": 3,
            "z": 16,
            "elements": [
                "mekanism:reinforcedplasticblock@15"
            ]
        },
        {
            "x": -11,
            "y": 5,
            "z": 17,
            "elements": [
                "tconstruct:metal@0"
            ]
        },
        {
            "x": -12,
            "y": 1,
            "z": 15,
            "elements": [
                "appliedenergistics2:quartz_pillar@1"
            ]
        },
        {
            "x": -5,
            "y": 3,
            "z": 16,
            "elements": [
                "botania:storage@1"
            ]
        },
        {
            "x": 0,
            "y": 3,
            "z": 16,
            "elements": [
                "botania:storage@1"
            ]
        },
        {
            "x": 6,
            "y": 5,
            "z": 17,
            "elements": [
                "tconstruct:metal@0"
            ]
        },
        {
            "x": 7,
            "y": 3,
            "z": 16,
            "elements": [
                "mekanism:reinforcedplasticblock@15"
            ]
        },
        {
            "x": 7,
            "y": 1,
            "z": 15,
            "elements": [
                "botania:quartztypemana@2"
            ]
        },
        {
            "x": -5,
            "y": 4,
            "z": 0,
            "elements": [
                "ic2:resource@13"
            ]
        },
        {
            "x": -4,
            "y": 4,
            "z": 0,
            "elements": [
                "nuclearcraft:tritium_lamp@0"
            ]
        },
        {
            "x": -3,
            "y": 4,
            "z": 0,
            "elements": [
                "ic2:resource@13"
            ]
        },
        {
            "x": -2,
            "y": 4,
            "z": 0,
            "elements": [
                "ic2:resource@13"
            ]
        },
        {
            "x": -1,
            "y": 4,
            "z": 0,
            "elements": [
                "nuclearcraft:tritium_lamp@0"
            ]
        },
        {
            "x": 0,
            "y": 4,
            "z": 0,
            "elements": [
                "ic2:resource@13"
            ]
        },
        {
            "x": -12,
            "y": 4,
            "z": 16,
            "elements": [
                "ic2:resource@13"
            ]
        },
        {
            "x": -12,
            "y": 2,
            "z": 15,
            "elements": [
                "appliedenergistics2:quartz_pillar@1"
            ]
        },
        {
            "x": -12,
            "y": 0,
            "z": 14,
            "elements": [
                "botania:storage@2"
            ]
        },
        {
            "x": 7,
            "y": 4,
            "z": 16,
            "elements": [
                "ic2:resource@13"
            ]
        },
        {
            "x": 7,
            "y": 2,
            "z": 15,
            "elements": [
                "botania:quartztypemana@2"
            ]
        },
        {
            "x": 7,
            "y": 0,
            "z": 14,
            "elements": [
                "botania:storage@2"
            ]
        },
        {
            "x": -5,
            "y": 5,
            "z": 0,
            "elements": [
                "tconstruct:metal@0"
            ]
        },
        {
            "x": -4,
            "y": 5,
            "z": 0,
            "elements": [
                "tconstruct:metal@0"
            ]
        },
        {
            "x": -3,
            "y": 5,
            "z": 0,
            "elements": [
                "tconstruct:metal@0"
            ]
        },
        {
            "x": -2,
            "y": 5,
            "z": 0,
            "elements": [
                "tconstruct:metal@0"
            ]
        },
        {
            "x": -1,
            "y": 5,
            "z": 0,
            "elements": [
                "tconstruct:metal@0"
            ]
        },
        {
            "x": 0,
            "y": 5,
            "z": 0,
            "elements": [
                "tconstruct:metal@0"
            ]
        },
        {
            "x": -12,
            "y": 5,
            "z": 16,
            "elements": [
                "tconstruct:metal@0"
            ]
        },
        {
            "x": -12,
            "y": 3,
            "z": 15,
            "elements": [
                "appliedenergistics2:quartz_pillar@1"
            ]
        },
        {
            "x": -5,
            "y": 3,
            "z": 15,
            "elements": [
                "botania:storage@1"
            ]
        },
        {
            "x": 0,
            "y": 3,
            "z": 15,
            "elements": [
                "botania:storage@1"
            ]
        },
        {
            "x": 7,
            "y": 5,
            "z": 16,
            "elements": [
                "tconstruct:metal@0"
            ]
        },
        {
            "x": 7,
            "y": 3,
            "z": 15,
            "elements": [
                "botania:quartztypemana@2"
            ]
        },
        {
            "x": -12,
            "y": 4,
            "z": 15,
            "elements": [
                "nuclearcraft:tritium_lamp@0"
            ]
        },
        {
            "x": -12,
            "y": 0,
            "z": 13,
            "elements": [
                "botania:storage@2"
            ]
        },
        {
            "x": -5,
            "y": 0,
            "z": 13,
            "elements": [
                "thermalfoundation:storage@7"
            ]
        },
        {
            "x": 0,
            "y": 0,
            "z": 13,
            "elements": [
                "thermalfoundation:storage@7"
            ]
        },
        {
            "x": 7,
            "y": 4,
            "z": 15,
            "elements": [
                "nuclearcraft:tritium_lamp@0"
            ]
        },
        {
            "x": 7,
            "y": 0,
            "z": 13,
            "elements": [
                "botania:storage@2"
            ]
        },
        {
            "x": -12,
            "y": 5,
            "z": 15,
            "elements": [
                "tconstruct:metal@0"
            ]
        },
        {
            "x": -12,
            "y": 3,
            "z": 14,
            "elements": [
                "mekanism:reinforcedplasticblock@15"
            ]
        },
        {
            "x": -5,
            "y": 3,
            "z": 14,
            "elements": [
                "botania:storage@1"
            ]
        },
        {
            "x": -5,
            "y": 1,
            "z": 13,
            "elements": [
                "nuclearcraft:tritium_lamp@0"
            ]
        },
        {
            "x": 0,
            "y": 3,
            "z": 14,
            "elements": [
                "botania:storage@1"
            ]
        },
        {
            "x": 0,
            "y": 1,
            "z": 13,
            "elements": [
                "nuclearcraft:tritium_lamp@0"
            ]
        },
        {
            "x": 7,
            "y": 5,
            "z": 15,
            "elements": [
                "tconstruct:metal@0"
            ]
        },
        {
            "x": 7,
            "y": 3,
            "z": 14,
            "elements": [
                "mekanism:reinforcedplasticblock@15"
            ]
        },
        {
            "x": -12,
            "y": 4,
            "z": 14,
            "elements": [
                "ic2:resource@13"
            ]
        },
        {
            "x": -13,
            "y": 0,
            "z": 12,
            "elements": [
                "botania:storage@2"
            ]
        },
        {
            "x": -5,
            "y": 2,
            "z": 13,
            "elements": [
                "thermalfoundation:storage@7"
            ]
        },
        {
            "x": 0,
            "y": 2,
            "z": 13,
            "elements": [
                "thermalfoundation:storage@7"
            ]
        },
        {
            "x": 7,
            "y": 4,
            "z": 14,
            "elements": [
                "ic2:resource@13"
            ]
        },
        {
            "x": 8,
            "y": 0,
            "z": 12,
            "elements": [
                "botania:storage@2"
            ]
        },
        {
            "x": -13,
            "y": 3,
            "z": 13,
            "elements": [
                "mekanism:reinforcedplasticblock@15"
            ]
        },
        {
            "x": -12,
            "y": 5,
            "z": 14,
            "elements": [
                "tconstruct:metal@0"
            ]
        },
        {
            "x": -13,
            "y": 1,
            "z": 12,
            "elements": [
                "appliedenergistics2:quartz_pillar@1"
            ]
        },
        {
            "x": -12,
            "y": 3,
            "z": 13,
            "elements": [
                "enderio:block_alloy_endergy@3"
            ]
        },
        {
            "x": -11,
            "y": 3,
            "z": 13,
            "elements": [
                "enderio:block_alloy_endergy@3"
            ]
        },
        {
            "x": -10,
            "y": 3,
            "z": 13,
            "elements": [
                "enderio:block_alloy_endergy@3"
            ]
        },
        {
            "x": -9,
            "y": 3,
            "z": 13,
            "elements": [
                "enderio:block_alloy_endergy@3"
            ]
        },
        {
            "x": -8,
            "y": 3,
            "z": 13,
            "elements": [
                "enderio:block_alloy_endergy@3"
            ]
        },
        {
            "x": -7,
            "y": 3,
            "z": 13,
            "elements": [
                "enderio:block_alloy_endergy@3"
            ]
        },
        {
            "x": -6,
            "y": 3,
            "z": 13,
            "elements": [
                "enderio:block_alloy_endergy@3"
            ]
        },
        {
            "x": -5,
            "y": 3,
            "z": 13,
            "elements": [
                "avaritia:block_resource@0"
            ]
        },
        {
            "x": 0,
            "y": 3,
            "z": 13,
            "elements": [
                "avaritia:block_resource@0"
            ]
        },
        {
            "x": 1,
            "y": 3,
            "z": 13,
            "elements": [
                "botania:storage@0"
            ]
        },
        {
            "x": 2,
            "y": 3,
            "z": 13,
            "elements": [
                "botania:storage@0"
            ]
        },
        {
            "x": 3,
            "y": 3,
            "z": 13,
            "elements": [
                "botania:storage@0"
            ]
        },
        {
            "x": 4,
            "y": 3,
            "z": 13,
            "elements": [
                "botania:storage@0"
            ]
        },
        {
            "x": 5,
            "y": 3,
            "z": 13,
            "elements": [
                "botania:storage@0"
            ]
        },
        {
            "x": 7,
            "y": 5,
            "z": 14,
            "elements": [
                "tconstruct:metal@0"
            ]
        },
        {
            "x": 6,
            "y": 3,
            "z": 13,
            "elements": [
                "botania:storage@0"
            ]
        },
        {
            "x": 7,
            "y": 3,
            "z": 13,
            "elements": [
                "botania:storage@0"
            ]
        },
        {
            "x": 8,
            "y": 3,
            "z": 13,
            "elements": [
                "mekanism:reinforcedplasticblock@15"
            ]
        },
        {
            "x": 8,
            "y": 1,
            "z": 12,
            "elements": [
                "botania:quartztypemana@2"
            ]
        },
        {
            "x": -13,
            "y": 4,
            "z": 13,
            "elements": [
                "ic2:resource@13"
            ]
        },
        {
            "x": -13,
            "y": 2,
            "z": 12,
            "elements": [
                "appliedenergistics2:quartz_pillar@1"
            ]
        },
        {
            "x": -13,
            "y": 0,
            "z": 11,
            "elements": [
                "botania:storage@2"
            ]
        },
        {
            "x": -5,
            "y": 4,
            "z": 13,
            "elements": [
                "thermalfoundation:storage@7"
            ]
        },
        {
            "x": -3,
            "y": 2,
            "z": 12,
            "elements": [
                "botania:bifrostperm@0"
            ]
        },
        {
            "x": -2,
            "y": 2,
            "z": 12,
            "elements": [
                "botania:bifrostperm@0"
            ]
        },
        {
            "x": 0,
            "y": 4,
            "z": 13,
            "elements": [
                "thermalfoundation:storage@7"
            ]
        },
        {
            "x": 8,
            "y": 4,
            "z": 13,
            "elements": [
                "ic2:resource@13"
            ]
        },
        {
            "x": 8,
            "y": 2,
            "z": 12,
            "elements": [
                "botania:quartztypemana@2"
            ]
        },
        {
            "x": 8,
            "y": 0,
            "z": 11,
            "elements": [
                "botania:storage@2"
            ]
        },
        {
            "x": -13,
            "y": 5,
            "z": 13,
            "elements": [
                "tconstruct:metal@0"
            ]
        },
        {
            "x": -13,
            "y": 3,
            "z": 12,
            "elements": [
                "appliedenergistics2:quartz_pillar@1"
            ]
        },
        {
            "x": -5,
            "y": 5,
            "z": 13,
            "elements": [
                "nuclearcraft:tritium_lamp@0"
            ]
        },
        {
            "x": -3,
            "y": 3,
            "z": 12,
            "elements": [
                "botania:bifrostperm@0"
            ]
        },
        {
            "x": -3,
            "y": 1,
            "z": 11,
            "elements": [
                "avaritia:block_resource@2"
            ]
        },
        {
            "x": -2,
            "y": 3,
            "z": 12,
            "elements": [
                "botania:bifrostperm@0"
            ]
        },
        {
            "x": 0,
            "y": 5,
            "z": 13,
            "elements": [
                "nuclearcraft:tritium_lamp@0"
            ]
        },
        {
            "x": -2,
            "y": 1,
            "z": 11,
            "elements": [
                "avaritia:block_resource@2"
            ]
        },
        {
            "x": 8,
            "y": 5,
            "z": 13,
            "elements": [
                "tconstruct:metal@0"
            ]
        },
        {
            "x": 8,
            "y": 3,
            "z": 12,
            "elements": [
                "botania:quartztypemana@2"
            ]
        },
        {
            "x": -13,
            "y": 4,
            "z": 12,
            "elements": [
                "nuclearcraft:tritium_lamp@0"
            ]
        },
        {
            "x": -13,
            "y": 0,
            "z": 10,
            "elements": [
                "botania:storage@2"
            ]
        },
        {
            "x": -5,
            "y": 6,
            "z": 13,
            "elements": [
                "thermalfoundation:storage@7"
            ]
        },
        {
            "x": -4,
            "y": 2,
            "z": 11,
            "elements": [
                "botania:bifrostperm@0"
            ]
        },
        {
            "x": -3,
            "y": 4,
            "z": 12,
            "elements": [
                "botania:bifrostperm@0"
            ]
        },
        {
            "x": -3,
            "y": 2,
            "z": 11,
            "elements": [
                "draconicevolution:draconic_block@0"
            ]
        },
        {
            "x": -2,
            "y": 4,
            "z": 12,
            "elements": [
                "botania:bifrostperm@0"
            ]
        },
        {
            "x": 0,
            "y": 6,
            "z": 13,
            "elements": [
                "thermalfoundation:storage@7"
            ]
        },
        {
            "x": -2,
            "y": 2,
            "z": 11,
            "elements": [
                "draconicevolution:draconic_block@0"
            ]
        },
        {
            "x": -1,
            "y": 2,
            "z": 11,
            "elements": [
                "botania:bifrostperm@0"
            ]
        },
        {
            "x": 8,
            "y": 4,
            "z": 12,
            "elements": [
                "nuclearcraft:tritium_lamp@0"
            ]
        },
        {
            "x": 8,
            "y": 0,
            "z": 10,
            "elements": [
                "botania:storage@2"
            ]
        },
        {
            "x": -13,
            "y": 5,
            "z": 12,
            "elements": [
                "tconstruct:metal@0"
            ]
        },
        {
            "x": -13,
            "y": 3,
            "z": 11,
            "elements": [
                "mekanism:reinforcedplasticblock@15"
            ]
        },
        {
            "x": [-5,-4,-3,-2,-1,0],
            "y": 7,
            "z": [13,12,11,10,9,8],
            "elements": [
                "thermalfoundation:glass@6"
            ]
        },
        {
            "x": -4,
            "y": 3,
            "z": 11,
            "elements": [
                "botania:bifrostperm@0"
            ]
        },
        {
            "x": -3,
            "y": 3,
            "z": 11,
            "elements": [
                "extrabotany:blockorichalcos@0"
            ]
        },
        {
            "x": -3,
            "y": 1,
            "z": 10,
            "elements": [
                "avaritia:block_resource@2"
            ]
        },
        {
            "x": -2,
            "y": 3,
            "z": 11,
            "elements": [
                "extrabotany:blockorichalcos@0"
            ]
        },
        {
            "x": -2,
            "y": 1,
            "z": 10,
            "elements": [
                "avaritia:block_resource@2"
            ]
        },
        {
            "x": -1,
            "y": 3,
            "z": 11,
            "elements": [
                "botania:bifrostperm@0"
            ]
        },
        {
            "x": 8,
            "y": 5,
            "z": 12,
            "elements": [
                "tconstruct:metal@0"
            ]
        },
        {
            "x": 8,
            "y": 3,
            "z": 11,
            "elements": [
                "mekanism:reinforcedplasticblock@15"
            ]
        },
        {
            "x": -13,
            "y": 4,
            "z": 11,
            "elements": [
                "ic2:resource@13"
            ]
        },
        {
            "x": -13,
            "y": 0,
            "z": 9,
            "elements": [
                "botania:storage@2"
            ]
        },
        {
            "x": -4,
            "y": 4,
            "z": 11,
            "elements": [
                "botania:bifrostperm@0"
            ]
        },
        {
            "x": -4,
            "y": 2,
            "z": 10,
            "elements": [
                "botania:bifrostperm@0"
            ]
        },
        {
            "x": -3,
            "y": 4,
            "z": 11,
            "elements": [
                "draconicevolution:draconic_block@0"
            ]
        },
        {
            "x": -3,
            "y": 2,
            "z": 10,
            "elements": [
                "draconicevolution:draconic_block@0"
            ]
        },
        {
            "x": -2,
            "y": 4,
            "z": 11,
            "elements": [
                "draconicevolution:draconic_block@0"
            ]
        },
        {
            "x": -2,
            "y": 2,
            "z": 10,
            "elements": [
                "draconicevolution:draconic_block@0"
            ]
        },
        {
            "x": -1,
            "y": 4,
            "z": 11,
            "elements": [
                "botania:bifrostperm@0"
            ]
        },
        {
            "x": -1,
            "y": 2,
            "z": 10,
            "elements": [
                "botania:bifrostperm@0"
            ]
        },
        {
            "x": 8,
            "y": 4,
            "z": 11,
            "elements": [
                "ic2:resource@13"
            ]
        },
        {
            "x": 8,
            "y": 0,
            "z": 9,
            "elements": [
                "botania:storage@2"
            ]
        },
        {
            "x": -13,
            "y": 5,
            "z": 11,
            "elements": [
                "tconstruct:metal@0"
            ]
        },
        {
            "x": -13,
            "y": 3,
            "z": 10,
            "elements": [
                "mekanism:reinforcedplasticblock@15"
            ]
        },
        {
            "x": -13,
            "y": 1,
            "z": 9,
            "elements": [
                "appliedenergistics2:quartz_pillar@1"
            ]
        },
        {
            "x": -4,
            "y": 3,
            "z": 10,
            "elements": [
                "botania:bifrostperm@0"
            ]
        },
        {
            "x": -3,
            "y": 5,
            "z": 11,
            "elements": [
                "avaritia:block_resource@2"
            ]
        },
        {
            "x": -3,
            "y": 3,
            "z": 10,
            "elements": [
                "extrabotany:blockorichalcos@0"
            ]
        },
        {
            "x": -2,
            "y": 5,
            "z": 11,
            "elements": [
                "avaritia:block_resource@2"
            ]
        },
        {
            "x": -2,
            "y": 3,
            "z": 10,
            "elements": [
                "extrabotany:blockorichalcos@0"
            ]
        },
        {
            "x": -1,
            "y": 3,
            "z": 10,
            "elements": [
                "botania:bifrostperm@0"
            ]
        },
        {
            "x": 8,
            "y": 5,
            "z": 11,
            "elements": [
                "tconstruct:metal@0"
            ]
        },
        {
            "x": 8,
            "y": 3,
            "z": 10,
            "elements": [
                "mekanism:reinforcedplasticblock@15"
            ]
        },
        {
            "x": 8,
            "y": 1,
            "z": 9,
            "elements": [
                "botania:quartztypemana@2"
            ]
        },
        {
            "x": -13,
            "y": 4,
            "z": 10,
            "elements": [
                "ic2:resource@13"
            ]
        },
        {
            "x": -13,
            "y": 2,
            "z": 9,
            "elements": [
                "appliedenergistics2:quartz_pillar@1"
            ]
        },
        {
            "x": -12,
            "y": 0,
            "z": 8,
            "elements": [
                "botania:storage@2"
            ]
        },
        {
            "x": -4,
            "y": 4,
            "z": 10,
            "elements": [
                "botania:bifrostperm@0"
            ]
        },
        {
            "x": -5,
            "y": 0,
            "z": 8,
            "elements": [
                "thermalfoundation:storage@7"
            ]
        },
        {
            "x": -3,
            "y": 4,
            "z": 10,
            "elements": [
                "draconicevolution:draconic_block@0"
            ]
        },
        {
            "x": -3,
            "y": 2,
            "z": 9,
            "elements": [
                "botania:bifrostperm@0"
            ]
        },
        {
            "x": -2,
            "y": 4,
            "z": 10,
            "elements": [
                "draconicevolution:draconic_block@0"
            ]
        },
        {
            "x": -2,
            "y": 2,
            "z": 9,
            "elements": [
                "botania:bifrostperm@0"
            ]
        },
        {
            "x": -1,
            "y": 4,
            "z": 10,
            "elements": [
                "botania:bifrostperm@0"
            ]
        },
        {
            "x": 0,
            "y": 0,
            "z": 8,
            "elements": [
                "thermalfoundation:storage@7"
            ]
        },
        {
            "x": 8,
            "y": 4,
            "z": 10,
            "elements": [
                "ic2:resource@13"
            ]
        },
        {
            "x": 8,
            "y": 2,
            "z": 9,
            "elements": [
                "botania:quartztypemana@2"
            ]
        },
        {
            "x": 7,
            "y": 0,
            "z": 8,
            "elements": [
                "botania:storage@2"
            ]
        },
        {
            "x": -13,
            "y": 5,
            "z": 10,
            "elements": [
                "tconstruct:metal@0"
            ]
        },
        {
            "x": -13,
            "y": 3,
            "z": 9,
            "elements": [
                "appliedenergistics2:quartz_pillar@1"
            ]
        },
        {
            "x": -5,
            "y": 1,
            "z": 8,
            "elements": [
                "nuclearcraft:tritium_lamp@0"
            ]
        },
        {
            "x": -3,
            "y": 5,
            "z": 10,
            "elements": [
                "avaritia:block_resource@2"
            ]
        },
        {
            "x": -3,
            "y": 3,
            "z": 9,
            "elements": [
                "botania:bifrostperm@0"
            ]
        },
        {
            "x": -2,
            "y": 5,
            "z": 10,
            "elements": [
                "avaritia:block_resource@2"
            ]
        },
        {
            "x": -2,
            "y": 3,
            "z": 9,
            "elements": [
                "botania:bifrostperm@0"
            ]
        },
        {
            "x": 0,
            "y": 1,
            "z": 8,
            "elements": [
                "nuclearcraft:tritium_lamp@0"
            ]
        },
        {
            "x": 8,
            "y": 5,
            "z": 10,
            "elements": [
                "tconstruct:metal@0"
            ]
        },
        {
            "x": 8,
            "y": 3,
            "z": 9,
            "elements": [
                "botania:quartztypemana@2"
            ]
        },
        {
            "x": -13,
            "y": 4,
            "z": 9,
            "elements": [
                "nuclearcraft:tritium_lamp@0"
            ]
        },
        {
            "x": -12,
            "y": 0,
            "z": 7,
            "elements": [
                "botania:storage@2"
            ]
        },
        {
            "x": -5,
            "y": 2,
            "z": 8,
            "elements": [
                "thermalfoundation:storage@7"
            ]
        },
        {
            "x": -3,
            "y": 4,
            "z": 9,
            "elements": [
                "botania:bifrostperm@0"
            ]
        },
        {
            "x": -2,
            "y": 4,
            "z": 9,
            "elements": [
                "botania:bifrostperm@0"
            ]
        },
        {
            "x": 0,
            "y": 2,
            "z": 8,
            "elements": [
                "thermalfoundation:storage@7"
            ]
        },
        {
            "x": 8,
            "y": 4,
            "z": 9,
            "elements": [
                "nuclearcraft:tritium_lamp@0"
            ]
        },
        {
            "x": 7,
            "y": 0,
            "z": 7,
            "elements": [
                "botania:storage@2"
            ]
        },
        {
            "x": -13,
            "y": 5,
            "z": 9,
            "elements": [
                "tconstruct:metal@0"
            ]
        },
        {
            "x": -13,
            "y": 3,
            "z": 8,
            "elements": [
                "mekanism:reinforcedplasticblock@15"
            ]
        },
        {
            "x": -12,
            "y": 3,
            "z": 8,
            "elements": [
                "enderio:block_alloy_endergy@3"
            ]
        },
        {
            "x": -11,
            "y": 3,
            "z": 8,
            "elements": [
                "enderio:block_alloy_endergy@3"
            ]
        },
        {
            "x": -10,
            "y": 3,
            "z": 8,
            "elements": [
                "enderio:block_alloy_endergy@3"
            ]
        },
        {
            "x": -9,
            "y": 3,
            "z": 8,
            "elements": [
                "enderio:block_alloy_endergy@3"
            ]
        },
        {
            "x": -8,
            "y": 3,
            "z": 8,
            "elements": [
                "enderio:block_alloy_endergy@3"
            ]
        },
        {
            "x": -7,
            "y": 3,
            "z": 8,
            "elements": [
                "enderio:block_alloy_endergy@3"
            ]
        },
        {
            "x": -6,
            "y": 3,
            "z": 8,
            "elements": [
                "enderio:block_alloy_endergy@3"
            ]
        },
        {
            "x": -5,
            "y": 3,
            "z": 8,
            "elements": [
                "avaritia:block_resource@0"
            ]
        },
        {
            "x": 0,
            "y": 3,
            "z": 8,
            "elements": [
                "avaritia:block_resource@0"
            ]
        },
        {
            "x": 1,
            "y": 3,
            "z": 8,
            "elements": [
                "botania:storage@0"
            ]
        },
        {
            "x": 2,
            "y": 3,
            "z": 8,
            "elements": [
                "botania:storage@0"
            ]
        },
        {
            "x": 3,
            "y": 3,
            "z": 8,
            "elements": [
                "botania:storage@0"
            ]
        },
        {
            "x": 4,
            "y": 3,
            "z": 8,
            "elements": [
                "botania:storage@0"
            ]
        },
        {
            "x": 5,
            "y": 3,
            "z": 8,
            "elements": [
                "botania:storage@0"
            ]
        },
        {
            "x": 6,
            "y": 3,
            "z": 8,
            "elements": [
                "botania:storage@0"
            ]
        },
        {
            "x": 8,
            "y": 5,
            "z": 9,
            "elements": [
                "tconstruct:metal@0"
            ]
        },
        {
            "x": 7,
            "y": 3,
            "z": 8,
            "elements": [
                "botania:storage@0"
            ]
        },
        {
            "x": 8,
            "y": 3,
            "z": 8,
            "elements": [
                "mekanism:reinforcedplasticblock@15"
            ]
        },
        {
            "x": -13,
            "y": 4,
            "z": 8,
            "elements": [
                "ic2:resource@13"
            ]
        },
        {
            "x": -12,
            "y": 0,
            "z": 6,
            "elements": [
                "botania:storage@2"
            ]
        },
        {
            "x": -5,
            "y": 4,
            "z": 8,
            "elements": [
                "thermalfoundation:storage@7"
            ]
        },
        {
            "x": 0,
            "y": 4,
            "z": 8,
            "elements": [
                "thermalfoundation:storage@7"
            ]
        },
        {
            "x": 8,
            "y": 4,
            "z": 8,
            "elements": [
                "ic2:resource@13"
            ]
        },
        {
            "x": 7,
            "y": 0,
            "z": 6,
            "elements": [
                "botania:storage@2"
            ]
        },
        {
            "x": -13,
            "y": 5,
            "z": 8,
            "elements": [
                "tconstruct:metal@0"
            ]
        },
        {
            "x": -12,
            "y": 3,
            "z": 7,
            "elements": [
                "mekanism:reinforcedplasticblock@15"
            ]
        },
        {
            "x": -12,
            "y": 1,
            "z": 6,
            "elements": [
                "appliedenergistics2:quartz_pillar@1"
            ]
        },
        {
            "x": -5,
            "y": 5,
            "z": 8,
            "elements": [
                "nuclearcraft:tritium_lamp@0"
            ]
        },
        {
            "x": -5,
            "y": 3,
            "z": 7,
            "elements": [
                "thermalfoundation:storage_alloy@7"
            ]
        },
        {
            "x": 0,
            "y": 5,
            "z": 8,
            "elements": [
                "nuclearcraft:tritium_lamp@0"
            ]
        },
        {
            "x": 0,
            "y": 3,
            "z": 7,
            "elements": [
                "thermalfoundation:storage_alloy@7"
            ]
        },
        {
            "x": 8,
            "y": 5,
            "z": 8,
            "elements": [
                "tconstruct:metal@0"
            ]
        },
        {
            "x": 7,
            "y": 3,
            "z": 7,
            "elements": [
                "mekanism:reinforcedplasticblock@15"
            ]
        },
        {
            "x": 7,
            "y": 1,
            "z": 6,
            "elements": [
                "botania:quartztypemana@2"
            ]
        },
        {
            "x": -12,
            "y": 4,
            "z": 7,
            "elements": [
                "ic2:resource@13"
            ]
        },
        {
            "x": -12,
            "y": 2,
            "z": 6,
            "elements": [
                "appliedenergistics2:quartz_pillar@1"
            ]
        },
        {
            "x": -11,
            "y": 0,
            "z": 5,
            "elements": [
                "botania:storage@2"
            ]
        },
        {
            "x": -5,
            "y": 6,
            "z": 8,
            "elements": [
                "thermalfoundation:storage@7"
            ]
        },
        {
            "x": 0,
            "y": 6,
            "z": 8,
            "elements": [
                "thermalfoundation:storage@7"
            ]
        },
        {
            "x": 7,
            "y": 4,
            "z": 7,
            "elements": [
                "ic2:resource@13"
            ]
        },
        {
            "x": 7,
            "y": 2,
            "z": 6,
            "elements": [
                "botania:quartztypemana@2"
            ]
        },
        {
            "x": 6,
            "y": 0,
            "z": 5,
            "elements": [
                "botania:storage@2"
            ]
        },
        {
            "x": -4,
            "y": 0,
            "z": 21,
            "elements": [
                "botania:storage@2"
            ]
        },
        {
            "x": -3,
            "y": 0,
            "z": 21,
            "elements": [
                "botania:storage@2"
            ]
        },
        {
            "x": -2,
            "y": 0,
            "z": 21,
            "elements": [
                "botania:storage@2"
            ]
        },
        {
            "x": -1,
            "y": 0,
            "z": 21,
            "elements": [
                "botania:storage@2"
            ]
        },
        {
            "x": -12,
            "y": 5,
            "z": 7,
            "elements": [
                "tconstruct:metal@0"
            ]
        },
        {
            "x": -12,
            "y": 3,
            "z": 6,
            "elements": [
                "appliedenergistics2:quartz_pillar@1"
            ]
        },
        {
            "x": 0,
            "y": 3,
            "z": 6,
            "elements": [
                "thermalfoundation:storage_alloy@7"
            ]
        },
        {
            "x": 7,
            "y": 5,
            "z": 7,
            "elements": [
                "tconstruct:metal@0"
            ]
        },
        {
            "x": 7,
            "y": 3,
            "z": 6,
            "elements": [
                "botania:quartztypemana@2"
            ]
        },
        {
            "x": -4,
            "y": 1,
            "z": 21,
            "elements": [
                "appliedenergistics2:quartz_pillar@1"
            ]
        },
        {
            "x": -1,
            "y": 1,
            "z": 21,
            "elements": [
                "botania:quartztypemana@2"
            ]
        },
        {
            "x": -12,
            "y": 4,
            "z": 6,
            "elements": [
                "nuclearcraft:tritium_lamp@0"
            ]
        },
        {
            "x": -11,
            "y": 0,
            "z": 4,
            "elements": [
                "botania:storage@2"
            ]
        },
        {
            "x": 7,
            "y": 4,
            "z": 6,
            "elements": [
                "nuclearcraft:tritium_lamp@0"
            ]
        },
        {
            "x": 6,
            "y": 0,
            "z": 4,
            "elements": [
                "botania:storage@2"
            ]
        },
        {
            "x": -7,
            "y": 0,
            "z": 20,
            "elements": [
                "botania:storage@2"
            ]
        },
        {
            "x": -6,
            "y": 0,
            "z": 20,
            "elements": [
                "botania:storage@2"
            ]
        },
        {
            "x": -5,
            "y": 0,
            "z": 20,
            "elements": [
                "botania:storage@2"
            ]
        },
        {
            "x": -4,
            "y": 2,
            "z": 21,
            "elements": [
                "appliedenergistics2:quartz_pillar@1"
            ]
        },
        {
            "x": -1,
            "y": 2,
            "z": 21,
            "elements": [
                "botania:quartztypemana@2"
            ]
        },
        {
            "x": 0,
            "y": 0,
            "z": 20,
            "elements": [
                "botania:storage@2"
            ]
        },
        {
            "x": -12,
            "y": 5,
            "z": 6,
            "elements": [
                "tconstruct:metal@0"
            ]
        },
        {
            "x": 1,
            "y": 0,
            "z": 20,
            "elements": [
                "botania:storage@2"
            ]
        },
        {
            "x": -12,
            "y": 3,
            "z": 5,
            "elements": [
                "mekanism:reinforcedplasticblock@15"
            ]
        },
        {
            "x": 2,
            "y": 0,
            "z": 20,
            "elements": [
                "botania:storage@2"
            ]
        },
        {
            "x": -5,
            "y": 3,
            "z": 5,
            "elements": [
                "thermalfoundation:storage_alloy@7"
            ]
        },
        {
            "x": 0,
            "y": 3,
            "z": 5,
            "elements": [
                "thermalfoundation:storage_alloy@7"
            ]
        },
        {
            "x": 7,
            "y": 5,
            "z": 6,
            "elements": [
                "tconstruct:metal@0"
            ]
        },
        {
            "x": 7,
            "y": 3,
            "z": 5,
            "elements": [
                "mekanism:reinforcedplasticblock@15"
            ]
        },
        {
            "x": -7,
            "y": 1,
            "z": 20,
            "elements": [
                "appliedenergistics2:quartz_pillar@1"
            ]
        },
        {
            "x": -5,
            "y": 3,
            "z": 21,
            "elements": [
                "mekanism:reinforcedplasticblock@15"
            ]
        },
        {
            "x": -4,
            "y": 3,
            "z": 21,
            "elements": [
                "appliedenergistics2:quartz_pillar@1"
            ]
        },
        {
            "x": -3,
            "y": 3,
            "z": 21,
            "elements": [
                "mekanism:reinforcedplasticblock@15"
            ]
        },
        {
            "x": -2,
            "y": 3,
            "z": 21,
            "elements": [
                "mekanism:reinforcedplasticblock@15"
            ]
        },
        {
            "x": -1,
            "y": 3,
            "z": 21,
            "elements": [
                "botania:quartztypemana@2"
            ]
        },
        {
            "x": 0,
            "y": 3,
            "z": 21,
            "elements": [
                "mekanism:reinforcedplasticblock@15"
            ]
        },
        {
            "x": -12,
            "y": 4,
            "z": 5,
            "elements": [
                "ic2:resource@13"
            ]
        },
        {
            "x": 2,
            "y": 1,
            "z": 20,
            "elements": [
                "botania:quartztypemana@2"
            ]
        },
        {
            "x": -10,
            "y": 0,
            "z": 3,
            "elements": [
                "botania:storage@2"
            ]
        },
        {
            "x": 7,
            "y": 4,
            "z": 5,
            "elements": [
                "ic2:resource@13"
            ]
        },
        {
            "x": 5,
            "y": 0,
            "z": 3,
            "elements": [
                "botania:storage@2"
            ]
        },
        {
            "x": -9,
            "y": 0,
            "z": 19,
            "elements": [
                "botania:storage@2"
            ]
        },
        {
            "x": -8,
            "y": 0,
            "z": 19,
            "elements": [
                "botania:storage@2"
            ]
        },
        {
            "x": -7,
            "y": 2,
            "z": 20,
            "elements": [
                "appliedenergistics2:quartz_pillar@1"
            ]
        },
        {
            "x": -5,
            "y": 4,
            "z": 21,
            "elements": [
                "ic2:resource@13"
            ]
        },
        {
            "x": -4,
            "y": 4,
            "z": 21,
            "elements": [
                "nuclearcraft:tritium_lamp@0"
            ]
        },
        {
            "x": -3,
            "y": 4,
            "z": 21,
            "elements": [
                "ic2:resource@13"
            ]
        },
        {
            "x": -2,
            "y": 4,
            "z": 21,
            "elements": [
                "ic2:resource@13"
            ]
        },
        {
            "x": -1,
            "y": 4,
            "z": 21,
            "elements": [
                "nuclearcraft:tritium_lamp@0"
            ]
        },
        {
            "x": 0,
            "y": 4,
            "z": 21,
            "elements": [
                "ic2:resource@13"
            ]
        },
        {
            "x": -12,
            "y": 5,
            "z": 5,
            "elements": [
                "tconstruct:metal@0"
            ]
        },
        {
            "x": 2,
            "y": 2,
            "z": 20,
            "elements": [
                "botania:quartztypemana@2"
            ]
        },
        {
            "x": -11,
            "y": 3,
            "z": 4,
            "elements": [
                "mekanism:reinforcedplasticblock@15"
            ]
        },
        {
            "x": 3,
            "y": 0,
            "z": 19,
            "elements": [
                "botania:storage@2"
            ]
        },
        {
            "x": 4,
            "y": 0,
            "z": 19,
            "elements": [
                "botania:storage@2"
            ]
        },
        {
            "x": -5,
            "y": 3,
            "z": 4,
            "elements": [
                "thermalfoundation:storage_alloy@7"
            ]
        },
        {
            "x": 0,
            "y": 3,
            "z": 4,
            "elements": [
                "thermalfoundation:storage_alloy@7"
            ]
        },
        {
            "x": 7,
            "y": 5,
            "z": 5,
            "elements": [
                "tconstruct:metal@0"
            ]
        },
        {
            "x": 6,
            "y": 3,
            "z": 4,
            "elements": [
                "mekanism:reinforcedplasticblock@15"
            ]
        },
        {
            "x": 5,
            "y": 1,
            "z": 3,
            "elements": [
                "botania:quartztypemana@2"
            ]
        },
        {
            "x": -8,
            "y": 3,
            "z": 20,
            "elements": [
                "mekanism:reinforcedplasticblock@15"
            ]
        },
        {
            "x": -7,
            "y": 3,
            "z": 20,
            "elements": [
                "appliedenergistics2:quartz_pillar@1"
            ]
        },
        {
            "x": -6,
            "y": 3,
            "z": 20,
            "elements": [
                "mekanism:reinforcedplasticblock@15"
            ]
        },
        {
            "x": -5,
            "y": 5,
            "z": 21,
            "elements": [
                "tconstruct:metal@0"
            ]
        },
        {
            "x": -5,
            "y": 3,
            "z": 20,
            "elements": [
                "botania:storage@1"
            ]
        },
        {
            "x": -4,
            "y": 5,
            "z": 21,
            "elements": [
                "tconstruct:metal@0"
            ]
        },
        {
            "x": -3,
            "y": 5,
            "z": 21,
            "elements": [
                "tconstruct:metal@0"
            ]
        },
        {
            "x": -2,
            "y": 5,
            "z": 21,
            "elements": [
                "tconstruct:metal@0"
            ]
        },
        {
            "x": -1,
            "y": 5,
            "z": 21,
            "elements": [
                "tconstruct:metal@0"
            ]
        },
        {
            "x": 0,
            "y": 5,
            "z": 21,
            "elements": [
                "tconstruct:metal@0"
            ]
        },
        {
            "x": 0,
            "y": 3,
            "z": 20,
            "elements": [
                "botania:storage@1"
            ]
        },
        {
            "x": 1,
            "y": 3,
            "z": 20,
            "elements": [
                "mekanism:reinforcedplasticblock@15"
            ]
        },
        {
            "x": 2,
            "y": 3,
            "z": 20,
            "elements": [
                "botania:quartztypemana@2"
            ]
        },
        {
            "x": 3,
            "y": 3,
            "z": 20,
            "elements": [
                "mekanism:reinforcedplasticblock@15"
            ]
        },
        {
            "x": -11,
            "y": 4,
            "z": 4,
            "elements": [
                "ic2:resource@13"
            ]
        },
        {
            "x": -10,
            "y": 2,
            "z": 3,
            "elements": [
                "appliedenergistics2:quartz_pillar@1"
            ]
        },
        {
            "x": -9,
            "y": 0,
            "z": 2,
            "elements": [
                "botania:storage@2"
            ]
        },
        {
            "x": -8,
            "y": 0,
            "z": 2,
            "elements": [
                "botania:storage@2"
            ]
        },
        {
            "x": 3,
            "y": 0,
            "z": 2,
            "elements": [
                "botania:storage@2"
            ]
        },
        {
            "x": 6,
            "y": 4,
            "z": 4,
            "elements": [
                "ic2:resource@13"
            ]
        },
        {
            "x": 5,
            "y": 2,
            "z": 3,
            "elements": [
                "botania:quartztypemana@2"
            ]
        },
        {
            "x": 4,
            "y": 0,
            "z": 2,
            "elements": [
                "botania:storage@2"
            ]
        },
        {
            "x": -10,
            "y": 0,
            "z": 18,
            "elements": [
                "botania:storage@2"
            ]
        },
        {
            "x": -8,
            "y": 4,
            "z": 20,
            "elements": [
                "ic2:resource@13"
            ]
        },
        {
            "x": -7,
            "y": 4,
            "z": 20,
            "elements": [
                "nuclearcraft:tritium_lamp@0"
            ]
        },
        {
            "x": -6,
            "y": 4,
            "z": 20,
            "elements": [
                "ic2:resource@13"
            ]
        },
        {
            "x": 1,
            "y": 4,
            "z": 20,
            "elements": [
                "ic2:resource@13"
            ]
        },
        {
            "x": 2,
            "y": 4,
            "z": 20,
            "elements": [
                "nuclearcraft:tritium_lamp@0"
            ]
        },
        {
            "x": 3,
            "y": 4,
            "z": 20,
            "elements": [
                "ic2:resource@13"
            ]
        },
        {
            "x": -11,
            "y": 5,
            "z": 4,
            "elements": [
                "tconstruct:metal@0"
            ]
        },
        {
            "x": -10,
            "y": 3,
            "z": 3,
            "elements": [
                "appliedenergistics2:quartz_pillar@1"
            ]
        },
        {
            "x": 5,
            "y": 0,
            "z": 18,
            "elements": [
                "botania:storage@2"
            ]
        },
        {
            "x": -5,
            "y": 3,
            "z": 3,
            "elements": [
                "thermalfoundation:storage_alloy@7"
            ]
        },
        {
            "x": 0,
            "y": 3,
            "z": 3,
            "elements": [
                "thermalfoundation:storage_alloy@7"
            ]
        },
        {
            "x": 6,
            "y": 5,
            "z": 4,
            "elements": [
                "tconstruct:metal@0"
            ]
        },
        {
            "x": 5,
            "y": 3,
            "z": 3,
            "elements": [
                "botania:quartztypemana@2"
            ]
        },
        {
            "x": -10,
            "y": 1,
            "z": 18,
            "elements": [
                "appliedenergistics2:quartz_pillar@1"
            ]
        },
        {
            "x": -9,
            "y": 3,
            "z": 19,
            "elements": [
                "mekanism:reinforcedplasticblock@15"
            ]
        },
        {
            "x": -8,
            "y": 5,
            "z": 20,
            "elements": [
                "tconstruct:metal@0"
            ]
        },
        {
            "x": -7,
            "y": 5,
            "z": 20,
            "elements": [
                "tconstruct:metal@0"
            ]
        },
        {
            "x": -6,
            "y": 5,
            "z": 20,
            "elements": [
                "tconstruct:metal@0"
            ]
        },
        {
            "x": -5,
            "y": 3,
            "z": 19,
            "elements": [
                "botania:storage@1"
            ]
        },
        {
            "x": 1,
            "y": 5,
            "z": 20,
            "elements": [
                "tconstruct:metal@0"
            ]
        },
        {
            "x": 0,
            "y": 3,
            "z": 19,
            "elements": [
                "botania:storage@1"
            ]
        },
        {
            "x": 2,
            "y": 5,
            "z": 20,
            "elements": [
                "tconstruct:metal@0"
            ]
        },
        {
            "x": 3,
            "y": 5,
            "z": 20,
            "elements": [
                "tconstruct:metal@0"
            ]
        },
        {
            "x": 4,
            "y": 3,
            "z": 19,
            "elements": [
                "mekanism:reinforcedplasticblock@15"
            ]
        },
        {
            "x": -10,
            "y": 4,
            "z": 3,
            "elements": [
                "nuclearcraft:tritium_lamp@0"
            ]
        },
        {
            "x": 5,
            "y": 1,
            "z": 18,
            "elements": [
                "botania:quartztypemana@2"
            ]
        },
        {
            "x": -7,
            "y": 0,
            "z": 1,
            "elements": [
                "botania:storage@2"
            ]
        },
        {
            "x": -6,
            "y": 0,
            "z": 1,
            "elements": [
                "botania:storage@2"
            ]
        },
        {
            "x": -5,
            "y": 0,
            "z": 1,
            "elements": [
                "botania:storage@2"
            ]
        },
        {
            "x": 0,
            "y": 0,
            "z": 1,
            "elements": [
                "botania:storage@2"
            ]
        },
        {
            "x": 1,
            "y": 0,
            "z": 1,
            "elements": [
                "botania:storage@2"
            ]
        },
        {
            "x": 2,
            "y": 0,
            "z": 1,
            "elements": [
                "botania:storage@2"
            ]
        },
        {
            "x": 5,
            "y": 4,
            "z": 3,
            "elements": [
                "nuclearcraft:tritium_lamp@0"
            ]
        },
        {
            "x": -11,
            "y": 0,
            "z": 17,
            "elements": [
                "botania:storage@2"
            ]
        },
        {
            "x": -10,
            "y": 2,
            "z": 18,
            "elements": [
                "appliedenergistics2:quartz_pillar@1"
            ]
        },
        {
            "x": -9,
            "y": 4,
            "z": 19,
            "elements": [
                "ic2:resource@13"
            ]
        },
        {
            "x": 4,
            "y": 4,
            "z": 19,
            "elements": [
                "ic2:resource@13"
            ]
        },
        {
            "x": -10,
            "y": 5,
            "z": 3,
            "elements": [
                "tconstruct:metal@0"
            ]
        },
        {
            "x": 5,
            "y": 2,
            "z": 18,
            "elements": [
                "botania:quartztypemana@2"
            ]
        },
        {
            "x": -9,
            "y": 3,
            "z": 2,
            "elements": [
                "mekanism:reinforcedplasticblock@15"
            ]
        },
        {
            "x": 6,
            "y": 0,
            "z": 17,
            "elements": [
                "botania:storage@2"
            ]
        },
        {
            "x": -7,
            "y": 1,
            "z": 1,
            "elements": [
                "appliedenergistics2:quartz_pillar@1"
            ]
        },
        {
            "x": -5,
            "y": 3,
            "z": 2,
            "elements": [
                "thermalfoundation:storage_alloy@7"
            ]
        },
        {
            "x": 0,
            "y": 3,
            "z": 2,
            "elements": [
                "thermalfoundation:storage_alloy@7"
            ]
        },
        {
            "x": 2,
            "y": 1,
            "z": 1,
            "elements": [
                "botania:quartztypemana@2"
            ]
        },
        {
            "x": 5,
            "y": 5,
            "z": 3,
            "elements": [
                "tconstruct:metal@0"
            ]
        },
        {
            "x": 4,
            "y": 3,
            "z": 2,
            "elements": [
                "mekanism:reinforcedplasticblock@15"
            ]
        },
        {
            "x": -10,
            "y": 3,
            "z": 18,
            "elements": [
                "appliedenergistics2:quartz_pillar@1"
            ]
        },
        {
            "x": -9,
            "y": 5,
            "z": 19,
            "elements": [
                "tconstruct:metal@0"
            ]
        },
        {
            "x": -5,
            "y": 3,
            "z": 18,
            "elements": [
                "botania:storage@1"
            ]
        },
        {
            "x": 0,
            "y": 3,
            "z": 18,
            "elements": [
                "botania:storage@1"
            ]
        },
        {
            "x": 4,
            "y": 5,
            "z": 19,
            "elements": [
                "tconstruct:metal@0"
            ]
        },
        {
            "x": 5,
            "y": 3,
            "z": 18,
            "elements": [
                "botania:quartztypemana@2"
            ]
        },
        {
            "x": -9,
            "y": 4,
            "z": 2,
            "elements": [
                "ic2:resource@13"
            ]
        },
        {
            "x": -7,
            "y": 2,
            "z": 1,
            "elements": [
                "appliedenergistics2:quartz_pillar@1"
            ]
        }
    ]}