{
    "registryname": "ECO_Y6",
    "localizedname": "§bECO-§dY6 §e物质生成机",
    "requires-blueprint": false,
    "parts": [
        {
            "x": -1,
            "y": 0,
            "z": 0,
            "elements": [
                "mekanism:plasticfence@8"
            ]
        },
        {
            "x": 2,
            "y": 4,
            "z": 2,
            "elements": [
                "mekanism:reinforcedplasticblock@8"
            ]
        },
        {
            "x": 3,
            "y": 6,
            "z": 3,
            "elements": [
                "appliedenergistics2:quartz_glass@0"
            ]
        },
        {
            "x": 1,
            "y": 0,
            "z": 0,
            "elements": [
                "mekanism:plasticfence@8"
            ]
        },
        {
            "x": 3,
            "y": 4,
            "z": 2,
            "elements": [
                "mekanism:plasticfence@8"
            ]
        },
        {
            "x": 4,
            "y": 4,
            "z": 2,
            "elements": [
                "mekanism:plasticfence@8"
            ]
        },
        {
            "x": 5,
            "y": 4,
            "z": 2,
            "elements": [
                "mekanism:plasticfence@8"
            ]
        },
        {
            "x": -5,
            "y": 3,
            "z": 1,
            "elements": [
                "appliedenergistics2:sky_stone_small_brick_slab@8"
            ]
        },
        {
            "x": -3,
            "y": 7,
            "z": 3,
            "elements": [
                "appliedenergistics2:sky_stone_small_brick_slab@0"
            ]
        },
        {
            "x": -3,
            "y": 5,
            "z": 2,
            "elements": [
                "appliedenergistics2:sky_stone_small_brick_slab@8"
            ]
        },
        {
            "x": -2,
            "y": 7,
            "z": 3,
            "elements": [
                "appliedenergistics2:quartz_glass@0"
            ]
        },
        {
            "x": 3,
            "y": -1,
            "z": 0,
            "elements": [
                "appliedenergistics2:sky_stone_small_brick_stairs@2"
            ]
        },
        {
            "x": -2,
            "y": 5,
            "z": 2,
            "elements": [
                "appliedenergistics2:quartz_glass@0"
            ]
        },
        {
            "x": 2,
            "y": -1,
            "z": 0,
            "elements": [
                "appliedenergistics2:sky_stone_small_brick_stairs@2"
            ]
        },
        {
            "x": 1,
            "y": -1,
            "z": 0,
            "elements": [
                "mekanism:plasticfence@8"
            ]
        },
        {
            "x": -1,
            "y": 3,
            "z": 1,
            "elements": [
                "appliedenergistics2:sky_stone_small_brick_slab@8"
            ]
        },
        {
            "x": 0,
            "y": -1,
            "z": 0,
            "elements": [
                "modularmachinery:blockinputbus"
            ]
        },
        {
            "x": -1,
            "y": 1,
            "z": 0,
            "elements": [
                "appliedenergistics2:sky_stone_small_brick_slab@0"
            ]
        },
        {
            "x": 0,
            "y": 3,
            "z": 1,
            "elements": [
                "appliedenergistics2:quartz_pillar@1"
            ]
        },
        {
            "x": 2,
            "y": 7,
            "z": 3,
            "elements": [
                "appliedenergistics2:quartz_glass@0"
            ]
        },
        {
            "x": -1,
            "y": -1,
            "z": 0,
            "elements": [
                "mekanism:plasticfence@8"
            ]
        },
        {
            "x": 0,
            "y": 1,
            "z": 0,
            "elements": [
                "appliedenergistics2:sky_stone_small_brick_slab@0"
            ]
        },
        {
            "x": 1,
            "y": 3,
            "z": 1,
            "elements": [
                "appliedenergistics2:sky_stone_small_brick_slab@8"
            ]
        },
        {
            "x": 2,
            "y": 5,
            "z": 2,
            "elements": [
                "appliedenergistics2:quartz_glass@0"
            ]
        },
        {
            "x": 3,
            "y": 7,
            "z": 3,
            "elements": [
                "appliedenergistics2:sky_stone_small_brick_slab@0"
            ]
        },
        {
            "x": -2,
            "y": -1,
            "z": 0,
            "elements": [
                "appliedenergistics2:sky_stone_small_brick_stairs@0"
            ]
        },
        {
            "x": 1,
            "y": 1,
            "z": 0,
            "elements": [
                "appliedenergistics2:sky_stone_small_brick_slab@0"
            ]
        },
        {
            "x": 3,
            "y": 5,
            "z": 2,
            "elements": [
                "appliedenergistics2:sky_stone_small_brick_slab@8"
            ]
        },
        {
            "x": -3,
            "y": -1,
            "z": 0,
            "elements": [
                "appliedenergistics2:sky_stone_small_brick_stairs@2"
            ]
        },
        {
            "x": 5,
            "y": 3,
            "z": 1,
            "elements": [
                "appliedenergistics2:sky_stone_small_brick_slab@8"
            ]
        },
        {
            "x": -3,
            "y": -1,
            "z": 7,
            "elements": [
                "modularmachinery:blockcasing@4"
            ]
        },
        {
            "x": 3,
            "y": -1,
            "z": 7,
            "elements": [
                "modularmachinery:blockcasing@4"
            ]
        },
        {
            "x": -3,
            "y": 6,
            "z": 2,
            "elements": [
                "appliedenergistics2:quartz_glass@0"
            ]
        },
        {
            "x": -2,
            "y": 8,
            "z": 3,
            "elements": [
                "appliedenergistics2:sky_stone_small_brick_stairs@0"
            ]
        },
        {
            "x": -1,
            "y": 8,
            "z": 3,
            "elements": [
                "appliedenergistics2:quartz_glass@0"
            ]
        },
        {
            "x": -2,
            "y": 4,
            "z": 1,
            "elements": [
                "appliedenergistics2:sky_stone_small_brick_slab@8"
            ]
        },
        {
            "x": 0,
            "y": 8,
            "z": 3,
            "elements": [
                "appliedenergistics2:quartz_glass@0"
            ]
        },
        {
            "x": -1,
            "y": 4,
            "z": 1,
            "elements": [
                "mekanism:reinforcedplasticblock@8"
            ]
        },
        {
            "x": 0,
            "y": 6,
            "z": 2,
            "elements": [
                "appliedenergistics2:quartz_pillar@2"
            ]
        },
        {
            "x": 1,
            "y": 8,
            "z": 3,
            "elements": [
                "appliedenergistics2:quartz_glass@0"
            ]
        },
        {
            "x": 0,
            "y": 4,
            "z": 1,
            "elements": [
                "appliedenergistics2:sky_stone_small_brick_stairs@3"
            ]
        },
        {
            "x": 2,
            "y": 8,
            "z": 3,
            "elements": [
                "appliedenergistics2:sky_stone_small_brick_stairs@1"
            ]
        },
        {
            "x": 1,
            "y": 4,
            "z": 1,
            "elements": [
                "mekanism:reinforcedplasticblock@8"
            ]
        },
        {
            "x": 2,
            "y": 4,
            "z": 1,
            "elements": [
                "appliedenergistics2:sky_stone_small_brick_slab@8"
            ]
        },
        {
            "x": 3,
            "y": 6,
            "z": 2,
            "elements": [
                "appliedenergistics2:quartz_glass@0"
            ]
        },
        {
            "x": -3,
            "y": 0,
            "z": 7,
            "elements": [
                "appliedenergistics2:sky_stone_small_brick@0"
            ]
        },
        {
            "x": 3,
            "y": 0,
            "z": 7,
            "elements": [
                "appliedenergistics2:sky_stone_small_brick@0"
            ]
        },
        {
            "x": -5,
            "y": 3,
            "z": 0,
            "elements": [
                "appliedenergistics2:sky_stone_small_brick_slab@8"
            ]
        },
        {
            "x": -3,
            "y": 7,
            "z": 2,
            "elements": [
                "appliedenergistics2:sky_stone_small_brick_slab@0"
            ]
        },
        {
            "x": -3,
            "y": 5,
            "z": 1,
            "elements": [
                "appliedenergistics2:sky_stone_small_brick_slab@8"
            ]
        },
        {
            "x": -2,
            "y": 7,
            "z": 2,
            "elements": [
                "appliedenergistics2:quartz_glass@0"
            ]
        },
        {
            "x": -1,
            "y": 9,
            "z": 3,
            "elements": [
                "appliedenergistics2:sky_stone_small_brick_slab@0"
            ]
        },
        {
            "x": -2,
            "y": 5,
            "z": 1,
            "elements": [
                "appliedenergistics2:quartz_glass@0"
            ]
        },
        {
            "x": 0,
            "y": 9,
            "z": 3,
            "elements": [
                "appliedenergistics2:sky_stone_small_brick_slab@0"
            ]
        },
        {
            "x": 1,
            "y": 9,
            "z": 3,
            "elements": [
                "appliedenergistics2:sky_stone_small_brick_slab@0"
            ]
        },
        {
            "x": 0,
            "y": 3,
            "z": 0,
            "elements": [
                "appliedenergistics2:sky_stone_small_brick_stairs@6"
            ]
        },
        {
            "x": 2,
            "y": 7,
            "z": 2,
            "elements": [
                "appliedenergistics2:quartz_glass@0"
            ]
        },
        {
            "x": 2,
            "y": 5,
            "z": 1,
            "elements": [
                "appliedenergistics2:quartz_glass@0"
            ]
        },
        {
            "x": 3,
            "y": 7,
            "z": 2,
            "elements": [
                "appliedenergistics2:sky_stone_small_brick_slab@0"
            ]
        },
        {
            "x": 3,
            "y": 5,
            "z": 1,
            "elements": [
                "appliedenergistics2:sky_stone_small_brick_slab@8"
            ]
        },
        {
            "x": 5,
            "y": 3,
            "z": 0,
            "elements": [
                "appliedenergistics2:sky_stone_small_brick_slab@8"
            ]
        },
        {
            "x": -3,
            "y": 1,
            "z": 7,
            "elements": [
                "appliedenergistics2:sky_stone_small_brick@0"
            ]
        },
        {
            "x": 3,
            "y": 1,
            "z": 7,
            "elements": [
                "appliedenergistics2:sky_stone_small_brick@0"
            ]
        },
        {
            "x": -3,
            "y": 6,
            "z": 1,
            "elements": [
                "appliedenergistics2:quartz_glass@0"
            ]
        },
        {
            "x": -2,
            "y": 8,
            "z": 2,
            "elements": [
                "appliedenergistics2:sky_stone_small_brick_slab@0"
            ]
        },
        {
            "x": -1,
            "y": 8,
            "z": 2,
            "elements": [
                "appliedenergistics2:quartz_glass@0"
            ]
        },
        {
            "x": -1,
            "y": 4,
            "z": 0,
            "elements": [
                "appliedenergistics2:sky_stone_small_brick_slab@8"
            ]
        },
        {
            "x": 1,
            "y": 8,
            "z": 2,
            "elements": [
                "appliedenergistics2:quartz_glass@0"
            ]
        },
        {
            "x": 0,
            "y": 4,
            "z": 0,
            "elements": [
                "mekanism:reinforcedplasticblock@8"
            ]
        },
        {
            "x": 2,
            "y": 8,
            "z": 2,
            "elements": [
                "appliedenergistics2:sky_stone_small_brick_slab@0"
            ]
        },
        {
            "x": 1,
            "y": 4,
            "z": 0,
            "elements": [
                "appliedenergistics2:sky_stone_small_brick_slab@8"
            ]
        },
        {
            "x": 3,
            "y": 6,
            "z": 1,
            "elements": [
                "appliedenergistics2:quartz_glass@0"
            ]
        },
        {
            "x": -3,
            "y": 2,
            "z": 7,
            "elements": [
                "modularmachinery:blockcasing@4"
            ]
        },
        {
            "x": 0,
            "y": 2,
            "z": 7,
            "elements": [
                "minecraft:sea_lantern@0"
            ]
        },
        {
            "x": 3,
            "y": 2,
            "z": 7,
            "elements": [
                "modularmachinery:blockcasing@4"
            ]
        },
        {
            "x": -3,
            "y": 7,
            "z": 1,
            "elements": [
                "appliedenergistics2:sky_stone_small_brick_slab@0"
            ]
        },
        {
            "x": -2,
            "y": 7,
            "z": 1,
            "elements": [
                "appliedenergistics2:quartz_glass@0"
            ]
        },
        {
            "x": -1,
            "y": 9,
            "z": 2,
            "elements": [
                "appliedenergistics2:sky_stone_small_brick_slab@0"
            ]
        },
        {
            "x": -2,
            "y": 5,
            "z": 0,
            "elements": [
                "appliedenergistics2:sky_stone_small_brick_slab@8"
            ]
        },
        {
            "x": 0,
            "y": 9,
            "z": 2,
            "elements": [
                "appliedenergistics2:sky_stone_small_brick_slab@0"
            ]
        },
        {
            "x": -1,
            "y": 5,
            "z": 0,
            "elements": [
                "appliedenergistics2:quartz_glass@0"
            ]
        },
        {
            "x": 1,
            "y": 9,
            "z": 2,
            "elements": [
                "appliedenergistics2:sky_stone_small_brick_slab@0"
            ]
        },
        {
            "x": 0,
            "y": 5,
            "z": 0,
            "elements": [
                "appliedenergistics2:quartz_glass@0"
            ]
        },
        {
            "x": 1,
            "y": 5,
            "z": 0,
            "elements": [
                "appliedenergistics2:quartz_glass@0"
            ]
        },
        {
            "x": 2,
            "y": 7,
            "z": 1,
            "elements": [
                "appliedenergistics2:quartz_glass@0"
            ]
        },
        {
            "x": 2,
            "y": 5,
            "z": 0,
            "elements": [
                "appliedenergistics2:sky_stone_small_brick_slab@8"
            ]
        },
        {
            "x": 3,
            "y": 7,
            "z": 1,
            "elements": [
                "appliedenergistics2:sky_stone_small_brick_slab@0"
            ]
        },
        {
            "x": -5,
            "y": -1,
            "z": 5,
            "elements": [
                "modularmachinery:blockcasing@4"
            ]
        },
        {
            "x": -3,
            "y": 3,
            "z": 7,
            "elements": [
                "mekanism:reinforcedplasticblock@8"
            ]
        },
        {
            "x": -2,
            "y": 3,
            "z": 7,
            "elements": [
                "appliedenergistics2:sky_stone_small_brick_slab@8"
            ]
        },
        {
            "x": -1,
            "y": 3,
            "z": 7,
            "elements": [
                "appliedenergistics2:sky_stone_small_brick_slab@8"
            ]
        },
        {
            "x": -2,
            "y": -1,
            "z": 5,
            "elements": [
                "appliedenergistics2:sky_stone_small_brick_stairs@0"
            ]
        },
        {
            "x": 0,
            "y": 3,
            "z": 7,
            "elements": [
                "appliedenergistics2:sky_stone_small_brick@0"
            ]
        },
        {
            "x": -1,
            "y": -1,
            "z": 5,
            "elements": [
                "appliedenergistics2:sky_stone_small_brick_stairs@3"
            ]
        },
        {
            "x": 1,
            "y": 3,
            "z": 7,
            "elements": [
                "appliedenergistics2:sky_stone_small_brick_slab@8"
            ]
        },
        {
            "x": 0,
            "y": -1,
            "z": 5,
            "elements": [
                "appliedenergistics2:sky_stone_small_brick_stairs@3"
            ]
        },
        {
            "x": 2,
            "y": 3,
            "z": 7,
            "elements": [
                "appliedenergistics2:sky_stone_small_brick_slab@8"
            ]
        },
        {
            "x": 1,
            "y": -1,
            "z": 5,
            "elements": [
                "appliedenergistics2:sky_stone_small_brick_stairs@3"
            ]
        },
        {
            "x": 3,
            "y": 3,
            "z": 7,
            "elements": [
                "mekanism:reinforcedplasticblock@8"
            ]
        },
        {
            "x": 2,
            "y": -1,
            "z": 5,
            "elements": [
                "appliedenergistics2:sky_stone_small_brick_stairs@1"
            ]
        },
        {
            "x": 5,
            "y": -1,
            "z": 5,
            "elements": [
                "modularmachinery:blockcasing@4"
            ]
        },
        {
            "x": -2,
            "y": 8,
            "z": 1,
            "elements": [
                "appliedenergistics2:sky_stone_small_brick_stairs@0"
            ]
        },
        {
            "x": -2,
            "y": 6,
            "z": 0,
            "elements": [
                "appliedenergistics2:quartz_glass@0"
            ]
        },
        {
            "x": -1,
            "y": 8,
            "z": 1,
            "elements": [
                "appliedenergistics2:quartz_glass@0"
            ]
        },
        {
            "x": 0,
            "y": 8,
            "z": 1,
            "elements": [
                "appliedenergistics2:quartz_glass@0"
            ]
        },
        {
            "x": 1,
            "y": 8,
            "z": 1,
            "elements": [
                "appliedenergistics2:quartz_glass@0"
            ]
        },
        {
            "x": 2,
            "y": 8,
            "z": 1,
            "elements": [
                "appliedenergistics2:sky_stone_small_brick_stairs@1"
            ]
        },
        {
            "x": 2,
            "y": 6,
            "z": 0,
            "elements": [
                "appliedenergistics2:quartz_glass@0"
            ]
        },
        {
            "x": -5,
            "y": 0,
            "z": 5,
            "elements": [
                "appliedenergistics2:sky_stone_small_brick@0"
            ]
        },
        {
            "x": 0,
            "y": 4,
            "z": 7,
            "elements": [
                "mekanism:plasticfence@8"
            ]
        },
        {
            "x": 0,
            "y": 4,
            "z": -3,
            "elements": [
                "mekanism:plasticfence@8"
            ]
        },
        {
            "x": 5,
            "y": 0,
            "z": 5,
            "elements": [
                "appliedenergistics2:sky_stone_small_brick@0"
            ]
        },
        {
            "x": -2,
            "y": 7,
            "z": 0,
            "elements": [
                "appliedenergistics2:sky_stone_small_brick_slab@0"
            ]
        },
        {
            "x": -1,
            "y": 9,
            "z": 1,
            "elements": [
                "appliedenergistics2:sky_stone_small_brick_slab@0"
            ]
        },
        {
            "x": -1,
            "y": 7,
            "z": 0,
            "elements": [
                "appliedenergistics2:quartz_glass@0"
            ]
        },
        {
            "x": 0,
            "y": 9,
            "z": 1,
            "elements": [
                "appliedenergistics2:sky_stone_small_brick_slab@0"
            ]
        },
        {
            "x": 0,
            "y": 7,
            "z": 0,
            "elements": [
                "appliedenergistics2:quartz_glass@0"
            ]
        },
        {
            "x": 1,
            "y": 9,
            "z": 1,
            "elements": [
                "appliedenergistics2:sky_stone_small_brick_slab@0"
            ]
        },
        {
            "x": 1,
            "y": 7,
            "z": 0,
            "elements": [
                "appliedenergistics2:quartz_glass@0"
            ]
        },
        {
            "x": 2,
            "y": 7,
            "z": 0,
            "elements": [
                "appliedenergistics2:sky_stone_small_brick_slab@0"
            ]
        },
        {
            "x": -5,
            "y": 1,
            "z": 5,
            "elements": [
                "appliedenergistics2:sky_stone_small_brick@0"
            ]
        },
        {
            "x": -4,
            "y": 3,
            "z": 6,
            "elements": [
                "appliedenergistics2:sky_stone_small_brick@0"
            ]
        },
        {
            "x": 3,
            "y": 3,
            "z": -3,
            "elements": [
                "mekanism:reinforcedplasticblock@8"
            ]
        },
        {
            "x": -3,
            "y": -1,
            "z": 4,
            "elements": [
                "appliedenergistics2:sky_stone_small_brick_stairs@3"
            ]
        },
        {
            "x": 2,
            "y": 3,
            "z": -3,
            "elements": [
                "appliedenergistics2:sky_stone_small_brick_slab@8"
            ]
        },
        {
            "x": -2,
            "y": -1,
            "z": 4,
            "elements": [
                "appliedenergistics2:sky_stone_small_brick_stairs@0"
            ]
        },
        {
            "x": 0,
            "y": 3,
            "z": 6,
            "elements": [
                "appliedenergistics2:sky_stone_small_brick_slab@8"
            ]
        },
        {
            "x": 1,
            "y": 3,
            "z": -3,
            "elements": [
                "appliedenergistics2:sky_stone_small_brick_slab@8"
            ]
        },
        {
            "x": -1,
            "y": -1,
            "z": 4,
            "elements": [
                "mekanism:plasticfence@8"
            ]
        },
        {
            "x": 0,
            "y": 3,
            "z": -3,
            "elements": [
                "appliedenergistics2:sky_stone_small_brick@0"
            ]
        },
        {
            "x": 0,
            "y": -1,
            "z": 4,
            "elements": [
                "modularmachinery:blockcasing@5"
            ]
        },
        {
            "x": -1,
            "y": 3,
            "z": -3,
            "elements": [
                "appliedenergistics2:sky_stone_small_brick_slab@8"
            ]
        },
        {
            "x": 1,
            "y": 7,
            "z": -1,
            "elements": [
                "appliedenergistics2:sky_stone_small_brick_slab@0"
            ]
        },
        {
            "x": 1,
            "y": -1,
            "z": 4,
            "elements": [
                "mekanism:plasticfence@8"
            ]
        },
        {
            "x": -2,
            "y": 3,
            "z": -3,
            "elements": [
                "appliedenergistics2:sky_stone_small_brick_slab@8"
            ]
        },
        {
            "x": 0,
            "y": 7,
            "z": -1,
            "elements": [
                "appliedenergistics2:sky_stone_small_brick_slab@0"
            ]
        },
        {
            "x": 2,
            "y": -1,
            "z": 4,
            "elements": [
                "appliedenergistics2:sky_stone_small_brick_stairs@1"
            ]
        },
        {
            "x": 4,
            "y": 3,
            "z": 6,
            "elements": [
                "appliedenergistics2:sky_stone_small_brick@0"
            ]
        },
        {
            "x": -3,
            "y": 3,
            "z": -3,
            "elements": [
                "mekanism:reinforcedplasticblock@8"
            ]
        },
        {
            "x": -1,
            "y": 7,
            "z": -1,
            "elements": [
                "appliedenergistics2:sky_stone_small_brick_slab@0"
            ]
        },
        {
            "x": 3,
            "y": -1,
            "z": 4,
            "elements": [
                "appliedenergistics2:sky_stone_small_brick_stairs@3"
            ]
        },
        {
            "x": 5,
            "y": 1,
            "z": 5,
            "elements": [
                "appliedenergistics2:sky_stone_small_brick@0"
            ]
        },
        {
            "x": -1,
            "y": 8,
            "z": 0,
            "elements": [
                "appliedenergistics2:sky_stone_small_brick_stairs@2"
            ]
        },
        {
            "x": 0,
            "y": 8,
            "z": 0,
            "elements": [
                "appliedenergistics2:sky_stone_small_brick_slab@0"
            ]
        },
        {
            "x": 1,
            "y": 8,
            "z": 0,
            "elements": [
                "appliedenergistics2:sky_stone_small_brick_stairs@2"
            ]
        },
        {
            "x": -5,
            "y": 2,
            "z": 5,
            "elements": [
                "modularmachinery:blockcasing@4"
            ]
        },
        {
            "x": 3,
            "y": 2,
            "z": -3,
            "elements": [
                "modularmachinery:blockcasing@4"
            ]
        },
        {
            "x": 0,
            "y": 4,
            "z": 6,
            "elements": [
                "mekanism:plasticfence@8"
            ]
        },
        {
            "x": -1,
            "y": 0,
            "z": 4,
            "elements": [
                "mekanism:plasticfence@8"
            ]
        },
        {
            "x": 0,
            "y": 2,
            "z": -3,
            "elements": [
                "minecraft:sea_lantern@0"
            ]
        },
        {
            "x": 0,
            "y": 0,
            "z": 4,
            "elements": [
                "modularmachinery:blockfluidoutputhatch"
            ]
        },
        {
            "x": 0,
            "y": 4,
            "z": -2,
            "elements": [
                "mekanism:plasticfence@8"
            ]
        },
        {
            "x": 1,
            "y": 6,
            "z": -1,
            "elements": [
                "appliedenergistics2:quartz_glass@0"
            ]
        },
        {
            "x": 1,
            "y": 0,
            "z": 4,
            "elements": [
                "mekanism:plasticfence@8"
            ]
        },
        {
            "x": 0,
            "y": 6,
            "z": -1,
            "elements": [
                "appliedenergistics2:quartz_glass@0"
            ]
        },
        {
            "x": -3,
            "y": 2,
            "z": -3,
            "elements": [
                "modularmachinery:blockcasing@4"
            ]
        },
        {
            "x": -1,
            "y": 6,
            "z": -1,
            "elements": [
                "appliedenergistics2:quartz_glass@0"
            ]
        },
        {
            "x": 5,
            "y": 2,
            "z": 5,
            "elements": [
                "modularmachinery:blockcasing@4"
            ]
        },
        {
            "x": -5,
            "y": 3,
            "z": 5,
            "elements": [
                "mekanism:reinforcedplasticblock@8"
            ]
        },
        {
            "x": 3,
            "y": 1,
            "z": -3,
            "elements": [
                "appliedenergistics2:sky_stone_small_brick@0"
            ]
        },
        {
            "x": 4,
            "y": 3,
            "z": -2,
            "elements": [
                "appliedenergistics2:sky_stone_small_brick@0"
            ]
        },
        {
            "x": -3,
            "y": -1,
            "z": 3,
            "elements": [
                "appliedenergistics2:sky_stone_small_brick_stairs@0"
            ]
        },
        {
            "x": -2,
            "y": -1,
            "z": 3,
            "elements": [
                "mekanism:plasticfence@8"
            ]
        },
        {
            "x": -1,
            "y": 1,
            "z": 4,
            "elements": [
                "appliedenergistics2:sky_stone_small_brick_slab@0"
            ]
        },
        {
            "x": 0,
            "y": 3,
            "z": 5,
            "elements": [
                "appliedenergistics2:sky_stone_small_brick_slab@8"
            ]
        },
        {
            "x": -1,
            "y": -1,
            "z": 3,
            "elements": [
                "appliedenergistics2:sky_stone_small_brick@0"
            ]
        },
        {
            "x": 0,
            "y": 1,
            "z": 4,
            "elements": [
                "appliedenergistics2:sky_stone_small_brick_slab@0"
            ]
        },
        {
            "x": 0,
            "y": 3,
            "z": -2,
            "elements": [
                "appliedenergistics2:sky_stone_small_brick_slab@8"
            ]
        },
        {
            "x": 1,
            "y": 5,
            "z": -1,
            "elements": [
                "appliedenergistics2:sky_stone_small_brick_slab@8"
            ]
        },
        {
            "x": 0,
            "y": -1,
            "z": 3,
            "elements": [
                "appliedenergistics2:sky_stone_small_brick@0"
            ]
        },
        {
            "x": 1,
            "y": 1,
            "z": 4,
            "elements": [
                "appliedenergistics2:sky_stone_small_brick_slab@0"
            ]
        },
        {
            "x": 0,
            "y": 5,
            "z": -1,
            "elements": [
                "appliedenergistics2:sky_stone_small_brick_slab@8"
            ]
        },
        {
            "x": 1,
            "y": -1,
            "z": 3,
            "elements": [
                "appliedenergistics2:sky_stone_small_brick@0"
            ]
        },
        {
            "x": -3,
            "y": 1,
            "z": -3,
            "elements": [
                "appliedenergistics2:sky_stone_small_brick@0"
            ]
        },
        {
            "x": -1,
            "y": 5,
            "z": -1,
            "elements": [
                "appliedenergistics2:sky_stone_small_brick_slab@8"
            ]
        },
        {
            "x": 2,
            "y": -1,
            "z": 3,
            "elements": [
                "mekanism:plasticfence@8"
            ]
        },
        {
            "x": 3,
            "y": -1,
            "z": 3,
            "elements": [
                "appliedenergistics2:sky_stone_small_brick_stairs@1"
            ]
        },
        {
            "x": 5,
            "y": 3,
            "z": 5,
            "elements": [
                "mekanism:reinforcedplasticblock@8"
            ]
        },
        {
            "x": -4,
            "y": 3,
            "z": -2,
            "elements": [
                "appliedenergistics2:sky_stone_small_brick@0"
            ]
        },
        {
            "x": 3,
            "y": 0,
            "z": -3,
            "elements": [
                "appliedenergistics2:sky_stone_small_brick@0"
            ]
        },
        {
            "x": -2,
            "y": 0,
            "z": 3,
            "elements": [
                "mekanism:plasticfence@8"
            ]
        },
        {
            "x": 0,
            "y": 4,
            "z": 5,
            "elements": [
                "mekanism:plasticfence@8"
            ]
        },
        {
            "x": -1,
            "y": 0,
            "z": 3,
            "elements": [
                "appliedenergistics2:sky_stone_small_brick@0"
            ]
        },
        {
            "x": 0,
            "y": 0,
            "z": 3,
            "elements": [
                "appliedenergistics2:quartz_pillar@1"
            ]
        },
        {
            "x": 0,
            "y": 4,
            "z": -1,
            "elements": [
                "mekanism:plasticfence@8"
            ]
        },
        {
            "x": 1,
            "y": 0,
            "z": 3,
            "elements": [
                "appliedenergistics2:sky_stone_small_brick@0"
            ]
        },
        {
            "x": -3,
            "y": 0,
            "z": -3,
            "elements": [
                "appliedenergistics2:sky_stone_small_brick@0"
            ]
        },
        {
            "x": 2,
            "y": 0,
            "z": 3,
            "elements": [
                "mekanism:plasticfence@8"
            ]
        },
        {
            "x": -5,
            "y": 3,
            "z": 4,
            "elements": [
                "appliedenergistics2:sky_stone_small_brick_slab@8"
            ]
        },
        {
            "x": 3,
            "y": -1,
            "z": -3,
            "elements": [
                "modularmachinery:blockcasing@4"
            ]
        },
        {
            "x": 5,
            "y": 3,
            "z": -1,
            "elements": [
                "mekanism:reinforcedplasticblock@8"
            ]
        },
        {
            "x": -1,
            "y": 5,
            "z": 5,
            "elements": [
                "appliedenergistics2:sky_stone_small_brick_slab@8"
            ]
        },
        {
            "x": -3,
            "y": -1,
            "z": 2,
            "elements": [
                "appliedenergistics2:sky_stone_small_brick_stairs@0"
            ]
        },
        {
            "x": -2,
            "y": 1,
            "z": 3,
            "elements": [
                "appliedenergistics2:sky_stone_small_brick_slab@0"
            ]
        },
        {
            "x": 0,
            "y": 5,
            "z": 5,
            "elements": [
                "appliedenergistics2:sky_stone_small_brick_slab@8"
            ]
        },
        {
            "x": -2,
            "y": -1,
            "z": 2,
            "elements": [
                "modularmachinery:blockcasing@5"
            ]
        },
        {
            "x": -1,
            "y": 1,
            "z": 3,
            "elements": [
                "appliedenergistics2:sky_stone_small_brick_slab@0"
            ]
        },
        {
            "x": 0,
            "y": 3,
            "z": 4,
            "elements": [
                "appliedenergistics2:sky_stone_small_brick_stairs@7"
            ]
        },
        {
            "x": 1,
            "y": 5,
            "z": 5,
            "elements": [
                "appliedenergistics2:sky_stone_small_brick_slab@8"
            ]
        },
        {
            "x": -1,
            "y": -1,
            "z": 2,
            "elements": [
                "appliedenergistics2:sky_stone_small_brick@0"
            ]
        },
        {
            "x": 0,
            "y": 1,
            "z": 3,
            "elements": [
                "appliedenergistics2:quartz_pillar@1"
            ]
        },
        {
            "x": 0,
            "y": 3,
            "z": -1,
            "elements": [
                "appliedenergistics2:sky_stone_small_brick_slab@8"
            ]
        },
        {
            "x": 0,
            "y": -1,
            "z": 2,
            "elements": [
                "modularmachinery:blockcasing@5"
            ]
        },
        {
            "x": 1,
            "y": 1,
            "z": 3,
            "elements": [
                "appliedenergistics2:sky_stone_small_brick_slab@0"
            ]
        },
        {
            "x": -3,
            "y": -1,
            "z": -3,
            "elements": [
                "modularmachinery:blockcasing@4"
            ]
        },
        {
            "x": 1,
            "y": -1,
            "z": 2,
            "elements": [
                "appliedenergistics2:sky_stone_small_brick@0"
            ]
        },
        {
            "x": 2,
            "y": 1,
            "z": 3,
            "elements": [
                "appliedenergistics2:sky_stone_small_brick_slab@0"
            ]
        },
        {
            "x": 2,
            "y": -1,
            "z": 2,
            "elements": [
                "modularmachinery:blockcasing@5"
            ]
        },
        {
            "x": 3,
            "y": -1,
            "z": 2,
            "elements": [
                "appliedenergistics2:sky_stone_small_brick_stairs@1"
            ]
        },
        {
            "x": 5,
            "y": 3,
            "z": 4,
            "elements": [
                "appliedenergistics2:sky_stone_small_brick_slab@8"
            ]
        },
        {
            "x": -5,
            "y": 3,
            "z": -1,
            "elements": [
                "mekanism:reinforcedplasticblock@8"
            ]
        },
        {
            "x": 5,
            "y": 2,
            "z": -1,
            "elements": [
                "modularmachinery:blockcasing@4"
            ]
        },
        {
            "x": -1,
            "y": 6,
            "z": 5,
            "elements": [
                "appliedenergistics2:quartz_glass@0"
            ]
        },
        {
            "x": -1,
            "y": 4,
            "z": 4,
            "elements": [
                "appliedenergistics2:sky_stone_small_brick_slab@8"
            ]
        },
        {
            "x": 0,
            "y": 6,
            "z": 5,
            "elements": [
                "appliedenergistics2:quartz_glass@0"
            ]
        },
        {
            "x": -2,
            "y": 0,
            "z": 2,
            "elements": [
                "modularmachinery:blockenergyinputhatch"
            ]
        },
        {
            "x": 0,
            "y": 4,
            "z": 4,
            "elements": [
                "mekanism:reinforcedplasticblock@8"
            ]
        },
        {
            "x": 1,
            "y": 6,
            "z": 5,
            "elements": [
                "appliedenergistics2:quartz_glass@0"
            ]
        },
        {
            "x": -1,
            "y": 0,
            "z": 2,
            "elements": [
                "appliedenergistics2:quartz_pillar@2"
            ]
        },
        {
            "x": 0,
            "y": 2,
            "z": 3,
            "elements": [
                "appliedenergistics2:quartz_pillar@1"
            ]
        },
        {
            "x": 1,
            "y": 4,
            "z": 4,
            "elements": [
                "appliedenergistics2:sky_stone_small_brick_slab@8"
            ]
        },
        {
            "x": 1,
            "y": 0,
            "z": 2,
            "elements": [
                "appliedenergistics2:quartz_pillar@1"
            ]
        },
        {
            "x": 2,
            "y": 0,
            "z": 2,
            "elements": [
                "modularmachinery:blockenergyinputhatch"
            ]
        },
        {
            "x": -5,
            "y": 2,
            "z": -1,
            "elements": [
                "modularmachinery:blockcasing@4"
            ]
        },
        {
            "x": -5,
            "y": 3,
            "z": 3,
            "elements": [
                "appliedenergistics2:sky_stone_small_brick_slab@8"
            ]
        },
        {
            "x": 5,
            "y": 1,
            "z": -1,
            "elements": [
                "appliedenergistics2:sky_stone_small_brick@0"
            ]
        },
        {
            "x": -2,
            "y": 5,
            "z": 4,
            "elements": [
                "appliedenergistics2:sky_stone_small_brick_slab@8"
            ]
        },
        {
            "x": -1,
            "y": 7,
            "z": 5,
            "elements": [
                "appliedenergistics2:sky_stone_small_brick_slab@0"
            ]
        },
        {
            "x": -1,
            "y": 5,
            "z": 4,
            "elements": [
                "appliedenergistics2:quartz_glass@0"
            ]
        },
        {
            "x": 0,
            "y": 7,
            "z": 5,
            "elements": [
                "appliedenergistics2:sky_stone_small_brick_slab@0"
            ]
        },
        {
            "x": -3,
            "y": -1,
            "z": 1,
            "elements": [
                "appliedenergistics2:sky_stone_small_brick_stairs@0"
            ]
        },
        {
            "x": -2,
            "y": 1,
            "z": 2,
            "elements": [
                "appliedenergistics2:sky_stone_small_brick_slab@0"
            ]
        },
        {
            "x": -1,
            "y": 3,
            "z": 3,
            "elements": [
                "appliedenergistics2:sky_stone_small_brick_slab@8"
            ]
        },
        {
            "x": 0,
            "y": 5,
            "z": 4,
            "elements": [
                "appliedenergistics2:quartz_glass@0"
            ]
        },
        {
            "x": 1,
            "y": 7,
            "z": 5,
            "elements": [
                "appliedenergistics2:sky_stone_small_brick_slab@0"
            ]
        },
        {
            "x": -2,
            "y": -1,
            "z": 1,
            "elements": [
                "mekanism:plasticfence@8"
            ]
        },
        {
            "x": -1,
            "y": 1,
            "z": 2,
            "elements": [
                "appliedenergistics2:quartz_pillar@1"
            ]
        },
        {
            "x": 0,
            "y": 3,
            "z": 3,
            "elements": [
                "appliedenergistics2:quartz_pillar@1"
            ]
        },
        {
            "x": 1,
            "y": 5,
            "z": 4,
            "elements": [
                "appliedenergistics2:quartz_glass@0"
            ]
        },
        {
            "x": -1,
            "y": -1,
            "z": 1,
            "elements": [
                "appliedenergistics2:sky_stone_small_brick@0"
            ]
        },
        {
            "x": 1,
            "y": 3,
            "z": 3,
            "elements": [
                "appliedenergistics2:sky_stone_small_brick_slab@8"
            ]
        },
        {
            "x": 2,
            "y": 5,
            "z": 4,
            "elements": [
                "appliedenergistics2:sky_stone_small_brick_slab@8"
            ]
        },
        {
            "x": 0,
            "y": -1,
            "z": 1,
            "elements": [
                "appliedenergistics2:sky_stone_small_brick@0"
            ]
        },
        {
            "x": 1,
            "y": 1,
            "z": 2,
            "elements": [
                "appliedenergistics2:quartz_pillar@1"
            ]
        },
        {
            "x": 1,
            "y": -1,
            "z": 1,
            "elements": [
                "appliedenergistics2:sky_stone_small_brick@0"
            ]
        },
        {
            "x": 2,
            "y": 1,
            "z": 2,
            "elements": [
                "appliedenergistics2:sky_stone_small_brick_slab@0"
            ]
        },
        {
            "x": 2,
            "y": -1,
            "z": 1,
            "elements": [
                "mekanism:plasticfence@8"
            ]
        },
        {
            "x": 3,
            "y": -1,
            "z": 1,
            "elements": [
                "appliedenergistics2:sky_stone_small_brick_stairs@1"
            ]
        },
        {
            "x": 5,
            "y": 3,
            "z": 3,
            "elements": [
                "appliedenergistics2:sky_stone_small_brick_slab@8"
            ]
        },
        {
            "x": -5,
            "y": 1,
            "z": -1,
            "elements": [
                "appliedenergistics2:sky_stone_small_brick@0"
            ]
        },
        {
            "x": 5,
            "y": 0,
            "z": -1,
            "elements": [
                "appliedenergistics2:sky_stone_small_brick@0"
            ]
        },
        {
            "x": -5,
            "y": 2,
            "z": 2,
            "elements": [
                "minecraft:sea_lantern@0"
            ]
        },
        {
            "x": -2,
            "y": 6,
            "z": 4,
            "elements": [
                "appliedenergistics2:quartz_glass@0"
            ]
        },
        {
            "x": -2,
            "y": 4,
            "z": 3,
            "elements": [
                "appliedenergistics2:sky_stone_small_brick_slab@8"
            ]
        },
        {
            "x": -1,
            "y": 4,
            "z": 3,
            "elements": [
                "mekanism:reinforcedplasticblock@8"
            ]
        },
        {
            "x": -2,
            "y": 0,
            "z": 1,
            "elements": [
                "mekanism:plasticfence@8"
            ]
        },
        {
            "x": -1,
            "y": 2,
            "z": 2,
            "elements": [
                "appliedenergistics2:quartz_pillar@1"
            ]
        },
        {
            "x": 0,
            "y": 4,
            "z": 3,
            "elements": [
                "appliedenergistics2:sky_stone_small_brick_stairs@2"
            ]
        },
        {
            "x": -1,
            "y": 0,
            "z": 1,
            "elements": [
                "appliedenergistics2:sky_stone_small_brick@0"
            ]
        },
        {
            "x": 1,
            "y": 4,
            "z": 3,
            "elements": [
                "mekanism:reinforcedplasticblock@8"
            ]
        },
        {
            "x": 2,
            "y": 6,
            "z": 4,
            "elements": [
                "appliedenergistics2:quartz_glass@0"
            ]
        },
        {
            "x": 0,
            "y": 0,
            "z": 1,
            "elements": [
                "appliedenergistics2:quartz_pillar@1"
            ]
        },
        {
            "x": 1,
            "y": 2,
            "z": 2,
            "elements": [
                "appliedenergistics2:quartz_pillar@1"
            ]
        },
        {
            "x": 2,
            "y": 4,
            "z": 3,
            "elements": [
                "appliedenergistics2:sky_stone_small_brick_slab@8"
            ]
        },
        {
            "x": 1,
            "y": 0,
            "z": 1,
            "elements": [
                "appliedenergistics2:sky_stone_small_brick@0"
            ]
        },
        {
            "x": 2,
            "y": 0,
            "z": 1,
            "elements": [
                "mekanism:plasticfence@8"
            ]
        },
        {
            "x": -5,
            "y": 0,
            "z": -1,
            "elements": [
                "appliedenergistics2:sky_stone_small_brick@0"
            ]
        },
        {
            "x": 5,
            "y": 2,
            "z": 2,
            "elements": [
                "minecraft:sea_lantern@0"
            ]
        },
        {
            "x": 5,
            "y": -1,
            "z": -1,
            "elements": [
                "modularmachinery:blockcasing@4"
            ]
        },
        {
            "x": -5,
            "y": 3,
            "z": 2,
            "elements": [
                "appliedenergistics2:sky_stone_small_brick@0"
            ]
        },
        {
            "x": -4,
            "y": 3,
            "z": 2,
            "elements": [
                "appliedenergistics2:sky_stone_small_brick_slab@8"
            ]
        },
        {
            "x": -3,
            "y": 5,
            "z": 3,
            "elements": [
                "appliedenergistics2:sky_stone_small_brick_slab@8"
            ]
        },
        {
            "x": -2,
            "y": 7,
            "z": 4,
            "elements": [
                "appliedenergistics2:sky_stone_small_brick_slab@0"
            ]
        },
        {
            "x": -3,
            "y": 3,
            "z": 2,
            "elements": [
                "appliedenergistics2:sky_stone_small_brick_slab@8"
            ]
        },
        {
            "x": -2,
            "y": 5,
            "z": 3,
            "elements": [
                "appliedenergistics2:quartz_glass@0"
            ]
        },
        {
            "x": -1,
            "y": 7,
            "z": 4,
            "elements": [
                "appliedenergistics2:quartz_glass@0"
            ]
        },
        {
            "x": 2,
            "y": -1,
            "z": -1,
            "elements": [
                "appliedenergistics2:sky_stone_small_brick_stairs@1"
            ]
        },
        {
            "x": -2,
            "y": 3,
            "z": 2,
            "elements": [
                "appliedenergistics2:sky_stone_small_brick_stairs@4"
            ]
        },
        {
            "x": 0,
            "y": 7,
            "z": 4,
            "elements": [
                "appliedenergistics2:quartz_glass@0"
            ]
        },
        {
            "x": 1,
            "y": -1,
            "z": -1,
            "elements": [
                "appliedenergistics2:sky_stone_small_brick_stairs@2"
            ]
        },
        {
            "x": -2,
            "y": 1,
            "z": 1,
            "elements": [
                "appliedenergistics2:sky_stone_small_brick_slab@0"
            ]
        },
        {
            "x": -1,
            "y": 3,
            "z": 2,
            "elements": [
                "appliedenergistics2:quartz_pillar@1"
            ]
        },
        {
            "x": 1,
            "y": 7,
            "z": 4,
            "elements": [
                "appliedenergistics2:quartz_glass@0"
            ]
        },
        {
            "x": -1,
            "y": 1,
            "z": 1,
            "elements": [
                "appliedenergistics2:sky_stone_small_brick_slab@0"
            ]
        },
        {
            "x": 2,
            "y": 7,
            "z": 4,
            "elements": [
                "appliedenergistics2:sky_stone_small_brick_slab@0"
            ]
        },
        {
            "x": -1,
            "y": -1,
            "z": -1,
            "elements": [
                "appliedenergistics2:sky_stone_small_brick_stairs@2"
            ]
        },
        {
            "x": 0,
            "y": 1,
            "z": 1,
            "elements": [
                "appliedenergistics2:quartz_pillar@1"
            ]
        },
        {
            "x": 1,
            "y": 3,
            "z": 2,
            "elements": [
                "appliedenergistics2:quartz_pillar@1"
            ]
        },
        {
            "x": 2,
            "y": 5,
            "z": 3,
            "elements": [
                "appliedenergistics2:quartz_glass@0"
            ]
        },
        {
            "x": -2,
            "y": -1,
            "z": -1,
            "elements": [
                "appliedenergistics2:sky_stone_small_brick_stairs@0"
            ]
        },
        {
            "x": 1,
            "y": 1,
            "z": 1,
            "elements": [
                "appliedenergistics2:sky_stone_small_brick_slab@0"
            ]
        },
        {
            "x": 2,
            "y": 3,
            "z": 2,
            "elements": [
                "appliedenergistics2:sky_stone_small_brick_stairs@5"
            ]
        },
        {
            "x": 3,
            "y": 5,
            "z": 3,
            "elements": [
                "appliedenergistics2:sky_stone_small_brick_slab@8"
            ]
        },
        {
            "x": 2,
            "y": 1,
            "z": 1,
            "elements": [
                "appliedenergistics2:sky_stone_small_brick_slab@0"
            ]
        },
        {
            "x": 3,
            "y": 3,
            "z": 2,
            "elements": [
                "appliedenergistics2:sky_stone_small_brick_slab@8"
            ]
        },
        {
            "x": 4,
            "y": 3,
            "z": 2,
            "elements": [
                "appliedenergistics2:sky_stone_small_brick_slab@8"
            ]
        },
        {
            "x": -5,
            "y": -1,
            "z": -1,
            "elements": [
                "modularmachinery:blockcasing@4"
            ]
        },
        {
            "x": 5,
            "y": 3,
            "z": 2,
            "elements": [
                "appliedenergistics2:sky_stone_small_brick@0"
            ]
        },
        {
            "x": -5,
            "y": 4,
            "z": 2,
            "elements": [
                "mekanism:plasticfence@8"
            ]
        },
        {
            "x": -4,
            "y": 4,
            "z": 2,
            "elements": [
                "mekanism:plasticfence@8"
            ]
        },
        {
            "x": -3,
            "y": 6,
            "z": 3,
            "elements": [
                "appliedenergistics2:quartz_glass@0"
            ]
        },
        {
            "x": -3,
            "y": 4,
            "z": 2,
            "elements": [
                "mekanism:plasticfence@8"
            ]
        },
        {
            "x": -1,
            "y": 8,
            "z": 4,
            "elements": [
                "appliedenergistics2:sky_stone_small_brick_stairs@3"
            ]
        },
        {
            "x": -2,
            "y": 4,
            "z": 2,
            "elements": [
                "mekanism:reinforcedplasticblock@8"
            ]
        },
        {
            "x": 0,
            "y": 8,
            "z": 4,
            "elements": [
                "appliedenergistics2:sky_stone_small_brick_slab@0"
            ]
        },
        {
            "x": -1,
            "y": 4,
            "z": 2,
            "elements": [
                "appliedenergistics2:sky_stone_small_brick_stairs@1"
            ]
        },
        {
            "x": 1,
            "y": 8,
            "z": 4,
            "elements": [
                "appliedenergistics2:sky_stone_small_brick_stairs@3"
            ]
        },
        {
            "x": 0,
            "y": 2,
            "z": 1,
            "elements": [
                "appliedenergistics2:quartz_pillar@1"
            ]
        },
        {
            "x": 1,
            "y": 4,
            "z": 2,
            "elements": [
                "appliedenergistics2:sky_stone_small_brick_stairs@0"
            ]
        }
    ]}