{
    "registryname": "Energy_crystal",
	"localizedname": "§e能量转换§d核晶 α型",
    "color": "FFFFFF",
    "requires-blueprint": true,
    "modifiers": [
        {
            "elements": "modularmachinery:blockfluidinputhatch@7",
            "x": -4,
            "y": 12,
            "z": 4,
            "description": "将机器左方的流体输入仓换为真空流体输入仓以降低10%流体消耗",
            "modifier": {
                "io": "input",
                "target": "fluid",
                "operation": 1,
                "multiplier": 0.9
            }
        },
        {
            "elements": "modularmachinery:blockfluidinputhatch@7",
            "x": 4,
            "y": 12,
            "z": 4,
            "description": "将机器右方的流体输入仓换为真空流体输入仓以提高10%能量输出,但是会提高35%流体消耗",
            "modifier": [
            {
                "io": "input",
                "target": "fluid",
                "operation": 1,
                "multiplier": 1.35
            },
            {
                "io": "output",
                "target": "energy",
                "operation": 1,
                "multiplier": 1.1
            }
            ]
        },
        {
            "elements": "modularmachinery:blockinputbus@6",
            "x": 0,
            "y": 0,
            "z": 1,
            "description": "将机器控制器后方的物品输入仓换为超级物品输入仓会有5%概率不消耗水晶,但是会降低10%发电量",
            "modifier": [
            {
                "io": "input",
                "target": "item",
                "operation": 0,
                "multiplier": -0.05,
                "affectChance": true
            },
            {
                "io": "output",
                "target": "energy",
                "operation": 1,
                "multiplier": 0.9
            }
            ]
        }
    ],
    "parts": [
        {
            "x": -1,
            "y": 0,
            "z": 0,
            "elements": [
                "appliedenergistics2:chiseled_quartz_stairs@2"
            ]
        },
        {
            "x": 1,
            "y": 0,
            "z": 0,
            "elements": [
                "appliedenergistics2:chiseled_quartz_stairs@2"
            ]
        },
        {
            "x": 6,
            "y": 8,
            "z": 4,
            "elements": [
                "thermalfoundation:glass_alloy@6"
            ]
        },
        {
            "x": 8,
            "y": 8,
            "z": 4,
            "elements": [
                "thermalfoundation:glass_alloy@6"
            ]
        },
        {
            "x": 7,
            "y": 6,
            "z": 3,
            "elements": [
                "modularmachinery:blockcasing@3"
            ]
        },
        {
            "x": -8,
            "y": 9,
            "z": 4,
            "elements": [
                "appliedenergistics2:chiseled_quartz_stairs@0"
            ]
        },
        {
            "x": -7,
            "y": 7,
            "z": 3,
            "elements": [
                "thermalfoundation:glass_alloy@6"
            ]
        },
        {
            "x": -6,
            "y": 9,
            "z": 4,
            "elements": [
                "appliedenergistics2:chiseled_quartz_stairs@1"
            ]
        },
        {
            "x": -2,
            "y": 13,
            "z": 6,
            "elements": [
                "modularmachinery:blockcasing@0"
            ]
        },
        {
            "x": -2,
            "y": 11,
            "z": 5,
            "elements": [
                "thermalfoundation:glass_alloy@6"
            ]
        },
        {
            "x": -1,
            "y": 13,
            "z": 6,
            "elements": [
                "modularmachinery:blockcasing@0"
            ]
        },
        {
            "x": 0,
            "y": 13,
            "z": 6,
            "elements": [
                "modularmachinery:blockcasing@4"
            ]
        },
        {
            "x": -2,
            "y": 9,
            "z": 4,
            "elements": [
                "thermalfoundation:glass_alloy@6"
            ]
        },
        {
            "x": 1,
            "y": 13,
            "z": 6,
            "elements": [
                "modularmachinery:blockcasing@0"
            ]
        },
        {
            "x": -2,
            "y": 7,
            "z": 3,
            "elements": [
                "thermalfoundation:glass_alloy@6"
            ]
        },
        {
            "x": -1,
            "y": 9,
            "z": 4,
            "elements": [
                "enderio:block_alloy_endergy@3"
            ]
        },
        {
            "x": 2,
            "y": 13,
            "z": 6,
            "elements": [
                "modularmachinery:blockcasing@0"
            ]
        },
        {
            "x": 0,
            "y": 9,
            "z": 4,
            "elements": [
                "avaritia:block_resource@2"
            ]
        },
        {
            "x": -1,
            "y": 7,
            "z": 3,
            "elements": [
                "thermalfoundation:storage_alloy@6"
            ]
        },
        {
            "x": 2,
            "y": 11,
            "z": 5,
            "elements": [
                "thermalfoundation:glass_alloy@6"
            ]
        },
        {
            "x": 1,
            "y": 9,
            "z": 4,
            "elements": [
                "enderio:block_alloy_endergy@3"
            ]
        },
        {
            "x": 0,
            "y": 7,
            "z": 3,
            "elements": [
                "botania:storage@1"
            ]
        },
        {
            "x": -1,
            "y": 5,
            "z": 2,
            "elements": [
                "thermalfoundation:glass_alloy@6"
            ]
        },
        {
            "x": 2,
            "y": 9,
            "z": 4,
            "elements": [
                "thermalfoundation:glass_alloy@6"
            ]
        },
        {
            "x": 1,
            "y": 7,
            "z": 3,
            "elements": [
                "thermalfoundation:storage_alloy@6"
            ]
        },
        {
            "x": 0,
            "y": 5,
            "z": 2,
            "elements": [
                "thermalfoundation:glass_alloy@6"
            ]
        },
        {
            "x": 1,
            "y": -1,
            "z": 0,
            "elements": [
                "appliedenergistics2:chiseled_quartz_stairs@6"
            ]
        },
        {
            "x": 0,
            "y": -1,
            "z": 0,
            "elements": [
                "modularmachinery:blockcasing@4"
            ]
        },
        {
            "x": 2,
            "y": 7,
            "z": 3,
            "elements": [
                "thermalfoundation:glass_alloy@6"
            ]
        },
        {
            "x": 1,
            "y": 5,
            "z": 2,
            "elements": [
                "thermalfoundation:glass_alloy@6"
            ]
        },
        {
            "x": -1,
            "y": -1,
            "z": 0,
            "elements": [
                "appliedenergistics2:chiseled_quartz_stairs@6"
            ]
        },
        {
            "x": 6,
            "y": 9,
            "z": 4,
            "elements": [
                "appliedenergistics2:chiseled_quartz_stairs@0"
            ]
        },
        {
            "x": 8,
            "y": 9,
            "z": 4,
            "elements": [
                "appliedenergistics2:chiseled_quartz_stairs@1"
            ]
        },
        {
            "x": 7,
            "y": 7,
            "z": 3,
            "elements": [
                "thermalfoundation:glass_alloy@6"
            ]
        },
        {
            "x": -7,
            "y": 8,
            "z": 3,
            "elements": [
                "thermalfoundation:glass_alloy@6"
            ]
        },
        {
            "x": -4,
            "y": 12,
            "z": 5,
            "elements": [
                "appliedenergistics2:chiseled_quartz_stairs@4"
            ]
        },
        {
            "x": -3,
            "y": 12,
            "z": 5,
            "elements": [
                "appliedenergistics2:chiseled_quartz_stairs@7"
            ]
        },
        {
            "x": -2,
            "y": 12,
            "z": 5,
            "elements": [
                "appliedenergistics2:chiseled_quartz_stairs@7"
            ]
        },
        {
            "x": 0,
            "y": 14,
            "z": 6,
            "elements": [
                "appliedenergistics2:chiseled_quartz_stairs@3"
            ]
        },
        {
            "x": -2,
            "y": 10,
            "z": 4,
            "elements": [
                "thermalfoundation:glass_alloy@6"
            ]
        },
        {
            "x": -1,
            "y": 12,
            "z": 5,
            "elements": [
                "minecraft:iron_block@0"
            ]
        },
        {
            "x": 0,
            "y": 12,
            "z": 5,
            "elements": [
                "minecraft:iron_block@0"
            ]
        },
        {
            "x": -2,
            "y": 8,
            "z": 3,
            "elements": [
                "thermalfoundation:glass_alloy@6"
            ]
        },
        {
            "x": 1,
            "y": 12,
            "z": 5,
            "elements": [
                "minecraft:iron_block@0"
            ]
        },
        {
            "x": 0,
            "y": 10,
            "z": 4,
            "elements": [
                "psi:psi_decorative@2"
            ]
        },
        {
            "x": -1,
            "y": 8,
            "z": 3,
            "elements": [
                "enderio:block_alloy_endergy@3"
            ]
        },
        {
            "x": 2,
            "y": 12,
            "z": 5,
            "elements": [
                "appliedenergistics2:chiseled_quartz_stairs@5"
            ]
        },
        {
            "x": 0,
            "y": 8,
            "z": 3,
            "elements": [
                "draconicevolution:draconic_block@0"
            ]
        },
        {
            "x": -1,
            "y": 6,
            "z": 2,
            "elements": [
                "thermalfoundation:glass_alloy@6"
            ]
        },
        {
            "x": 3,
            "y": 12,
            "z": 5,
            "elements": [
                "appliedenergistics2:chiseled_quartz_stairs@7"
            ]
        },
        {
            "x": 2,
            "y": 10,
            "z": 4,
            "elements": [
                "thermalfoundation:glass_alloy@6"
            ]
        },
        {
            "x": 1,
            "y": 8,
            "z": 3,
            "elements": [
                "enderio:block_alloy_endergy@3"
            ]
        },
        {
            "x": 0,
            "y": 6,
            "z": 2,
            "elements": [
                "minecraft:sea_lantern@0"
            ]
        },
        {
            "x": 4,
            "y": 12,
            "z": 5,
            "elements": [
                "appliedenergistics2:chiseled_quartz_stairs@5"
            ]
        },
        {
            "x": 2,
            "y": 8,
            "z": 3,
            "elements": [
                "thermalfoundation:glass_alloy@6"
            ]
        },
        {
            "x": 1,
            "y": 6,
            "z": 2,
            "elements": [
                "thermalfoundation:glass_alloy@6"
            ]
        },
        {
            "x": 7,
            "y": 8,
            "z": 3,
            "elements": [
                "thermalfoundation:glass_alloy@6"
            ]
        },
        {
            "x": -7,
            "y": 9,
            "z": 3,
            "elements": [
                "appliedenergistics2:chiseled_quartz_stairs@2"
            ]
        },
        {
            "x": -4,
            "y": 13,
            "z": 5,
            "elements": [
                "appliedenergistics2:chiseled_quartz_stairs@0"
            ]
        },
        {
            "x": -4,
            "y": 11,
            "z": 4,
            "elements": [
                "appliedenergistics2:chiseled_quartz_slab@8"
            ]
        },
        {
            "x": -3,
            "y": 13,
            "z": 5,
            "elements": [
                "modularmachinery:blockcasing@0"
            ]
        },
        {
            "x": -3,
            "y": 11,
            "z": 4,
            "elements": [
                "appliedenergistics2:chiseled_quartz_slab@8"
            ]
        },
        {
            "x": -2,
            "y": 13,
            "z": 5,
            "elements": [
                "modularmachinery:blockcasing@0"
            ]
        },
        {
            "x": -2,
            "y": 11,
            "z": 4,
            "elements": [
                "thermalfoundation:glass_alloy@6"
            ]
        },
        {
            "x": -1,
            "y": 13,
            "z": 5,
            "elements": [
                "modularmachinery:blockcasing@0"
            ]
        },
        {
            "x": 0,
            "y": 13,
            "z": 5,
            "elements": [
                "modularmachinery:blockcasing@4"
            ]
        },
        {
            "x": -2,
            "y": 9,
            "z": 3,
            "elements": [
                "thermalfoundation:glass_alloy@6"
            ]
        },
        {
            "x": 1,
            "y": 13,
            "z": 5,
            "elements": [
                "modularmachinery:blockcasing@0"
            ]
        },
        {
            "x": 2,
            "y": 13,
            "z": 5,
            "elements": [
                "modularmachinery:blockcasing@0"
            ]
        },
        {
            "x": 0,
            "y": 9,
            "z": 3,
            "elements": [
                "enderio:block_alloy_endergy@3"
            ]
        },
        {
            "x": -1,
            "y": 7,
            "z": 2,
            "elements": [
                "thermalfoundation:glass_alloy@6"
            ]
        },
        {
            "x": 3,
            "y": 13,
            "z": 5,
            "elements": [
                "modularmachinery:blockcasing@0"
            ]
        },
        {
            "x": 2,
            "y": 11,
            "z": 4,
            "elements": [
                "thermalfoundation:glass_alloy@6"
            ]
        },
        {
            "x": 0,
            "y": 7,
            "z": 2,
            "elements": [
                "thermalfoundation:glass_alloy@6"
            ]
        },
        {
            "x": 4,
            "y": 13,
            "z": 5,
            "elements": [
                "appliedenergistics2:chiseled_quartz_stairs@1"
            ]
        },
        {
            "x": 3,
            "y": 11,
            "z": 4,
            "elements": [
                "appliedenergistics2:chiseled_quartz_slab@8"
            ]
        },
        {
            "x": 2,
            "y": 9,
            "z": 3,
            "elements": [
                "thermalfoundation:glass_alloy@6"
            ]
        },
        {
            "x": 1,
            "y": 7,
            "z": 2,
            "elements": [
                "thermalfoundation:glass_alloy@6"
            ]
        },
        {
            "x": 4,
            "y": 11,
            "z": 4,
            "elements": [
                "appliedenergistics2:chiseled_quartz_slab@8"
            ]
        },
        {
            "x": 7,
            "y": 9,
            "z": 3,
            "elements": [
                "appliedenergistics2:chiseled_quartz_stairs@2"
            ]
        },
        {
            "x": -4,
            "y": 12,
            "z": 4,
            "elements": [
                "modularmachinery:blockfluidinputhatch"
            ]
        },
        {
            "x": -3,
            "y": 12,
            "z": 4,
            "elements": [
                "modularmachinery:blockcasing@5"
            ]
        },
        {
            "x": -2,
            "y": 12,
            "z": 4,
            "elements": [
                "modularmachinery:blockcasing@0"
            ]
        },
        {
            "x": -1,
            "y": 14,
            "z": 5,
            "elements": [
                "modularmachinery:blockcasing@0"
            ]
        },
        {
            "x": -2,
            "y": 10,
            "z": 3,
            "elements": [
                "thermalfoundation:glass_alloy@6"
            ]
        },
        {
            "x": -1,
            "y": 12,
            "z": 4,
            "elements": [
                "minecraft:iron_block@0"
            ]
        },
        {
            "x": 1,
            "y": 14,
            "z": 5,
            "elements": [
                "modularmachinery:blockcasing@0"
            ]
        },
        {
            "x": 0,
            "y": 12,
            "z": 4,
            "elements": [
                "minecraft:iron_block@0"
            ]
        },
        {
            "x": 1,
            "y": 12,
            "z": 4,
            "elements": [
                "minecraft:iron_block@0"
            ]
        },
        {
            "x": -1,
            "y": 8,
            "z": 2,
            "elements": [
                "thermalfoundation:glass_alloy@6"
            ]
        },
        {
            "x": 2,
            "y": 12,
            "z": 4,
            "elements": [
                "modularmachinery:blockcasing@0"
            ]
        },
        {
            "x": 0,
            "y": 8,
            "z": 2,
            "elements": [
                "thermalfoundation:glass_alloy@6"
            ]
        },
        {
            "x": 3,
            "y": 12,
            "z": 4,
            "elements": [
                "modularmachinery:blockcasing@5"
            ]
        },
        {
            "x": 2,
            "y": 10,
            "z": 3,
            "elements": [
                "thermalfoundation:glass_alloy@6"
            ]
        },
        {
            "x": 1,
            "y": 8,
            "z": 2,
            "elements": [
                "thermalfoundation:glass_alloy@6"
            ]
        },
        {
            "x": 4,
            "y": 12,
            "z": 4,
            "elements": [
                "modularmachinery:blockfluidinputhatch"
            ]
        },
        {
            "x": -4,
            "y": 13,
            "z": 4,
            "elements": [
                "modularmachinery:blockcasing@4"
            ]
        },
        {
            "x": -3,
            "y": 13,
            "z": 4,
            "elements": [
                "modularmachinery:blockcasing@4"
            ]
        },
        {
            "x": -2,
            "y": 13,
            "z": 4,
            "elements": [
                "modularmachinery:blockcasing@4"
            ]
        },
        {
            "x": -2,
            "y": 11,
            "z": 3,
            "elements": [
                "thermalfoundation:glass_alloy@6"
            ]
        },
        {
            "x": -1,
            "y": 13,
            "z": 4,
            "elements": [
                "modularmachinery:blockcasing@4"
            ]
        },
        {
            "x": 0,
            "y": 13,
            "z": 4,
            "elements": [
                "minecraft:beacon@0"
            ]
        },
        {
            "x": 1,
            "y": 13,
            "z": 4,
            "elements": [
                "modularmachinery:blockcasing@4"
            ]
        },
        {
            "x": -1,
            "y": 9,
            "z": 2,
            "elements": [
                "thermalfoundation:glass_alloy@6"
            ]
        },
        {
            "x": 2,
            "y": 13,
            "z": 4,
            "elements": [
                "modularmachinery:blockcasing@4"
            ]
        },
        {
            "x": 0,
            "y": 9,
            "z": 2,
            "elements": [
                "thermalfoundation:glass_alloy@6"
            ]
        },
        {
            "x": 3,
            "y": 13,
            "z": 4,
            "elements": [
                "modularmachinery:blockcasing@4"
            ]
        },
        {
            "x": 2,
            "y": 11,
            "z": 3,
            "elements": [
                "thermalfoundation:glass_alloy@6"
            ]
        },
        {
            "x": 1,
            "y": 9,
            "z": 2,
            "elements": [
                "thermalfoundation:glass_alloy@6"
            ]
        },
        {
            "x": 4,
            "y": 13,
            "z": 4,
            "elements": [
                "modularmachinery:blockcasing@4"
            ]
        },
        {
            "x": -4,
            "y": 12,
            "z": 3,
            "elements": [
                "appliedenergistics2:chiseled_quartz_stairs@4"
            ]
        },
        {
            "x": -3,
            "y": 12,
            "z": 3,
            "elements": [
                "appliedenergistics2:chiseled_quartz_stairs@6"
            ]
        },
        {
            "x": -2,
            "y": 14,
            "z": 4,
            "elements": [
                "appliedenergistics2:chiseled_quartz_stairs@0"
            ]
        },

        {
            "x": -2,
            "y": 12,
            "z": 3,
            "elements": [
                "appliedenergistics2:chiseled_quartz_stairs@4"
            ]
        },
        {
            "x": -1,
            "y": 12,
            "z": 3,
            "elements": [
                "minecraft:iron_block@0"
            ]
        },
        {
            "x": 0,
            "y": 12,
            "z": 3,
            "elements": [
                "minecraft:iron_block@0"
            ]
        },
        {
            "x": -1,
            "y": 10,
            "z": 2,
            "elements": [
                "thermalfoundation:glass_alloy@6"
            ]
        },
        {
            "x": 2,
            "y": 14,
            "z": 4,
            "elements": [
                "appliedenergistics2:chiseled_quartz_stairs@1"
            ]
        },
        {
            "x": 1,
            "y": 12,
            "z": 3,
            "elements": [
                "minecraft:iron_block@0"
            ]
        },
        {
            "x": 0,
            "y": 10,
            "z": 2,
            "elements": [
                "thermalfoundation:glass_alloy@6"
            ]
        },
        {
            "x": 2,
            "y": 12,
            "z": 3,
            "elements": [
                "appliedenergistics2:chiseled_quartz_stairs@6"
            ]
        },
        {
            "x": 1,
            "y": 10,
            "z": 2,
            "elements": [
                "thermalfoundation:glass_alloy@6"
            ]
        },
        {
            "x": 3,
            "y": 12,
            "z": 3,
            "elements": [
                "appliedenergistics2:chiseled_quartz_stairs@6"
            ]
        },
        {
            "x": 4,
            "y": 12,
            "z": 3,
            "elements": [
                "appliedenergistics2:chiseled_quartz_stairs@5"
            ]
        },
        {
            "x": -4,
            "y": 13,
            "z": 3,
            "elements": [
                "appliedenergistics2:chiseled_quartz_stairs@0"
            ]
        },
        {
            "x": -3,
            "y": 13,
            "z": 3,
            "elements": [
                "modularmachinery:blockcasing@0"
            ]
        },
        {
            "x": -2,
            "y": 13,
            "z": 3,
            "elements": [
                "modularmachinery:blockcasing@0"
            ]
        },
        {
            "x": -1,
            "y": 13,
            "z": 3,
            "elements": [
                "modularmachinery:blockcasing@0"
            ]
        },
        {
            "x": 0,
            "y": 13,
            "z": 3,
            "elements": [
                "modularmachinery:blockcasing@4"
            ]
        },
        {
            "x": -1,
            "y": 11,
            "z": 2,
            "elements": [
                "thermalfoundation:glass_alloy@6"
            ]
        },
        {
            "x": 1,
            "y": 13,
            "z": 3,
            "elements": [
                "modularmachinery:blockcasing@0"
            ]
        },
        {
            "x": 0,
            "y": 11,
            "z": 2,
            "elements": [
                "thermalfoundation:glass_alloy@6"
            ]
        },
        {
            "x": 2,
            "y": 13,
            "z": 3,
            "elements": [
                "modularmachinery:blockcasing@0"
            ]
        },
        {
            "x": 1,
            "y": 11,
            "z": 2,
            "elements": [
                "thermalfoundation:glass_alloy@6"
            ]
        },
        {
            "x": 3,
            "y": 13,
            "z": 3,
            "elements": [
                "modularmachinery:blockcasing@0"
            ]
        },
        {
            "x": 4,
            "y": 13,
            "z": 3,
            "elements": [
                "appliedenergistics2:chiseled_quartz_stairs@1"
            ]
        },
        {
            "x": -2,
            "y": 12,
            "z": 2,
            "elements": [
                "appliedenergistics2:chiseled_quartz_stairs@4"
            ]
        },
        {
            "x": -1,
            "y": 14,
            "z": 3,
            "elements": [
                "modularmachinery:blockcasing@0"
            ]
        },
        {
            "x": -1,
            "y": 12,
            "z": 2,
            "elements": [
                "appliedenergistics2:chiseled_quartz_block@0"
            ]
        },
        {
            "x": 1,
            "y": 14,
            "z": 3,
            "elements": [
                "modularmachinery:blockcasing@0"
            ]
        },
        {
            "x": 0,
            "y": 12,
            "z": 2,
            "elements": [
                "modularmachinery:blockcasing@0"
            ]
        },
        {
            "x": 1,
            "y": 12,
            "z": 2,
            "elements": [
                "appliedenergistics2:chiseled_quartz_block@0"
            ]
        },
        {
            "x": 2,
            "y": 12,
            "z": 2,
            "elements": [
                "appliedenergistics2:chiseled_quartz_stairs@5"
            ]
        },
        {
            "x": -2,
            "y": 13,
            "z": 2,
            "elements": [
                "modularmachinery:blockcasing@0"
            ]
        },
        {
            "x": -1,
            "y": 13,
            "z": 2,
            "elements": [
                "modularmachinery:blockcasing@0"
            ]
        },
        {
            "x": 0,
            "y": 13,
            "z": 2,
            "elements": [
                "modularmachinery:blockcasing@4"
            ]
        },
        {
            "x": 1,
            "y": 13,
            "z": 2,
            "elements": [
                "modularmachinery:blockcasing@0"
            ]
        },
        {
            "x": 0,
            "y": 11,
            "z": 1,
            "elements": [
                "appliedenergistics2:chiseled_quartz_slab@8"
            ]
        },
        {
            "x": 2,
            "y": 13,
            "z": 2,
            "elements": [
                "modularmachinery:blockcasing@0"
            ]
        },
        {
            "x": 0,
            "y": 14,
            "z": 2,
            "elements": [
                "appliedenergistics2:chiseled_quartz_stairs@2"
            ]
        },
        {
            "x": -1,
            "y": 12,
            "z": 1,
            "elements": [
                "appliedenergistics2:chiseled_quartz_stairs@4"
            ]
        },
        {
            "x": 0,
            "y": 12,
            "z": 1,
            "elements": [
                "modularmachinery:blockcasing@5"
            ]
        },
        {
            "x": 1,
            "y": 12,
            "z": 1,
            "elements": [
                "appliedenergistics2:chiseled_quartz_stairs@5"
            ]
        },
        {
            "x": -1,
            "y": 13,
            "z": 1,
            "elements": [
                "modularmachinery:blockcasing@0"
            ]
        },
        {
            "x": 0,
            "y": 13,
            "z": 1,
            "elements": [
                "modularmachinery:blockcasing@4"
            ]
        },
        {
            "x": 1,
            "y": 13,
            "z": 1,
            "elements": [
                "modularmachinery:blockcasing@0"
            ]
        },
        {
            "x": 0,
            "y": 11,
            "z": 0,
            "elements": [
                "appliedenergistics2:chiseled_quartz_slab@8"
            ]
        },
        {
            "x": -1,
            "y": 12,
            "z": 0,
            "elements": [
                "appliedenergistics2:chiseled_quartz_stairs@6"
            ]
        },
        {
            "x": 0,
            "y": 12,
            "z": 0,
            "elements": [
                "modularmachinery:blockinputbus"
            ]
        },
        {
            "x": 1,
            "y": 12,
            "z": 0,
            "elements": [
                "appliedenergistics2:chiseled_quartz_stairs@6"
            ]
        },
        {
            "x": -1,
            "y": 13,
            "z": 0,
            "elements": [
                "appliedenergistics2:chiseled_quartz_stairs@2"
            ]
        },
        {
            "x": 0,
            "y": 13,
            "z": 0,
            "elements": [
                "modularmachinery:blockoutputbus"
            ]
        },
        {
            "x": 1,
            "y": 13,
            "z": 0,
            "elements": [
                "appliedenergistics2:chiseled_quartz_stairs@2"
            ]
        },
        {
            "x": -3,
            "y": -1,
            "z": 9,
            "elements": [
                "appliedenergistics2:chiseled_quartz_stairs@0"
            ]
        },
        {
            "x": -2,
            "y": -1,
            "z": 9,
            "elements": [
                "casings_energy"
            ]
        },
        {
            "x": -1,
            "y": -1,
            "z": 9,
            "elements": [
                "casings_energy"
            ]
        },
        {
            "x": 0,
            "y": -1,
            "z": 9,
            "elements": [
                "casings_energy"
            ]
        },
        {
            "x": 1,
            "y": -1,
            "z": 9,
            "elements": [
                "casings_energy"
            ]
        },
        {
            "x": 2,
            "y": -1,
            "z": 9,
            "elements": [
                "casings_energy"
            ]
        },
        {
            "x": 3,
            "y": -1,
            "z": 9,
            "elements": [
                "appliedenergistics2:chiseled_quartz_stairs@1"
            ]
        },
        {
            "x": -3,
            "y": -1,
            "z": 8,
            "elements": [
                "appliedenergistics2:chiseled_quartz_stairs@0"
            ]
        },
        {
            "x": -2,
            "y": -1,
            "z": 8,
            "elements": [
                "appliedenergistics2:chiseled_quartz_block@0"
            ]
        },
        {
            "x": -1,
            "y": -1,
            "z": 8,
            "elements": [
                "modularmachinery:blockcasing@4"
            ]
        },
        {
            "x": 0,
            "y": -1,
            "z": 8,
            "elements": [
                "modularmachinery:blockcasing@4"
            ]
        },
        {
            "x": 1,
            "y": -1,
            "z": 8,
            "elements": [
                "modularmachinery:blockcasing@4"
            ]
        },
        {
            "x": 2,
            "y": -1,
            "z": 8,
            "elements": [
                "appliedenergistics2:chiseled_quartz_block@0"
            ]
        },
        {
            "x": 3,
            "y": -1,
            "z": 8,
            "elements": [
                "appliedenergistics2:chiseled_quartz_stairs@1"
            ]
        },
        {
            "x": -1,
            "y": 0,
            "z": 8,
            "elements": [
                "appliedenergistics2:chiseled_quartz_stairs@3"
            ]
        },
        {
            "x": 0,
            "y": 0,
            "z": 8,
            "elements": [
                "appliedenergistics2:chiseled_quartz_stairs@3"
            ]
        },
        {
            "x": 1,
            "y": 0,
            "z": 8,
            "elements": [
                "appliedenergistics2:chiseled_quartz_stairs@3"
            ]
        },
        {
            "x": -1,
            "y": -1,
            "z": 7,
            "elements": [
                "modularmachinery:blockcasing@0"
            ]
        },
        {
            "x": 0,
            "y": -1,
            "z": 7,
            "elements": [
                "modularmachinery:blockcasing@4"
            ]
        },
        {
            "x": 1,
            "y": -1,
            "z": 7,
            "elements": [
                "modularmachinery:blockcasing@0"
            ]
        },
        {
            "x": -1,
            "y": 0,
            "z": 7,
            "elements": [
                "appliedenergistics2:chiseled_quartz_stairs@0"
            ]
        },
        {
            "x": 0,
            "y": 0,
            "z": 7,
            "elements": [
                "modularmachinery:blockcasing@5"
            ]
        },
        {
            "x": 1,
            "y": 0,
            "z": 7,
            "elements": [
                "appliedenergistics2:chiseled_quartz_stairs@1"
            ]
        },
        {
            "x": -2,
            "y": -1,
            "z": 6,
            "elements": [
                "modularmachinery:blockcasing@0"
            ]
        },
        {
            "x": -1,
            "y": -1,
            "z": 6,
            "elements": [
                "modularmachinery:blockcasing@0"
            ]
        },
        {
            "x": 0,
            "y": -1,
            "z": 6,
            "elements": [
                "modularmachinery:blockcasing@4"
            ]
        },
        {
            "x": 1,
            "y": -1,
            "z": 6,
            "elements": [
                "modularmachinery:blockcasing@0"
            ]
        },
        {
            "x": 2,
            "y": -1,
            "z": 6,
            "elements": [
                "modularmachinery:blockcasing@0"
            ]
        },
        {
            "x": -2,
            "y": 0,
            "z": 6,
            "elements": [
                "appliedenergistics2:chiseled_quartz_stairs@0"
            ]
        },
        {
            "x": -1,
            "y": 0,
            "z": 6,
            "elements": [
                "appliedenergistics2:chiseled_quartz_block@0"
            ]
        },
        {
            "x": 0,
            "y": 0,
            "z": 6,
            "elements": [
                "modularmachinery:blockcasing@0"
            ]
        },
        {
            "x": 1,
            "y": 0,
            "z": 6,
            "elements": [
                "appliedenergistics2:chiseled_quartz_block@0"
            ]
        },
        {
            "x": 2,
            "y": 0,
            "z": 6,
            "elements": [
                "appliedenergistics2:chiseled_quartz_stairs@1"
            ]
        },
        {
            "x": -4,
            "y": -1,
            "z": 5,
            "elements": [
                "appliedenergistics2:chiseled_quartz_stairs@4"
            ]
        },
        {
            "x": -3,
            "y": -1,
            "z": 5,
            "elements": [
                "modularmachinery:blockcasing@0"
            ]
        },
        {
            "x": -2,
            "y": -1,
            "z": 5,
            "elements": [
                "modularmachinery:blockcasing@0"
            ]
        },
        {
            "x": -1,
            "y": 1,
            "z": 6,
            "elements": [
                "thermalfoundation:glass_alloy@6"
            ]
        },
        {
            "x": 0,
            "y": 1,
            "z": 6,
            "elements": [
                "thermalfoundation:glass_alloy@6"
            ]
        },
        {
            "x": -1,
            "y": -1,
            "z": 5,
            "elements": [
                "modularmachinery:blockcasing@0"
            ]
        },
        {
            "x": 0,
            "y": -1,
            "z": 5,
            "elements": [
                "modularmachinery:blockcasing@4"
            ]
        },
        {
            "x": 1,
            "y": 1,
            "z": 6,
            "elements": [
                "thermalfoundation:glass_alloy@6"
            ]
        },
        {
            "x": 1,
            "y": -1,
            "z": 5,
            "elements": [
                "modularmachinery:blockcasing@0"
            ]
        },
        {
            "x": 2,
            "y": -1,
            "z": 5,
            "elements": [
                "modularmachinery:blockcasing@0"
            ]
        },
        {
            "x": 3,
            "y": -1,
            "z": 5,
            "elements": [
                "modularmachinery:blockcasing@0"
            ]
        },
        {
            "x": 4,
            "y": -1,
            "z": 5,
            "elements": [
                "appliedenergistics2:chiseled_quartz_stairs@5"
            ]
        },
        {
            "x": -4,
            "y": 0,
            "z": 5,
            "elements": [
                "appliedenergistics2:chiseled_quartz_stairs@0"
            ]
        },
        {
            "x": -3,
            "y": 0,
            "z": 5,
            "elements": [
                "appliedenergistics2:chiseled_quartz_stairs@3"
            ]
        },
        {
            "x": -2,
            "y": 0,
            "z": 5,
            "elements": [
                "appliedenergistics2:chiseled_quartz_block@0"
            ]
        },
        {
            "x": -1,
            "y": 2,
            "z": 6,
            "elements": [
                "thermalfoundation:glass_alloy@6"
            ]
        },
        {
            "x": 0,
            "y": 2,
            "z": 6,
            "elements": [
                "thermalfoundation:glass_alloy@6"
            ]
        },
        {
            "x": -1,
            "y": 0,
            "z": 5,
            "elements": [
                "modularmachinery:blockcasing@0"
            ]
        },
        {
            "x": 0,
            "y": 0,
            "z": 5,
            "elements": [
                "appliedenergistics2:chiseled_quartz_block@0"
            ]
        },
        {
            "x": 1,
            "y": 2,
            "z": 6,
            "elements": [
                "thermalfoundation:glass_alloy@6"
            ]
        },
        {
            "x": 1,
            "y": 0,
            "z": 5,
            "elements": [
                "modularmachinery:blockcasing@0"
            ]
        },
        {
            "x": 2,
            "y": 0,
            "z": 5,
            "elements": [
                "appliedenergistics2:chiseled_quartz_block@0"
            ]
        },
        {
            "x": 3,
            "y": 0,
            "z": 5,
            "elements": [
                "appliedenergistics2:chiseled_quartz_stairs@3"
            ]
        },
        {
            "x": 4,
            "y": 0,
            "z": 5,
            "elements": [
                "appliedenergistics2:chiseled_quartz_stairs@1"
            ]
        },
        {
            "x": -4,
            "y": -1,
            "z": 4,
            "elements": [
                "modularmachinery:blockcasing@4"
            ]
        },
        {
            "x": -3,
            "y": -1,
            "z": 4,
            "elements": [
                "modularmachinery:blockcasing@4"
            ]
        },
        {
            "x": -2,
            "y": 1,
            "z": 5,
            "elements": [
                "thermalfoundation:glass_alloy@6"
            ]
        },
        {
            "x": -1,
            "y": 3,
            "z": 6,
            "elements": [
                "thermalfoundation:glass_alloy@6"
            ]
        },
        {
            "x": 0,
            "y": 3,
            "z": 6,
            "elements": [
                "thermalfoundation:glass_alloy@6"
            ]
        },
        {
            "x": -2,
            "y": -1,
            "z": 4,
            "elements": [
                "modularmachinery:blockcasing@4"
            ]
        },
        {
            "x": 1,
            "y": 3,
            "z": 6,
            "elements": [
                "thermalfoundation:glass_alloy@6"
            ]
        },
        {
            "x": -1,
            "y": -1,
            "z": 4,
            "elements": [
                "modularmachinery:blockcasing@4"
            ]
        },
        {
            "x": 0,
            "y": -1,
            "z": 4,
            "elements": [
                "modularmachinery:blockcasing@4"
            ]
        },
        {
            "x": 2,
            "y": 1,
            "z": 5,
            "elements": [
                "thermalfoundation:glass_alloy@6"
            ]
        },
        {
            "x": 1,
            "y": -1,
            "z": 4,
            "elements": [
                "modularmachinery:blockcasing@4"
            ]
        },
        {
            "x": 2,
            "y": -1,
            "z": 4,
            "elements": [
                "modularmachinery:blockcasing@4"
            ]
        },
        {
            "x": 3,
            "y": -1,
            "z": 4,
            "elements": [
                "modularmachinery:blockcasing@4"
            ]
        },
        {
            "x": 4,
            "y": -1,
            "z": 4,
            "elements": [
                "modularmachinery:blockcasing@4"
            ]
        },
        {
            "x": -4,
            "y": 0,
            "z": 4,
            "elements": [
                "modularmachinery:blockfluidoutputhatch"
            ]
        },
        {
            "x": -3,
            "y": 0,
            "z": 4,
            "elements": [
                "modularmachinery:blockcasing@5"
            ]
        },
        {
            "x": -2,
            "y": 2,
            "z": 5,
            "elements": [
                "thermalfoundation:glass_alloy@6"
            ]
        },
        {
            "x": -1,
            "y": 4,
            "z": 6,
            "elements": [
                "thermalfoundation:glass_alloy@6"
            ]
        },
        {
            "x": 0,
            "y": 4,
            "z": 6,
            "elements": [
                "thermalfoundation:glass_alloy@6"
            ]
        },
        {
            "x": -2,
            "y": 0,
            "z": 4,
            "elements": [
                "modularmachinery:blockcasing@0"
            ]
        },
        {
            "x": 1,
            "y": 4,
            "z": 6,
            "elements": [
                "thermalfoundation:glass_alloy@6"
            ]
        },
        {
            "x": -1,
            "y": 0,
            "z": 4,
            "elements": [
                "appliedenergistics2:chiseled_quartz_block@0"
            ]
        },
        {
            "x": 0,
            "y": 0,
            "z": 4,
            "elements": [
                "minecraft:sea_lantern@0"
            ]
        },
        {
            "x": 2,
            "y": 2,
            "z": 5,
            "elements": [
                "thermalfoundation:glass_alloy@6"
            ]
        },
        {
            "x": 1,
            "y": 0,
            "z": 4,
            "elements": [
                "appliedenergistics2:chiseled_quartz_block@0"
            ]
        },
        {
            "x": 2,
            "y": 0,
            "z": 4,
            "elements": [
                "modularmachinery:blockcasing@0"
            ]
        },
        {
            "x": 3,
            "y": 0,
            "z": 4,
            "elements": [
                "modularmachinery:blockcasing@5"
            ]
        },
        {
            "x": 4,
            "y": 0,
            "z": 4,
            "elements": [
                "modularmachinery:blockfluidoutputhatch"
            ]
        },
        {
            "x": -7,
            "y": 3,
            "z": 5,
            "elements": [
                "appliedenergistics2:chiseled_quartz_stairs@7"
            ]
        },
        {
            "x": -4,
            "y": 1,
            "z": 4,
            "elements": [
                "appliedenergistics2:chiseled_quartz_slab@0"
            ]
        },
        {
            "x": -4,
            "y": -1,
            "z": 3,
            "elements": [
                "appliedenergistics2:chiseled_quartz_stairs@4"
            ]
        },
        {
            "x": -3,
            "y": 1,
            "z": 4,
            "elements": [
                "appliedenergistics2:chiseled_quartz_slab@0"
            ]
        },
        {
            "x": -2,
            "y": 3,
            "z": 5,
            "elements": [
                "thermalfoundation:glass_alloy@6"
            ]
        },
        {
            "x": -1,
            "y": 5,
            "z": 6,
            "elements": [
                "thermalfoundation:glass_alloy@6"
            ]
        },
        {
            "x": 0,
            "y": 5,
            "z": 6,
            "elements": [
                "thermalfoundation:glass_alloy@6"
            ]
        },
        {
            "x": -3,
            "y": -1,
            "z": 3,
            "elements": [
                "modularmachinery:blockcasing@0"
            ]
        },
        {
            "x": -2,
            "y": 1,
            "z": 4,
            "elements": [
                "thermalfoundation:glass_alloy@6"
            ]
        },
        {
            "x": 1,
            "y": 5,
            "z": 6,
            "elements": [
                "thermalfoundation:glass_alloy@6"
            ]
        },
        {
            "x": 0,
            "y": 3,
            "z": 5,
            "elements": [
                "enderio:block_alloy_endergy@3"
            ]
        },
        {
            "x": -2,
            "y": -1,
            "z": 3,
            "elements": [
                "modularmachinery:blockcasing@0"
            ]
        },
        {
            "x": -1,
            "y": -1,
            "z": 3,
            "elements": [
                "modularmachinery:blockcasing@0"
            ]
        },
        {
            "x": 0,
            "y": -1,
            "z": 3,
            "elements": [
                "modularmachinery:blockcasing@4"
            ]
        },
        {
            "x": 2,
            "y": 3,
            "z": 5,
            "elements": [
                "thermalfoundation:glass_alloy@6"
            ]
        },
        {
            "x": 2,
            "y": 1,
            "z": 4,
            "elements": [
                "thermalfoundation:glass_alloy@6"
            ]
        },
        {
            "x": 1,
            "y": -1,
            "z": 3,
            "elements": [
                "modularmachinery:blockcasing@0"
            ]
        },
        {
            "x": 3,
            "y": 1,
            "z": 4,
            "elements": [
                "appliedenergistics2:chiseled_quartz_slab@0"
            ]
        },
        {
            "x": 2,
            "y": -1,
            "z": 3,
            "elements": [
                "modularmachinery:blockcasing@0"
            ]
        },
        {
            "x": 4,
            "y": 1,
            "z": 4,
            "elements": [
                "appliedenergistics2:chiseled_quartz_slab@0"
            ]
        },
        {
            "x": 3,
            "y": -1,
            "z": 3,
            "elements": [
                "modularmachinery:blockcasing@0"
            ]
        },
        {
            "x": 4,
            "y": -1,
            "z": 3,
            "elements": [
                "appliedenergistics2:chiseled_quartz_stairs@5"
            ]
        },
        {
            "x": 7,
            "y": 3,
            "z": 5,
            "elements": [
                "appliedenergistics2:chiseled_quartz_stairs@7"
            ]
        },
        {
            "x": -7,
            "y": 4,
            "z": 5,
            "elements": [
                "thermalfoundation:glass_alloy@6"
            ]
        },
        {
            "x": -4,
            "y": 0,
            "z": 3,
            "elements": [
                "appliedenergistics2:chiseled_quartz_stairs@0"
            ]
        },
        {
            "x": -2,
            "y": 4,
            "z": 5,
            "elements": [
                "thermalfoundation:glass_alloy@6"
            ]
        },
        {
            "x": -1,
            "y": 6,
            "z": 6,
            "elements": [
                "thermalfoundation:glass_alloy@6"
            ]
        },
        {
            "x": 0,
            "y": 6,
            "z": 6,
            "elements": [
                "minecraft:sea_lantern@0"
            ]
        },
        {
            "x": -3,
            "y": 0,
            "z": 3,
            "elements": [
                "appliedenergistics2:chiseled_quartz_stairs@2"
            ]
        },
        {
            "x": -2,
            "y": 2,
            "z": 4,
            "elements": [
                "thermalfoundation:glass_alloy@6"
            ]
        },
        {
            "x": -1,
            "y": 4,
            "z": 5,
            "elements": [
                "enderio:block_alloy_endergy@3"
            ]
        },
        {
            "x": 1,
            "y": 6,
            "z": 6,
            "elements": [
                "thermalfoundation:glass_alloy@6"
            ]
        },
        {
            "x": 0,
            "y": 4,
            "z": 5,
            "elements": [
                "draconicevolution:draconic_block@0"
            ]
        },
        {
            "x": -2,
            "y": 0,
            "z": 3,
            "elements": [
                "appliedenergistics2:chiseled_quartz_block@0"
            ]
        },
        {
            "x": 1,
            "y": 4,
            "z": 5,
            "elements": [
                "enderio:block_alloy_endergy@3"
            ]
        },
        {
            "x": 0,
            "y": 2,
            "z": 4,
            "elements": [
                "psi:psi_decorative@2"
            ]
        },
        {
            "x": -1,
            "y": 0,
            "z": 3,
            "elements": [
                "modularmachinery:blockcasing@0"
            ]
        },
        {
            "x": 0,
            "y": 0,
            "z": 3,
            "elements": [
                "modularmachinery:blockcasing@5"
            ]
        },
        {
            "x": 2,
            "y": 4,
            "z": 5,
            "elements": [
                "thermalfoundation:glass_alloy@6"
            ]
        },
        {
            "x": 2,
            "y": 2,
            "z": 4,
            "elements": [
                "thermalfoundation:glass_alloy@6"
            ]
        },
        {
            "x": 1,
            "y": 0,
            "z": 3,
            "elements": [
                "modularmachinery:blockcasing@0"
            ]
        },
        {
            "x": 2,
            "y": 0,
            "z": 3,
            "elements": [
                "appliedenergistics2:chiseled_quartz_block@0"
            ]
        },
        {
            "x": 3,
            "y": 0,
            "z": 3,
            "elements": [
                "appliedenergistics2:chiseled_quartz_stairs@2"
            ]
        },
        {
            "x": 4,
            "y": 0,
            "z": 3,
            "elements": [
                "appliedenergistics2:chiseled_quartz_stairs@1"
            ]
        },
        {
            "x": 7,
            "y": 4,
            "z": 5,
            "elements": [
                "thermalfoundation:glass_alloy@6"
            ]
        },
        {
            "x": -8,
            "y": 3,
            "z": 4,
            "elements": [
                "appliedenergistics2:chiseled_quartz_stairs@4"
            ]
        },
        {
            "x": -7,
            "y": 5,
            "z": 5,
            "elements": [
                "thermalfoundation:glass_alloy@6"
            ]
        },
        {
            "x": -6,
            "y": 3,
            "z": 4,
            "elements": [
                "appliedenergistics2:chiseled_quartz_stairs@5"
            ]
        },
        {
            "x": 0,
            "y": 11,
            "z": 8,
            "elements": [
                "appliedenergistics2:chiseled_quartz_slab@8"
            ]
        },
        {
            "x": -2,
            "y": 5,
            "z": 5,
            "elements": [
                "thermalfoundation:glass_alloy@6"
            ]
        },
        {
            "x": -1,
            "y": 7,
            "z": 6,
            "elements": [
                "thermalfoundation:glass_alloy@6"
            ]
        },
        {
            "x": 0,
            "y": 7,
            "z": 6,
            "elements": [
                "thermalfoundation:glass_alloy@6"
            ]
        },
        {
            "x": -2,
            "y": 3,
            "z": 4,
            "elements": [
                "thermalfoundation:glass_alloy@6"
            ]
        },
        {
            "x": -1,
            "y": 5,
            "z": 5,
            "elements": [
                "thermalfoundation:storage_alloy@6"
            ]
        },
        {
            "x": 1,
            "y": 7,
            "z": 6,
            "elements": [
                "thermalfoundation:glass_alloy@6"
            ]
        },
        {
            "x": 0,
            "y": 5,
            "z": 5,
            "elements": [
                "botania:storage@1"
            ]
        },
        {
            "x": -2,
            "y": 1,
            "z": 3,
            "elements": [
                "thermalfoundation:glass_alloy@6"
            ]
        },
        {
            "x": -1,
            "y": 3,
            "z": 4,
            "elements": [
                "enderio:block_alloy_endergy@3"
            ]
        },
        {
            "x": 1,
            "y": 5,
            "z": 5,
            "elements": [
                "thermalfoundation:storage_alloy@6"
            ]
        },
        {
            "x": 0,
            "y": 3,
            "z": 4,
            "elements": [
                "avaritia:block_resource@2"
            ]
        },
        {
            "x": -2,
            "y": -1,
            "z": 2,
            "elements": [
                "modularmachinery:blockcasing@0"
            ]
        },
        {
            "x": 2,
            "y": 5,
            "z": 5,
            "elements": [
                "thermalfoundation:glass_alloy@6"
            ]
        },
        {
            "x": 1,
            "y": 3,
            "z": 4,
            "elements": [
                "enderio:block_alloy_endergy@3"
            ]
        },
        {
            "x": -1,
            "y": -1,
            "z": 2,
            "elements": [
                "modularmachinery:blockcasing@0"
            ]
        },
        {
            "x": 0,
            "y": -1,
            "z": 2,
            "elements": [
                "modularmachinery:blockcasing@4"
            ]
        },
        {
            "x": 2,
            "y": 3,
            "z": 4,
            "elements": [
                "thermalfoundation:glass_alloy@6"
            ]
        },
        {
            "x": 2,
            "y": 1,
            "z": 3,
            "elements": [
                "thermalfoundation:glass_alloy@6"
            ]
        },
        {
            "x": 1,
            "y": -1,
            "z": 2,
            "elements": [
                "modularmachinery:blockcasing@0"
            ]
        },
        {
            "x": 2,
            "y": -1,
            "z": 2,
            "elements": [
                "modularmachinery:blockcasing@0"
            ]
        },
        {
            "x": 7,
            "y": 5,
            "z": 5,
            "elements": [
                "thermalfoundation:glass_alloy@6"
            ]
        },
        {
            "x": 6,
            "y": 3,
            "z": 4,
            "elements": [
                "appliedenergistics2:chiseled_quartz_stairs@4"
            ]
        },

        {
            "x": 8,
            "y": 3,
            "z": 4,
            "elements": [
                "appliedenergistics2:chiseled_quartz_stairs@5"
            ]
        },
        {
            "x": -8,
            "y": 4,
            "z": 4,
            "elements": [
                "thermalfoundation:glass_alloy@6"
            ]
        },
        {
            "x": -7,
            "y": 6,
            "z": 5,
            "elements": [
                "modularmachinery:blockcasing@3"
            ]
        },
        {
            "x": -6,
            "y": 4,
            "z": 4,
            "elements": [
                "thermalfoundation:glass_alloy@6"
            ]
        },
        {
            "x": -1,
            "y": 12,
            "z": 8,
            "elements": [
                "appliedenergistics2:chiseled_quartz_stairs@7"
            ]
        },
        {
            "x": 0,
            "y": 12,
            "z": 8,
            "elements": [
                "modularmachinery:blockenergyinputhatch"
            ]
        },
        {
            "x": 1,
            "y": 12,
            "z": 8,
            "elements": [
                "appliedenergistics2:chiseled_quartz_stairs@7"
            ]
        },
        {
            "x": -2,
            "y": 6,
            "z": 5,
            "elements": [
                "thermalfoundation:glass_alloy@6"
            ]
        },
        {
            "x": -1,
            "y": 8,
            "z": 6,
            "elements": [
                "thermalfoundation:glass_alloy@6"
            ]
        },
        {
            "x": 0,
            "y": 8,
            "z": 6,
            "elements": [
                "thermalfoundation:glass_alloy@6"
            ]
        },
        {
            "x": -2,
            "y": 4,
            "z": 4,
            "elements": [
                "thermalfoundation:glass_alloy@6"
            ]
        },
        {
            "x": -1,
            "y": 6,
            "z": 5,
            "elements": [
                "enderio:block_alloy_endergy@6"
            ]
        },
        {
            "x": 1,
            "y": 8,
            "z": 6,
            "elements": [
                "thermalfoundation:glass_alloy@6"
            ]
        },
        {
            "x": 0,
            "y": 6,
            "z": 5,
            "elements": [
                "botania:storage@1"
            ]
        },
        {
            "x": -2,
            "y": 2,
            "z": 3,
            "elements": [
                "thermalfoundation:glass_alloy@6"
            ]
        },
        {
            "x": -1,
            "y": 4,
            "z": 4,
            "elements": [
                "draconicevolution:draconic_block@0"
            ]
        },
        {
            "x": 1,
            "y": 6,
            "z": 5,
            "elements": [
                "enderio:block_alloy_endergy@6"
            ]
        },
        {
            "x": 0,
            "y": 4,
            "z": 4,
            "elements": [
                "avaritia:block_resource@2"
            ]
        },
        {
            "x": -2,
            "y": 0,
            "z": 2,
            "elements": [
                "appliedenergistics2:chiseled_quartz_stairs@0"
            ]
        },
        {
            "x": 2,
            "y": 6,
            "z": 5,
            "elements": [
                "thermalfoundation:glass_alloy@6"
            ]
        },
        {
            "x": 1,
            "y": 4,
            "z": 4,
            "elements": [
                "draconicevolution:draconic_block@0"
            ]
        },
        {
            "x": -1,
            "y": 0,
            "z": 2,
            "elements": [
                "appliedenergistics2:chiseled_quartz_block@0"
            ]
        },
        {
            "x": 0,
            "y": 0,
            "z": 2,
            "elements": [
                "modularmachinery:blockcasing@5"
            ]
        },
        {
            "x": 2,
            "y": 4,
            "z": 4,
            "elements": [
                "thermalfoundation:glass_alloy@6"
            ]
        },
        {
            "x": 2,
            "y": 2,
            "z": 3,
            "elements": [
                "thermalfoundation:glass_alloy@6"
            ]
        },
        {
            "x": 1,
            "y": 0,
            "z": 2,
            "elements": [
                "appliedenergistics2:chiseled_quartz_block@0"
            ]
        },
        {
            "x": 2,
            "y": 0,
            "z": 2,
            "elements": [
                "appliedenergistics2:chiseled_quartz_stairs@1"
            ]
        },
        {
            "x": 7,
            "y": 6,
            "z": 5,
            "elements": [
                "modularmachinery:blockcasing@3"
            ]
        },
        {
            "x": 6,
            "y": 4,
            "z": 4,
            "elements": [
                "thermalfoundation:glass_alloy@6"
            ]
        },
        {
            "x": 8,
            "y": 4,
            "z": 4,
            "elements": [
                "thermalfoundation:glass_alloy@6"
            ]
        },
        {
            "x": -8,
            "y": 5,
            "z": 4,
            "elements": [
                "modularmachinery:blockcasing@3"
            ]
        },
        {
            "x": -7,
            "y": 7,
            "z": 5,
            "elements": [
                "thermalfoundation:glass_alloy@6"
            ]
        },
        {
            "x": -7,
            "y": 3,
            "z": 3,
            "elements": [
                "appliedenergistics2:chiseled_quartz_stairs@6"
            ]
        },
        {
            "x": -6,
            "y": 5,
            "z": 4,
            "elements": [
                "modularmachinery:blockcasing@3"
            ]
        },
        {
            "x": -1,
            "y": 13,
            "z": 8,
            "elements": [
                "appliedenergistics2:chiseled_quartz_stairs@3"
            ]
        },
        {
            "x": 0,
            "y": 13,
            "z": 8,
            "elements": [
                "modularmachinery:blockcasing@4"
            ]
        },
        {
            "x": 1,
            "y": 13,
            "z": 8,
            "elements": [
                "appliedenergistics2:chiseled_quartz_stairs@3"
            ]
        },
        {
            "x": 0,
            "y": 11,
            "z": 7,
            "elements": [
                "appliedenergistics2:chiseled_quartz_slab@8"
            ]
        },
        {
            "x": -2,
            "y": 7,
            "z": 5,
            "elements": [
                "thermalfoundation:glass_alloy@6"
            ]
        },
        {
            "x": -1,
            "y": 9,
            "z": 6,
            "elements": [
                "thermalfoundation:glass_alloy@6"
            ]
        },
        {
            "x": 0,
            "y": 9,
            "z": 6,
            "elements": [
                "thermalfoundation:glass_alloy@6"
            ]
        },
        {
            "x": -2,
            "y": 5,
            "z": 4,
            "elements": [
                "thermalfoundation:glass_alloy@6"
            ]
        },
        {
            "x": -1,
            "y": 7,
            "z": 5,
            "elements": [
                "thermalfoundation:storage_alloy@6"
            ]
        },
        {
            "x": 1,
            "y": 9,
            "z": 6,
            "elements": [
                "thermalfoundation:glass_alloy@6"
            ]
        },
        {
            "x": 0,
            "y": 7,
            "z": 5,
            "elements": [
                "botania:storage@1"
            ]
        },
        {
            "x": -2,
            "y": 3,
            "z": 3,
            "elements": [
                "thermalfoundation:glass_alloy@6"
            ]
        },
        {
            "x": -1,
            "y": 5,
            "z": 4,
            "elements": [
                "botania:storage@1"
            ]
        },
        {
            "x": 1,
            "y": 7,
            "z": 5,
            "elements": [
                "thermalfoundation:storage_alloy@6"
            ]
        },
        {
            "x": 0,
            "y": 5,
            "z": 4,
            "elements": [
                "avaritia:block_resource@2"
            ]
        },
        {
            "x": 2,
            "y": 7,
            "z": 5,
            "elements": [
                "thermalfoundation:glass_alloy@6"
            ]
        },
        {
            "x": 1,
            "y": 5,
            "z": 4,
            "elements": [
                "botania:storage@1"
            ]
        },
        {
            "x": 0,
            "y": 3,
            "z": 3,
            "elements": [
                "enderio:block_alloy_endergy@3"
            ]
        },
        {
            "x": -1,
            "y": 1,
            "z": 2,
            "elements": [
                "thermalfoundation:glass_alloy@6"
            ]
        },
        {
            "x": 2,
            "y": 5,
            "z": 4,
            "elements": [
                "thermalfoundation:glass_alloy@6"
            ]
        },
        {
            "x": 0,
            "y": 1,
            "z": 2,
            "elements": [
                "thermalfoundation:glass_alloy@6"
            ]
        },
        {
            "x": -1,
            "y": -1,
            "z": 1,
            "elements": [
                "modularmachinery:blockcasing@0"
            ]
        },
        {
            "x": 0,
            "y": -1,
            "z": 1,
            "elements": [
                "modularmachinery:blockcasing@4"
            ]
        },
        {
            "x": 2,
            "y": 3,
            "z": 3,
            "elements": [
                "thermalfoundation:glass_alloy@6"
            ]
        },
        {
            "x": 1,
            "y": 1,
            "z": 2,
            "elements": [
                "thermalfoundation:glass_alloy@6"
            ]
        },
        {
            "x": 1,
            "y": -1,
            "z": 1,
            "elements": [
                "modularmachinery:blockcasing@0"
            ]
        },
        {
            "x": 7,
            "y": 7,
            "z": 5,
            "elements": [
                "thermalfoundation:glass_alloy@6"
            ]
        },
        {
            "x": 6,
            "y": 5,
            "z": 4,
            "elements": [
                "modularmachinery:blockcasing@3"
            ]
        },
        {
            "x": 8,
            "y": 5,
            "z": 4,
            "elements": [
                "modularmachinery:blockcasing@3"
            ]
        },
        {
            "x": 7,
            "y": 3,
            "z": 3,
            "elements": [
                "appliedenergistics2:chiseled_quartz_stairs@6"
            ]
        },
        {
            "x": -8,
            "y": 6,
            "z": 4,
            "elements": [
                "thermalfoundation:glass_alloy@6"
            ]
        },
        {
            "x": -7,
            "y": 8,
            "z": 5,
            "elements": [
                "thermalfoundation:glass_alloy@6"
            ]
        },
        {
            "x": -7,
            "y": 4,
            "z": 3,
            "elements": [
                "thermalfoundation:glass_alloy@6"
            ]
        },
        {
            "x": -6,
            "y": 6,
            "z": 4,
            "elements": [
                "modularmachinery:blockcasing@5"
            ]
        },
        {
            "x": -5,
            "y": 6,
            "z": 4,
            "elements": [
                "modularmachinery:blockcasing@0"
            ]
        },
        {
            "x": -4,
            "y": 6,
            "z": 4,
            "elements": [
                "modularmachinery:blockcasing@5"
            ]
        },
        {
            "x": -1,
            "y": 12,
            "z": 7,
            "elements": [
                "appliedenergistics2:chiseled_quartz_stairs@4"
            ]
        },
        {
            "x": 0,
            "y": 12,
            "z": 7,
            "elements": [
                "modularmachinery:blockcasing@5"
            ]
        },
        {
            "x": -3,
            "y": 6,
            "z": 4,
            "elements": [
                "modularmachinery:blockcasing@0"
            ]
        },
        {
            "x": -2,
            "y": 8,
            "z": 5,
            "elements": [
                "thermalfoundation:glass_alloy@6"
            ]
        },
        {
            "x": -1,
            "y": 10,
            "z": 6,
            "elements": [
                "thermalfoundation:glass_alloy@6"
            ]
        },
        {
            "x": 1,
            "y": 12,
            "z": 7,
            "elements": [
                "appliedenergistics2:chiseled_quartz_stairs@5"
            ]
        },
        {
            "x": 0,
            "y": 10,
            "z": 6,
            "elements": [
                "thermalfoundation:glass_alloy@6"
            ]
        },
        {
            "x": -2,
            "y": 6,
            "z": 4,
            "elements": [
                "minecraft:sea_lantern@0"
            ]
        },
        {
            "x": -1,
            "y": 8,
            "z": 5,
            "elements": [
                "enderio:block_alloy_endergy@3"
            ]
        },
        {
            "x": 1,
            "y": 10,
            "z": 6,
            "elements": [
                "thermalfoundation:glass_alloy@6"
            ]
        },
        {
            "x": 0,
            "y": 8,
            "z": 5,
            "elements": [
                "draconicevolution:draconic_block@0"
            ]
        },
        {
            "x": -2,
            "y": 4,
            "z": 3,
            "elements": [
                "thermalfoundation:glass_alloy@6"
            ]
        },
        {
            "x": -1,
            "y": 6,
            "z": 4,
            "elements": [
                "botania:storage@1"
            ]
        },
        {
            "x": 1,
            "y": 8,
            "z": 5,
            "elements": [
                "enderio:block_alloy_endergy@3"
            ]
        },
        {
            "x": 0,
            "y": 6,
            "z": 4,
            "elements": [
                "extrabotany:blockorichalcos@0"
            ]
        },
        {
            "x": -1,
            "y": 4,
            "z": 3,
            "elements": [
                "enderio:block_alloy_endergy@3"
            ]
        },
        {
            "x": 2,
            "y": 8,
            "z": 5,
            "elements": [
                "thermalfoundation:glass_alloy@6"
            ]
        },
        {
            "x": 1,
            "y": 6,
            "z": 4,
            "elements": [
                "botania:storage@1"
            ]
        },
        {
            "x": 0,
            "y": 4,
            "z": 3,
            "elements": [
                "draconicevolution:draconic_block@0"
            ]
        },
        {
            "x": -1,
            "y": 2,
            "z": 2,
            "elements": [
                "thermalfoundation:glass_alloy@6"
            ]
        },
        {
            "x": 2,
            "y": 6,
            "z": 4,
            "elements": [
                "minecraft:sea_lantern@0"
            ]
        },
        {
            "x": 1,
            "y": 4,
            "z": 3,
            "elements": [
                "enderio:block_alloy_endergy@3"
            ]
        },
        {
            "x": 0,
            "y": 2,
            "z": 2,
            "elements": [
                "thermalfoundation:glass_alloy@6"
            ]
        },
        {
            "x": -1,
            "y": 0,
            "z": 1,
            "elements": [
                "appliedenergistics2:chiseled_quartz_stairs@0"
            ]
        },
        {
            "x": 0,
            "y": 0,
            "z": 1,
            "elements": [
                "modularmachinery:blockinputbus"
            ]
        },
        {
            "x": 3,
            "y": 6,
            "z": 4,
            "elements": [
                "modularmachinery:blockcasing@0"
            ]
        },
        {
            "x": 2,
            "y": 4,
            "z": 3,
            "elements": [
                "thermalfoundation:glass_alloy@6"
            ]
        },
        {
            "x": 1,
            "y": 2,
            "z": 2,
            "elements": [
                "thermalfoundation:glass_alloy@6"
            ]
        },
        {
            "x": 4,
            "y": 6,
            "z": 4,
            "elements": [
                "modularmachinery:blockcasing@5"
            ]
        },
        {
            "x": 1,
            "y": 0,
            "z": 1,
            "elements": [
                "appliedenergistics2:chiseled_quartz_stairs@1"
            ]
        },
        {
            "x": 5,
            "y": 6,
            "z": 4,
            "elements": [
                "modularmachinery:blockcasing@0"
            ]
        },
        {
            "x": 7,
            "y": 8,
            "z": 5,
            "elements": [
                "thermalfoundation:glass_alloy@6"
            ]
        },
        {
            "x": 6,
            "y": 6,
            "z": 4,
            "elements": [
                "modularmachinery:blockcasing@5"
            ]
        },
        {
            "x": 8,
            "y": 6,
            "z": 4,
            "elements": [
                "thermalfoundation:glass_alloy@6"
            ]
        },
        {
            "x": 7,
            "y": 4,
            "z": 3,
            "elements": [
                "thermalfoundation:glass_alloy@6"
            ]
        },
        {
            "x": -8,
            "y": 7,
            "z": 4,
            "elements": [
                "modularmachinery:blockcasing@3"
            ]
        },
        {
            "x": -7,
            "y": 9,
            "z": 5,
            "elements": [
                "appliedenergistics2:chiseled_quartz_stairs@3"
            ]
        },
        {
            "x": -7,
            "y": 5,
            "z": 3,
            "elements": [
                "thermalfoundation:glass_alloy@6"
            ]
        },
        {
            "x": -6,
            "y": 7,
            "z": 4,
            "elements": [
                "modularmachinery:blockcasing@3"
            ]
        },
        {
            "x": -1,
            "y": 13,
            "z": 7,
            "elements": [
                "modularmachinery:blockcasing@0"
            ]
        },
        {
            "x": 0,
            "y": 13,
            "z": 7,
            "elements": [
                "modularmachinery:blockcasing@4"
            ]
        },
        {
            "x": -2,
            "y": 9,
            "z": 5,
            "elements": [
                "thermalfoundation:glass_alloy@6"
            ]
        },
        {
            "x": -1,
            "y": 11,
            "z": 6,
            "elements": [
                "thermalfoundation:glass_alloy@6"
            ]
        },
        {
            "x": 1,
            "y": 13,
            "z": 7,
            "elements": [
                "modularmachinery:blockcasing@0"
            ]
        },
        {
            "x": 0,
            "y": 11,
            "z": 6,
            "elements": [
                "thermalfoundation:glass_alloy@6"
            ]
        },
        {
            "x": -2,
            "y": 7,
            "z": 4,
            "elements": [
                "thermalfoundation:glass_alloy@6"
            ]
        },
        {
            "x": 1,
            "y": 11,
            "z": 6,
            "elements": [
                "thermalfoundation:glass_alloy@6"
            ]
        },
        {
            "x": 0,
            "y": 9,
            "z": 5,
            "elements": [
                "enderio:block_alloy_endergy@3"
            ]
        },
        {
            "x": -2,
            "y": 5,
            "z": 3,
            "elements": [
                "thermalfoundation:glass_alloy@6"
            ]
        },
        {
            "x": -1,
            "y": 7,
            "z": 4,
            "elements": [
                "botania:storage@1"
            ]
        },
        {
            "x": 0,
            "y": 7,
            "z": 4,
            "elements": [
                "avaritia:block_resource@2"
            ]
        },
        {
            "x": -1,
            "y": 5,
            "z": 3,
            "elements": [
                "thermalfoundation:storage_alloy@6"
            ]
        },
        {
            "x": 2,
            "y": 9,
            "z": 5,
            "elements": [
                "thermalfoundation:glass_alloy@6"
            ]
        },
        {
            "x": 1,
            "y": 7,
            "z": 4,
            "elements": [
                "botania:storage@1"
            ]
        },
        {
            "x": 0,
            "y": 5,
            "z": 3,
            "elements": [
                "botania:storage@1"
            ]
        },
        {
            "x": -1,
            "y": 3,
            "z": 2,
            "elements": [
                "thermalfoundation:glass_alloy@6"
            ]
        },
        {
            "x": 2,
            "y": 7,
            "z": 4,
            "elements": [
                "thermalfoundation:glass_alloy@6"
            ]
        },
        {
            "x": 1,
            "y": 5,
            "z": 3,
            "elements": [
                "thermalfoundation:storage_alloy@6"
            ]
        },
        {
            "x": 0,
            "y": 3,
            "z": 2,
            "elements": [
                "thermalfoundation:glass_alloy@6"
            ]
        },
        {
            "x": 2,
            "y": 5,
            "z": 3,
            "elements": [
                "thermalfoundation:glass_alloy@6"
            ]
        },
        {
            "x": 1,
            "y": 3,
            "z": 2,
            "elements": [
                "thermalfoundation:glass_alloy@6"
            ]
        },
        {
            "x": 7,
            "y": 9,
            "z": 5,
            "elements": [
                "appliedenergistics2:chiseled_quartz_stairs@3"
            ]
        },
        {
            "x": 6,
            "y": 7,
            "z": 4,
            "elements": [
                "modularmachinery:blockcasing@3"
            ]
        },
        {
            "x": 8,
            "y": 7,
            "z": 4,
            "elements": [
                "modularmachinery:blockcasing@3"
            ]
        },
        {
            "x": 7,
            "y": 5,
            "z": 3,
            "elements": [
                "thermalfoundation:glass_alloy@6"
            ]
        },
        {
            "x": -8,
            "y": 8,
            "z": 4,
            "elements": [
                "thermalfoundation:glass_alloy@6"
            ]
        },
        {
            "x": -7,
            "y": 6,
            "z": 3,
            "elements": [
                "modularmachinery:blockcasing@3"
            ]
        },
        {
            "x": -6,
            "y": 8,
            "z": 4,
            "elements": [
                "thermalfoundation:glass_alloy@6"
            ]
        },
        {
            "x": -2,
            "y": 12,
            "z": 6,
            "elements": [
                "appliedenergistics2:chiseled_quartz_stairs@4"
            ]
        },
        {
            "x": -2,
            "y": 10,
            "z": 5,
            "elements": [
                "thermalfoundation:glass_alloy@6"
            ]
        },
        {
            "x": -1,
            "y": 12,
            "z": 6,
            "elements": [
                "appliedenergistics2:chiseled_quartz_block@0"
            ]
        },
        {
            "x": 0,
            "y": 12,
            "z": 6,
            "elements": [
                "modularmachinery:blockcasing@0"
            ]
        },
        {
            "x": -2,
            "y": 8,
            "z": 4,
            "elements": [
                "thermalfoundation:glass_alloy@6"
            ]
        },
        {
            "x": 1,
            "y": 12,
            "z": 6,
            "elements": [
                "appliedenergistics2:chiseled_quartz_block@0"
            ]
        },
        {
            "x": -2,
            "y": 6,
            "z": 3,
            "elements": [
                "thermalfoundation:glass_alloy@6"
            ]
        },
        {
            "x": -1,
            "y": 8,
            "z": 4,
            "elements": [
                "draconicevolution:draconic_block@0"
            ]
        },
        {
            "x": 2,
            "y": 12,
            "z": 6,
            "elements": [
                "appliedenergistics2:chiseled_quartz_stairs@7"
            ]
        },
        {
            "x": 0,
            "y": 8,
            "z": 4,
            "elements": [
                "avaritia:block_resource@2"
            ]
        },
        {
            "x": -1,
            "y": 6,
            "z": 3,
            "elements": [
                "enderio:block_alloy_endergy@6"
            ]
        },
        {
            "x": 2,
            "y": 10,
            "z": 5,
            "elements": [
                "thermalfoundation:glass_alloy@6"
            ]
        },
        {
            "x": 1,
            "y": 8,
            "z": 4,
            "elements": [
                "draconicevolution:draconic_block@0"
            ]
        },
        {
            "x": 0,
            "y": 6,
            "z": 3,
            "elements": [
                "botania:storage@1"
            ]
        },
        {
            "x": -1,
            "y": 4,
            "z": 2,
            "elements": [
                "thermalfoundation:glass_alloy@6"
            ]
        },
        {
            "x": 2,
            "y": 8,
            "z": 4,
            "elements": [
                "thermalfoundation:glass_alloy@6"
            ]
        },
        {
            "x": 1,
            "y": 6,
            "z": 3,
            "elements": [
                "enderio:block_alloy_endergy@6"
            ]
        },
        {
            "x": 0,
            "y": 4,
            "z": 2,
            "elements": [
                "thermalfoundation:glass_alloy@6"
            ]
        },
        {
            "x": 2,
            "y": 6,
            "z": 3,
            "elements": [
                "thermalfoundation:glass_alloy@6"
            ]
        },
        {
            "x": 1,
            "y": 4,
            "z": 2,
            "elements": [
                "thermalfoundation:glass_alloy@6"
            ]
        }
    ]}