{
    "registryname": "Energy_crystal_2",
    "localizedname": "§e能量转换§d核晶 β型",
    "requires-blueprint": true,
    "parts": [
        {
            "x": 4,
            "y": 8,
            "z": 4,
            "elements": [
                "appliedenergistics2:chiseled_quartz_block@0"
            ]
        },
        {
            "x": 2,
            "y": 4,
            "z": 2,
            "elements": [
                "enderio:block_alloy@0"
            ]
        },
        {
            "x": 5,
            "y": 8,
            "z": 4,
            "elements": [
                "appliedenergistics2:chiseled_quartz_block@0"
            ]
        },
        {
            "x": 3,
            "y": 4,
            "z": 2,
            "elements": [
                "enderio:block_alloy@0"
            ]
        },
        {
            "x": -5,
            "y": 9,
            "z": 4,
            "elements": [
                "appliedenergistics2:chiseled_quartz_stairs@2"
            ]
        },
        {
            "x": 0,
            "y": 17,
            "z": 8,
            "elements": [
                "draconicevolution:draconic_block@0"
            ]
        },
        {
            "x": -4,
            "y": 9,
            "z": 4,
            "elements": [
                "appliedenergistics2:quartz_slab@0"
            ]
        },
        {
            "x": -1,
            "y": 13,
            "z": 6,
            "elements": [
                "appliedenergistics2:chiseled_quartz_stairs@0"
            ]
        },
        {
            "x": 0,
            "y": 18,
            "z": -7,
            "elements": [
                "enderio:block_alloy_endergy@5"
            ]
        },
        {
            "x": 0,
            "y": 13,
            "z": 6,
            "elements": [
                "minecraft:diamond_block@0"
            ]
        },
        {
            "x": -3,
            "y": 5,
            "z": 2,
            "elements": [
                "enderio:block_alloy@0"
            ]
        },
        {
            "x": 1,
            "y": 13,
            "z": 6,
            "elements": [
                "appliedenergistics2:chiseled_quartz_stairs@1"
            ]
        },
        {
            "x": 4,
            "y": -1,
            "z": 0,
            "elements": [
                "modularmachinery:blockinputbus"
            ]
        },
        {
            "x": 3,
            "y": -1,
            "z": 0,
            "elements": [
                "modularmachinery:blockcasing@5"
            ]
        },
        {
            "x": 2,
            "y": -1,
            "z": 0,
            "elements": [
                "modularmachinery:blockcasing@5"
            ]
        },
        {
            "x": 1,
            "y": -1,
            "z": 0,
            "elements": [
                "modularmachinery:blockcasing@5"
            ]
        },
        {
            "x": 0,
            "y": -1,
            "z": 0,
            "elements": [
                "modularmachinery:blockcasing@5"
            ]
        },
        {
            "x": -1,
            "y": 1,
            "z": 0,
            "elements": [
                "appliedenergistics2:chiseled_quartz_stairs@4"
            ]
        },
        {
            "x": 4,
            "y": 9,
            "z": 4,
            "elements": [
                "appliedenergistics2:quartz_slab@0"
            ]
        },
        {
            "x": 0,
            "y": 1,
            "z": 0,
            "elements": [
                "enderio:block_alloy_endergy@3"
            ]
        },
        {
            "x": -1,
            "y": -1,
            "z": 0,
            "elements": [
                "modularmachinery:blockcasing@5"
            ]
        },
        {
            "x": 5,
            "y": 9,
            "z": 4,
            "elements": [
                "appliedenergistics2:chiseled_quartz_stairs@2"
            ]
        },
        {
            "x": 3,
            "y": 5,
            "z": 2,
            "elements": [
                "enderio:block_alloy@0"
            ]
        },
        {
            "x": 1,
            "y": 1,
            "z": 0,
            "elements": [
                "appliedenergistics2:chiseled_quartz_stairs@5"
            ]
        },
        {
            "x": -2,
            "y": -1,
            "z": 0,
            "elements": [
                "modularmachinery:blockcasing@5"
            ]
        },
        {
            "x": -3,
            "y": -1,
            "z": 0,
            "elements": [
                "modularmachinery:blockcasing@5"
            ]
        },
        {
            "x": -4,
            "y": -1,
            "z": 0,
            "elements": [
                "modularmachinery:blockinputbus"
            ]
        },
        {
            "x": 0,
            "y": 18,
            "z": 8,
            "elements": [
                "appliedenergistics2:chiseled_quartz_stairs@3"
            ]
        },
        {
            "x": -5,
            "y": 6,
            "z": 2,
            "elements": [
                "enderio:block_alloy_endergy@2"
            ]
        },
        {
            "x": 0,
            "y": 17,
            "z": -7,
            "elements": [
                "appliedenergistics2:chiseled_quartz_stairs@7"
            ]
        },
        {
            "x": -4,
            "y": 6,
            "z": 2,
            "elements": [
                "enderio:block_alloy@6"
            ]
        },
        {
            "x": -3,
            "y": 6,
            "z": 2,
            "elements": [
                "enderio:block_alloy@0"
            ]
        },
        {
            "x": -2,
            "y": 2,
            "z": 0,
            "elements": [
                "appliedenergistics2:chiseled_quartz_stairs@4"
            ]
        },
        {
            "x": -1,
            "y": 2,
            "z": 0,
            "elements": [
                "modularmachinery:blockcasing@5"
            ]
        },
        {
            "x": 3,
            "y": 6,
            "z": 2,
            "elements": [
                "enderio:block_alloy@0"
            ]
        },
        {
            "x": 1,
            "y": 2,
            "z": 0,
            "elements": [
                "modularmachinery:blockcasing@5"
            ]
        },
        {
            "x": 4,
            "y": 6,
            "z": 2,
            "elements": [
                "enderio:block_alloy@6"
            ]
        },
        {
            "x": 2,
            "y": 2,
            "z": 0,
            "elements": [
                "appliedenergistics2:chiseled_quartz_stairs@5"
            ]
        },
        {
            "x": 5,
            "y": 6,
            "z": 2,
            "elements": [
                "enderio:block_alloy_endergy@2"
            ]
        },
        {
            "x": 0,
            "y": 12,
            "z": -9,
            "elements": [
                "appliedenergistics2:chiseled_quartz_stairs@2"
            ]
        },
        {
            "x": 0,
            "y": 19,
            "z": 8,
            "elements": [
                "minecraft:sea_lantern@0"
            ]
        },
        {
            "x": -3,
            "y": 7,
            "z": 2,
            "elements": [
                "minecraft:stone_slab@0"
            ]
        },
        {
            "x": 0,
            "y": 20,
            "z": -5,
            "elements": [
                "appliedenergistics2:chiseled_quartz_slab@0"
            ]
        },
        {
            "x": -1,
            "y": 3,
            "z": 0,
            "elements": [
                "botania:bifrostperm@0"
            ]
        },
        {
            "x": 3,
            "y": 7,
            "z": 2,
            "elements": [
                "minecraft:stone_slab@0"
            ]
        },
        {
            "x": 1,
            "y": 3,
            "z": 0,
            "elements": [
                "botania:bifrostperm@0"
            ]
        },
        {
            "x": 0,
            "y": 11,
            "z": -9,
            "elements": [
                "enderio:block_alloy_endergy@5"
            ]
        },
        {
            "x": 0,
            "y": 20,
            "z": 8,
            "elements": [
                "appliedenergistics2:chiseled_quartz_stairs@7"
            ]
        },
        {
            "x": 3,
            "y": 19,
            "z": -5,
            "elements": [
                "enderio:block_alloy@1"
            ]
        },
        {
            "x": 2,
            "y": 19,
            "z": -5,
            "elements": [
                "thermalfoundation:storage_alloy@6"
            ]
        },
        {
            "x": 1,
            "y": 19,
            "z": -5,
            "elements": [
                "enderio:block_alloy@1"
            ]
        },
        {
            "x": 0,
            "y": 19,
            "z": -5,
            "elements": [
                "modularmachinery:blockcasing@5"
            ]
        },
        {
            "x": -1,
            "y": 19,
            "z": -5,
            "elements": [
                "enderio:block_alloy@1"
            ]
        },
        {
            "x": -2,
            "y": 19,
            "z": -5,
            "elements": [
                "thermalfoundation:storage_alloy@6"
            ]
        },
        {
            "x": -3,
            "y": 19,
            "z": -5,
            "elements": [
                "enderio:block_alloy@1"
            ]
        },
        {
            "x": -1,
            "y": 4,
            "z": 0,
            "elements": [
                "botania:bifrostperm@0"
            ]
        },
        {
            "x": 1,
            "y": 4,
            "z": 0,
            "elements": [
                "botania:bifrostperm@0"
            ]
        },
        {
            "x": 0,
            "y": 10,
            "z": -9,
            "elements": [
                "enderio:block_alloy_endergy@5"
            ]
        },
        {
            "x": 0,
            "y": 21,
            "z": 8,
            "elements": [
                "draconicevolution:draconic_block@0"
            ]
        },
        {
            "x": 0,
            "y": 18,
            "z": -5,
            "elements": [
                "appliedenergistics2:chiseled_quartz_slab@8"
            ]
        },
        {
            "x": -1,
            "y": 9,
            "z": 2,
            "elements": [
                "botania:storage@4"
            ]
        },
        {
            "x": 0,
            "y": 9,
            "z": 2,
            "elements": [
                "botania:storage@4"
            ]
        },
        {
            "x": -1,
            "y": 5,
            "z": 0,
            "elements": [
                "botania:bifrostperm@0"
            ]
        },
        {
            "x": 1,
            "y": 9,
            "z": 2,
            "elements": [
                "botania:storage@4"
            ]
        },
        {
            "x": 1,
            "y": 5,
            "z": 0,
            "elements": [
                "botania:bifrostperm@0"
            ]
        },
        {
            "x": 5,
            "y": 17,
            "z": -5,
            "elements": [
                "appliedenergistics2:quartz_slab@0"
            ]
        },
        {
            "x": -9,
            "y": 6,
            "z": 0,
            "elements": [
                "appliedenergistics2:chiseled_quartz_stairs@4"
            ]
        },
        {
            "x": 4,
            "y": 17,
            "z": -5,
            "elements": [
                "appliedenergistics2:chiseled_quartz_stairs@2"
            ]
        },
        {
            "x": 0,
            "y": 9,
            "z": -9,
            "elements": [
                "modularmachinery:blockfluidinputhatch@7"
            ]
        },
        {
            "x": 0,
            "y": 22,
            "z": 8,
            "elements": [
                "appliedenergistics2:chiseled_quartz_slab@0"
            ]
        },
        {
            "x": -8,
            "y": 6,
            "z": 0,
            "elements": [
                "enderio:block_alloy_endergy@5"
            ]
        },
        {
            "x": -7,
            "y": 6,
            "z": 0,
            "elements": [
                "thermalfoundation:storage_alloy@6"
            ]
        },
        {
            "x": 0,
            "y": 18,
            "z": 6,
            "elements": [
                "appliedenergistics2:chiseled_quartz_slab@8"
            ]
        },
        {
            "x": -6,
            "y": 6,
            "z": 0,
            "elements": [
                "enderio:block_alloy@8"
            ]
        },
        {
            "x": -5,
            "y": 6,
            "z": 0,
            "elements": [
                "enderio:block_alloy_endergy@2"
            ]
        },
        {
            "x": -4,
            "y": 6,
            "z": 0,
            "elements": [
                "enderio:block_alloy@6"
            ]
        },
        {
            "x": -2,
            "y": 10,
            "z": 2,
            "elements": [
                "avaritia:block_resource@2"
            ]
        },
        {
            "x": -1,
            "y": 10,
            "z": 2,
            "elements": [
                "avaritia:block_resource@2"
            ]
        },
        {
            "x": 0,
            "y": 10,
            "z": 2,
            "elements": [
                "extrabotany:blockorichalcos@0"
            ]
        },
        {
            "x": -1,
            "y": 6,
            "z": 0,
            "elements": [
                "botania:bifrostperm@0"
            ]
        },
        {
            "x": -4,
            "y": 17,
            "z": -5,
            "elements": [
                "appliedenergistics2:chiseled_quartz_stairs@2"
            ]
        },
        {
            "x": 1,
            "y": 10,
            "z": 2,
            "elements": [
                "avaritia:block_resource@2"
            ]
        },
        {
            "x": -5,
            "y": 17,
            "z": -5,
            "elements": [
                "appliedenergistics2:quartz_slab@0"
            ]
        },
        {
            "x": 2,
            "y": 10,
            "z": 2,
            "elements": [
                "avaritia:block_resource@2"
            ]
        },
        {
            "x": 1,
            "y": 6,
            "z": 0,
            "elements": [
                "botania:bifrostperm@0"
            ]
        },
        {
            "x": 4,
            "y": 6,
            "z": 0,
            "elements": [
                "enderio:block_alloy@6"
            ]
        },
        {
            "x": 5,
            "y": 6,
            "z": 0,
            "elements": [
                "enderio:block_alloy_endergy@2"
            ]
        },
        {
            "x": 6,
            "y": 6,
            "z": 0,
            "elements": [
                "enderio:block_alloy@8"
            ]
        },
        {
            "x": 7,
            "y": 6,
            "z": 0,
            "elements": [
                "thermalfoundation:storage_alloy@6"
            ]
        },
        {
            "x": 8,
            "y": 6,
            "z": 0,
            "elements": [
                "enderio:block_alloy_endergy@5"
            ]
        },
        {
            "x": 9,
            "y": 6,
            "z": 0,
            "elements": [
                "appliedenergistics2:chiseled_quartz_stairs@5"
            ]
        },
        {
            "x": 5,
            "y": 16,
            "z": -5,
            "elements": [
                "botania:bifrostperm@0"
            ]
        },
        {
            "x": -9,
            "y": 7,
            "z": 0,
            "elements": [
                "enderio:block_alloy_endergy@5"
            ]
        },
        {
            "x": -5,
            "y": 15,
            "z": 4,
            "elements": [
                "appliedenergistics2:chiseled_quartz_stairs@6"
            ]
        },
        {
            "x": 4,
            "y": 16,
            "z": -5,
            "elements": [
                "appliedenergistics2:chiseled_quartz_block@0"
            ]
        },
        {
            "x": 0,
            "y": 8,
            "z": -9,
            "elements": [
                "enderio:block_alloy_endergy@5"
            ]
        },
        {
            "x": -8,
            "y": 7,
            "z": 0,
            "elements": [
                "appliedenergistics2:chiseled_quartz_stairs@1"
            ]
        },
        {
            "x": -4,
            "y": 15,
            "z": 4,
            "elements": [
                "appliedenergistics2:quartz_slab@8"
            ]
        },
        {
            "x": 0,
            "y": 12,
            "z": -7,
            "elements": [
                "modularmachinery:blockcasing@5"
            ]
        },
        {
            "x": 0,
            "y": 19,
            "z": 6,
            "elements": [
                "modularmachinery:blockcasing@5"
            ]
        },
        {
            "x": -3,
            "y": 11,
            "z": 2,
            "elements": [
                "botania:storage@4"
            ]
        },
        {
            "x": -4,
            "y": 7,
            "z": 0,
            "elements": [
                "minecraft:stone_slab@0"
            ]
        },
        {
            "x": -2,
            "y": 11,
            "z": 2,
            "elements": [
                "avaritia:block_resource@2"
            ]
        },
        {
            "x": -3,
            "y": 7,
            "z": 0,
            "elements": [
                "modularmachinery:blockcasing@0"
            ]
        },
        {
            "x": 0,
            "y": 20,
            "z": -3,
            "elements": [
                "appliedenergistics2:chiseled_quartz_slab@0"
            ]
        },
        {
            "x": -1,
            "y": 7,
            "z": 0,
            "elements": [
                "botania:bifrostperm@0"
            ]
        },
        {
            "x": -4,
            "y": 16,
            "z": -5,
            "elements": [
                "appliedenergistics2:chiseled_quartz_block@0"
            ]
        },
        {
            "x": -5,
            "y": 16,
            "z": -5,
            "elements": [
                "botania:bifrostperm@0"
            ]
        },
        {
            "x": 4,
            "y": 15,
            "z": 4,
            "elements": [
                "appliedenergistics2:quartz_slab@8"
            ]
        },
        {
            "x": 2,
            "y": 11,
            "z": 2,
            "elements": [
                "avaritia:block_resource@2"
            ]
        },
        {
            "x": 5,
            "y": 15,
            "z": 4,
            "elements": [
                "appliedenergistics2:chiseled_quartz_stairs@6"
            ]
        },
        {
            "x": 3,
            "y": 11,
            "z": 2,
            "elements": [
                "botania:storage@4"
            ]
        },
        {
            "x": 1,
            "y": 7,
            "z": 0,
            "elements": [
                "botania:bifrostperm@0"
            ]
        },
        {
            "x": 3,
            "y": 7,
            "z": 0,
            "elements": [
                "modularmachinery:blockcasing@0"
            ]
        },
        {
            "x": 4,
            "y": 7,
            "z": 0,
            "elements": [
                "minecraft:stone_slab@0"
            ]
        },
        {
            "x": 8,
            "y": 7,
            "z": 0,
            "elements": [
                "appliedenergistics2:chiseled_quartz_stairs@0"
            ]
        },
        {
            "x": 9,
            "y": 7,
            "z": 0,
            "elements": [
                "enderio:block_alloy_endergy@5"
            ]
        },
        {
            "x": 5,
            "y": 15,
            "z": -5,
            "elements": [
                "botania:bifrostperm@0"
            ]
        },
        {
            "x": -9,
            "y": 8,
            "z": 0,
            "elements": [
                "enderio:block_alloy_endergy@5"
            ]
        },
        {
            "x": -5,
            "y": 16,
            "z": 4,
            "elements": [
                "appliedenergistics2:chiseled_quartz_block@0"
            ]
        },
        {
            "x": 4,
            "y": 15,
            "z": -5,
            "elements": [
                "appliedenergistics2:chiseled_quartz_stairs@6"
            ]
        },
        {
            "x": 0,
            "y": 7,
            "z": -9,
            "elements": [
                "enderio:block_alloy_endergy@5"
            ]
        },
        {
            "x": 5,
            "y": 19,
            "z": -3,
            "elements": [
                "enderio:block_alloy@1"
            ]
        },
        {
            "x": -4,
            "y": 16,
            "z": 4,
            "elements": [
                "appliedenergistics2:chiseled_quartz_block@0"
            ]
        },
        {
            "x": 0,
            "y": 20,
            "z": 6,
            "elements": [
                "appliedenergistics2:chiseled_quartz_slab@0"
            ]
        },
        {
            "x": -3,
            "y": 12,
            "z": 2,
            "elements": [
                "botania:storage@2"
            ]
        },
        {
            "x": -2,
            "y": 12,
            "z": 2,
            "elements": [
                "extrabotany:blockorichalcos@0"
            ]
        },
        {
            "x": 1,
            "y": 19,
            "z": -3,
            "elements": [
                "minecraft:stone_slab@0"
            ]
        },
        {
            "x": 0,
            "y": 19,
            "z": -3,
            "elements": [
                "modularmachinery:blockcasing@5"
            ]
        },
        {
            "x": -1,
            "y": 19,
            "z": -3,
            "elements": [
                "minecraft:stone_slab@0"
            ]
        },
        {
            "x": -1,
            "y": 8,
            "z": 0,
            "elements": [
                "botania:bifrostperm@0"
            ]
        },
        {
            "x": -4,
            "y": 15,
            "z": -5,
            "elements": [
                "appliedenergistics2:chiseled_quartz_stairs@5"
            ]
        },
        {
            "x": -5,
            "y": 15,
            "z": -5,
            "elements": [
                "botania:bifrostperm@0"
            ]
        },
        {
            "x": 4,
            "y": 16,
            "z": 4,
            "elements": [
                "appliedenergistics2:chiseled_quartz_block@0"
            ]
        },
        {
            "x": 2,
            "y": 12,
            "z": 2,
            "elements": [
                "extrabotany:blockorichalcos@0"
            ]
        },
        {
            "x": 5,
            "y": 16,
            "z": 4,
            "elements": [
                "appliedenergistics2:chiseled_quartz_block@0"
            ]
        },
        {
            "x": 3,
            "y": 12,
            "z": 2,
            "elements": [
                "botania:storage@2"
            ]
        },
        {
            "x": 1,
            "y": 8,
            "z": 0,
            "elements": [
                "botania:bifrostperm@0"
            ]
        },
        {
            "x": -5,
            "y": 19,
            "z": -3,
            "elements": [
                "enderio:block_alloy@1"
            ]
        },
        {
            "x": 9,
            "y": 8,
            "z": 0,
            "elements": [
                "enderio:block_alloy_endergy@5"
            ]
        },
        {
            "x": 5,
            "y": 14,
            "z": -5,
            "elements": [
                "botania:bifrostperm@0"
            ]
        },
        {
            "x": -9,
            "y": 9,
            "z": 0,
            "elements": [
                "modularmachinery:blockfluidinputhatch"
            ]
        },
        {
            "x": -5,
            "y": 17,
            "z": 4,
            "elements": [
                "appliedenergistics2:chiseled_quartz_stairs@0"
            ]
        },
        {
            "x": 0,
            "y": 6,
            "z": -9,
            "elements": [
                "appliedenergistics2:chiseled_quartz_stairs@6"
            ]
        },
        {
            "x": -4,
            "y": 17,
            "z": 4,
            "elements": [
                "appliedenergistics2:chiseled_quartz_block@0"
            ]
        },
        {
            "x": 4,
            "y": 18,
            "z": -3,
            "elements": [
                "enderio:block_alloy_endergy@2"
            ]
        },
        {
            "x": -3,
            "y": 17,
            "z": 4,
            "elements": [
                "appliedenergistics2:chiseled_quartz_stairs@5"
            ]
        },
        {
            "x": 3,
            "y": 18,
            "z": -3,
            "elements": [
                "enderio:block_alloy@6"
            ]
        },
        {
            "x": -3,
            "y": 13,
            "z": 2,
            "elements": [
                "botania:storage@4"
            ]
        },
        {
            "x": 2,
            "y": 18,
            "z": -3,
            "elements": [
                "enderio:block_alloy@6"
            ]
        },
        {
            "x": -2,
            "y": 13,
            "z": 2,
            "elements": [
                "avaritia:block_resource@2"
            ]
        },
        {
            "x": 1,
            "y": 18,
            "z": -3,
            "elements": [
                "minecraft:glass@0"
            ]
        },
        {
            "x": 0,
            "y": 18,
            "z": -3,
            "elements": [
                "minecraft:glass@0"
            ]
        },
        {
            "x": -1,
            "y": 18,
            "z": -3,
            "elements": [
                "minecraft:glass@0"
            ]
        },
        {
            "x": -2,
            "y": 9,
            "z": 0,
            "elements": [
                "botania:storage@4"
            ]
        },
        {
            "x": -1,
            "y": 9,
            "z": 0,
            "elements": [
                "botania:storage@4"
            ]
        },
        {
            "x": 0,
            "y": 22,
            "z": -1,
            "elements": [
                "appliedenergistics2:chiseled_quartz_stairs@2"
            ]
        },
        {
            "x": 3,
            "y": 17,
            "z": 4,
            "elements": [
                "appliedenergistics2:chiseled_quartz_stairs@4"
            ]
        },
        {
            "x": -2,
            "y": 18,
            "z": -3,
            "elements": [
                "enderio:block_alloy@6"
            ]
        },
        {
            "x": -5,
            "y": 14,
            "z": -5,
            "elements": [
                "botania:bifrostperm@0"
            ]
        },
        {
            "x": 4,
            "y": 17,
            "z": 4,
            "elements": [
                "appliedenergistics2:chiseled_quartz_block@0"
            ]
        },
        {
            "x": -3,
            "y": 18,
            "z": -3,
            "elements": [
                "enderio:block_alloy@6"
            ]
        },
        {
            "x": 2,
            "y": 13,
            "z": 2,
            "elements": [
                "avaritia:block_resource@2"
            ]
        },
        {
            "x": 0,
            "y": 9,
            "z": 0,
            "elements": [
                "plustic:plustic.molten_refinedglowstone@1"
            ]
        },
        {
            "x": 5,
            "y": 17,
            "z": 4,
            "elements": [
                "appliedenergistics2:chiseled_quartz_stairs@1"
            ]
        },
        {
            "x": -4,
            "y": 18,
            "z": -3,
            "elements": [
                "enderio:block_alloy_endergy@2"
            ]
        },
        {
            "x": 3,
            "y": 13,
            "z": 2,
            "elements": [
                "botania:storage@4"
            ]
        },
        {
            "x": 1,
            "y": 9,
            "z": 0,
            "elements": [
                "botania:storage@4"
            ]
        },
        {
            "x": 2,
            "y": 9,
            "z": 0,
            "elements": [
                "botania:storage@4"
            ]
        },
        {
            "x": 9,
            "y": 9,
            "z": 0,
            "elements": [
                "modularmachinery:blockfluidinputhatch"
            ]
        },
        {
            "x": 5,
            "y": 13,
            "z": -5,
            "elements": [
                "botania:bifrostperm@0"
            ]
        },
        {
            "x": -9,
            "y": 10,
            "z": 0,
            "elements": [
                "enderio:block_alloy_endergy@5"
            ]
        },
        {
            "x": -4,
            "y": 18,
            "z": 4,
            "elements": [
                "thermalfoundation:storage_alloy@6"
            ]
        },
        {
            "x": 4,
            "y": 17,
            "z": -3,
            "elements": [
                "appliedenergistics2:chiseled_quartz_stairs@7"
            ]
        },
        {
            "x": -3,
            "y": 18,
            "z": 4,
            "elements": [
                "enderio:block_alloy_endergy@2"
            ]
        },
        {
            "x": 3,
            "y": 17,
            "z": -3,
            "elements": [
                "appliedenergistics2:quartz_slab@8"
            ]
        },
        {
            "x": 0,
            "y": 18,
            "z": 4,
            "elements": [
                "appliedenergistics2:chiseled_quartz_slab@8"
            ]
        },
        {
            "x": -2,
            "y": 14,
            "z": 2,
            "elements": [
                "avaritia:block_resource@2"
            ]
        },
        {
            "x": 1,
            "y": 17,
            "z": -3,
            "elements": [
                "minecraft:stone_slab@8"
            ]
        },
        {
            "x": -3,
            "y": 10,
            "z": 0,
            "elements": [
                "botania:storage@1"
            ]
        },
        {
            "x": -1,
            "y": 14,
            "z": 2,
            "elements": [
                "avaritia:block_resource@2"
            ]
        },
        {
            "x": 0,
            "y": 17,
            "z": -3,
            "elements": [
                "minecraft:stone_slab@8"
            ]
        },
        {
            "x": -1,
            "y": 17,
            "z": -3,
            "elements": [
                "minecraft:stone_slab@8"
            ]
        },
        {
            "x": 0,
            "y": 14,
            "z": 2,
            "elements": [
                "extrabotany:blockorichalcos@0"
            ]
        },
        {
            "x": -2,
            "y": 10,
            "z": 0,
            "elements": [
                "extrabotany:blockorichalcos@0"
            ]
        },
        {
            "x": 0,
            "y": 21,
            "z": -1,
            "elements": [
                "thermalfoundation:storage_alloy@6"
            ]
        },
        {
            "x": 3,
            "y": 18,
            "z": 4,
            "elements": [
                "enderio:block_alloy_endergy@2"
            ]
        },
        {
            "x": 1,
            "y": 14,
            "z": 2,
            "elements": [
                "avaritia:block_resource@2"
            ]
        },
        {
            "x": -5,
            "y": 13,
            "z": -5,
            "elements": [
                "botania:bifrostperm@0"
            ]
        },
        {
            "x": 4,
            "y": 18,
            "z": 4,
            "elements": [
                "thermalfoundation:storage_alloy@6"
            ]
        },
        {
            "x": -3,
            "y": 17,
            "z": -3,
            "elements": [
                "appliedenergistics2:quartz_slab@8"
            ]
        },
        {
            "x": 2,
            "y": 14,
            "z": 2,
            "elements": [
                "avaritia:block_resource@2"
            ]
        },
        {
            "x": 0,
            "y": 10,
            "z": 0,
            "elements": [
                "plustic:plustic.molten_refinedglowstone@0"
            ]
        },
        {
            "x": -4,
            "y": 17,
            "z": -3,
            "elements": [
                "appliedenergistics2:chiseled_quartz_stairs@7"
            ]
        },
        {
            "x": 2,
            "y": 10,
            "z": 0,
            "elements": [
                "extrabotany:blockorichalcos@0"
            ]
        },
        {
            "x": 3,
            "y": 10,
            "z": 0,
            "elements": [
                "botania:storage@1"
            ]
        },
        {
            "x": 9,
            "y": 10,
            "z": 0,
            "elements": [
                "enderio:block_alloy_endergy@5"
            ]
        },
        {
            "x": 5,
            "y": 12,
            "z": -5,
            "elements": [
                "botania:bifrostperm@0"
            ]
        },
        {
            "x": -9,
            "y": 11,
            "z": 0,
            "elements": [
                "enderio:block_alloy_endergy@5"
            ]
        },
        {
            "x": -8,
            "y": 11,
            "z": 0,
            "elements": [
                "appliedenergistics2:chiseled_quartz_stairs@5"
            ]
        },
        {
            "x": -4,
            "y": 19,
            "z": 4,
            "elements": [
                "enderio:block_alloy@1"
            ]
        },
        {
            "x": -6,
            "y": 11,
            "z": 0,
            "elements": [
                "minecraft:diamond_block@0"
            ]
        },
        {
            "x": 0,
            "y": 19,
            "z": 4,
            "elements": [
                "modularmachinery:blockcasing@5"
            ]
        },
        {
            "x": -3,
            "y": 11,
            "z": 0,
            "elements": [
                "minecraft:glass@0"
            ]
        },
        {
            "x": 2,
            "y": 20,
            "z": -1,
            "elements": [
                "appliedenergistics2:chiseled_quartz_stairs@1"
            ]
        },
        {
            "x": -1,
            "y": 15,
            "z": 2,
            "elements": [
                "botania:storage@4"
            ]
        },
        {
            "x": 0,
            "y": 15,
            "z": 2,
            "elements": [
                "botania:storage@4"
            ]
        },
        {
            "x": 1,
            "y": 20,
            "z": -1,
            "elements": [
                "minecraft:gold_block@0"
            ]
        },
        {
            "x": -1,
            "y": 11,
            "z": 0,
            "elements": [
                "avaritia:block_resource@0"
            ]
        },
        {
            "x": 0,
            "y": 20,
            "z": -1,
            "elements": [
                "minecraft:gold_block@0"
            ]
        },
        {
            "x": 1,
            "y": 15,
            "z": 2,
            "elements": [
                "botania:storage@4"
            ]
        },
        {
            "x": -5,
            "y": 12,
            "z": -5,
            "elements": [
                "botania:bifrostperm@0"
            ]
        },
        {
            "x": 4,
            "y": 19,
            "z": 4,
            "elements": [
                "enderio:block_alloy@1"
            ]
        },
        {
            "x": -1,
            "y": 20,
            "z": -1,
            "elements": [
                "minecraft:gold_block@0"
            ]
        },
        {
            "x": 0,
            "y": 11,
            "z": 0,
            "elements": [
                "avaritia:block_resource@0"
            ]
        },
        {
            "x": -2,
            "y": 20,
            "z": -1,
            "elements": [
                "appliedenergistics2:chiseled_quartz_stairs@0"
            ]
        },
        {
            "x": 1,
            "y": 11,
            "z": 0,
            "elements": [
                "avaritia:block_resource@0"
            ]
        },
        {
            "x": 3,
            "y": 11,
            "z": 0,
            "elements": [
                "minecraft:glass@0"
            ]
        },
        {
            "x": 6,
            "y": 11,
            "z": 0,
            "elements": [
                "minecraft:diamond_block@0"
            ]
        },
        {
            "x": 8,
            "y": 11,
            "z": 0,
            "elements": [
                "appliedenergistics2:chiseled_quartz_stairs@4"
            ]
        },
        {
            "x": 9,
            "y": 11,
            "z": 0,
            "elements": [
                "enderio:block_alloy_endergy@5"
            ]
        },
        {
            "x": 5,
            "y": 11,
            "z": -5,
            "elements": [
                "botania:bifrostperm@0"
            ]
        },
        {
            "x": -9,
            "y": 12,
            "z": 0,
            "elements": [
                "appliedenergistics2:chiseled_quartz_stairs@0"
            ]
        },
        {
            "x": -8,
            "y": 12,
            "z": 0,
            "elements": [
                "enderio:block_alloy_endergy@5"
            ]
        },
        {
            "x": -7,
            "y": 12,
            "z": 0,
            "elements": [
                "modularmachinery:blockcasing@5"
            ]
        },
        {
            "x": -6,
            "y": 12,
            "z": 0,
            "elements": [
                "minecraft:sea_lantern@0"
            ]
        },
        {
            "x": 5,
            "y": 19,
            "z": -1,
            "elements": [
                "enderio:block_alloy@1"
            ]
        },
        {
            "x": 0,
            "y": 20,
            "z": 4,
            "elements": [
                "appliedenergistics2:chiseled_quartz_slab@0"
            ]
        },
        {
            "x": 3,
            "y": 19,
            "z": -1,
            "elements": [
                "minecraft:stone_slab@0"
            ]
        },
        {
            "x": -3,
            "y": 12,
            "z": 0,
            "elements": [
                "minecraft:stained_glass@15"
            ]
        },
        {
            "x": 2,
            "y": 19,
            "z": -1,
            "elements": [
                "modularmachinery:blockcasing@0"
            ]
        },
        {
            "x": 1,
            "y": 19,
            "z": -1,
            "elements": [
                "plustic:plustic.molten_refinedglowstone@0"
            ]
        },
        {
            "x": -5,
            "y": 11,
            "z": -5,
            "elements": [
                "botania:bifrostperm@0"
            ]
        },
        {
            "x": -1,
            "y": 19,
            "z": -1,
            "elements": [
                "plustic:plustic.molten_refinedglowstone@0"
            ]
        },
        {
            "x": 0,
            "y": 12,
            "z": 0,
            "elements": [
                "draconicevolution:draconic_block@0"
            ]
        },
        {
            "x": -2,
            "y": 19,
            "z": -1,
            "elements": [
                "modularmachinery:blockcasing@0"
            ]
        },
        {
            "x": -3,
            "y": 19,
            "z": -1,
            "elements": [
                "minecraft:stone_slab@0"
            ]
        },
        {
            "x": 3,
            "y": 12,
            "z": 0,
            "elements": [
                "minecraft:stained_glass@15"
            ]
        },
        {
            "x": -5,
            "y": 19,
            "z": -1,
            "elements": [
                "enderio:block_alloy@1"
            ]
        },
        {
            "x": 6,
            "y": 12,
            "z": 0,
            "elements": [
                "minecraft:sea_lantern@0"
            ]
        },
        {
            "x": 7,
            "y": 12,
            "z": 0,
            "elements": [
                "modularmachinery:blockcasing@5"
            ]
        },
        {
            "x": 8,
            "y": 12,
            "z": 0,
            "elements": [
                "enderio:block_alloy_endergy@5"
            ]
        },
        {
            "x": 9,
            "y": 12,
            "z": 0,
            "elements": [
                "appliedenergistics2:chiseled_quartz_stairs@1"
            ]
        },
        {
            "x": 5,
            "y": 10,
            "z": -5,
            "elements": [
                "botania:bifrostperm@0"
            ]
        },
        {
            "x": 0,
            "y": 6,
            "z": -7,
            "elements": [
                "thermalfoundation:storage_alloy@6"
            ]
        },
        {
            "x": -6,
            "y": 13,
            "z": 0,
            "elements": [
                "minecraft:diamond_block@0"
            ]
        },
        {
            "x": 3,
            "y": 18,
            "z": -1,
            "elements": [
                "minecraft:glass@0"
            ]
        },
        {
            "x": -2,
            "y": 17,
            "z": 2,
            "elements": [
                "minecraft:stone_slab@8"
            ]
        },
        {
            "x": 1,
            "y": 14,
            "z": -3,
            "elements": [
                "botania:storage@4"
            ]
        },
        {
            "x": -3,
            "y": 13,
            "z": 0,
            "elements": [
                "minecraft:glass@0"
            ]
        },
        {
            "x": 2,
            "y": 18,
            "z": -1,
            "elements": [
                "modularmachinery:blockcasing@5"
            ]
        },
        {
            "x": 0,
            "y": 14,
            "z": -3,
            "elements": [
                "botania:storage@1"
            ]
        },
        {
            "x": -1,
            "y": 14,
            "z": -3,
            "elements": [
                "botania:storage@4"
            ]
        },
        {
            "x": -1,
            "y": 13,
            "z": 0,
            "elements": [
                "avaritia:block_resource@0"
            ]
        },
        {
            "x": -5,
            "y": 10,
            "z": -5,
            "elements": [
                "botania:bifrostperm@0"
            ]
        },
        {
            "x": 2,
            "y": 17,
            "z": 2,
            "elements": [
                "minecraft:stone_slab@8"
            ]
        },
        {
            "x": 0,
            "y": 13,
            "z": 0,
            "elements": [
                "avaritia:block_resource@0"
            ]
        },
        {
            "x": -2,
            "y": 18,
            "z": -1,
            "elements": [
                "modularmachinery:blockcasing@5"
            ]
        },
        {
            "x": 1,
            "y": 13,
            "z": 0,
            "elements": [
                "avaritia:block_resource@0"
            ]
        },
        {
            "x": -3,
            "y": 18,
            "z": -1,
            "elements": [
                "minecraft:glass@0"
            ]
        },
        {
            "x": 3,
            "y": 13,
            "z": 0,
            "elements": [
                "minecraft:glass@0"
            ]
        },
        {
            "x": 6,
            "y": 13,
            "z": 0,
            "elements": [
                "minecraft:diamond_block@0"
            ]
        },
        {
            "x": 5,
            "y": 9,
            "z": -5,
            "elements": [
                "botania:bifrostperm@0"
            ]
        },
        {
            "x": 4,
            "y": 9,
            "z": -5,
            "elements": [
                "appliedenergistics2:chiseled_quartz_stairs@0"
            ]
        },
        {
            "x": -3,
            "y": 18,
            "z": 2,
            "elements": [
                "enderio:block_alloy@6"
            ]
        },
        {
            "x": 2,
            "y": 13,
            "z": -3,
            "elements": [
                "botania:storage@4"
            ]
        },
        {
            "x": 3,
            "y": 17,
            "z": -1,
            "elements": [
                "minecraft:stone_slab@8"
            ]
        },
        {
            "x": -2,
            "y": 18,
            "z": 2,
            "elements": [
                "modularmachinery:blockcasing@5"
            ]
        },
        {
            "x": 1,
            "y": 13,
            "z": -3,
            "elements": [
                "botania:storage@0"
            ]
        },
        {
            "x": -3,
            "y": 14,
            "z": 0,
            "elements": [
                "botania:storage@1"
            ]
        },
        {
            "x": -1,
            "y": 18,
            "z": 2,
            "elements": [
                "modularmachinery:blockcasing@5"
            ]
        },
        {
            "x": 0,
            "y": 13,
            "z": -3,
            "elements": [
                "minecraft:glass@0"
            ]
        },
        {
            "x": -1,
            "y": 13,
            "z": -3,
            "elements": [
                "botania:storage@0"
            ]
        },
        {
            "x": 0,
            "y": 18,
            "z": 2,
            "elements": [
                "modularmachinery:blockcasing@5"
            ]
        },
        {
            "x": -2,
            "y": 14,
            "z": 0,
            "elements": [
                "extrabotany:blockorichalcos@0"
            ]
        },
        {
            "x": 1,
            "y": 17,
            "z": -1,
            "elements": [
                "botania:bifrostperm@0"
            ]
        },
        {
            "x": 0,
            "y": 17,
            "z": -1,
            "elements": [
                "botania:bifrostperm@0"
            ]
        },
        {
            "x": -4,
            "y": 9,
            "z": -5,
            "elements": [
                "appliedenergistics2:chiseled_quartz_stairs@1"
            ]
        },
        {
            "x": -2,
            "y": 13,
            "z": -3,
            "elements": [
                "botania:storage@4"
            ]
        },
        {
            "x": 1,
            "y": 18,
            "z": 2,
            "elements": [
                "modularmachinery:blockcasing@5"
            ]
        },
        {
            "x": -5,
            "y": 9,
            "z": -5,
            "elements": [
                "botania:bifrostperm@0"
            ]
        },
        {
            "x": 2,
            "y": 18,
            "z": 2,
            "elements": [
                "modularmachinery:blockcasing@5"
            ]
        },
        {
            "x": -1,
            "y": 17,
            "z": -1,
            "elements": [
                "botania:bifrostperm@0"
            ]
        },
        {
            "x": 0,
            "y": 14,
            "z": 0,
            "elements": [
                "plustic:plustic.molten_refinedglowstone@1"
            ]
        },
        {
            "x": 3,
            "y": 18,
            "z": 2,
            "elements": [
                "enderio:block_alloy@6"
            ]
        },
        {
            "x": -3,
            "y": 17,
            "z": -1,
            "elements": [
                "minecraft:stone_slab@8"
            ]
        },
        {
            "x": 2,
            "y": 14,
            "z": 0,
            "elements": [
                "extrabotany:blockorichalcos@0"
            ]
        },
        {
            "x": 3,
            "y": 14,
            "z": 0,
            "elements": [
                "botania:storage@1"
            ]
        },
        {
            "x": 5,
            "y": 8,
            "z": -5,
            "elements": [
                "botania:bifrostperm@0"
            ]
        },
        {
            "x": 4,
            "y": 8,
            "z": -5,
            "elements": [
                "appliedenergistics2:chiseled_quartz_block@0"
            ]
        },
        {
            "x": -5,
            "y": 19,
            "z": 2,
            "elements": [
                "thermalfoundation:storage_alloy@6"
            ]
        },
        {
            "x": 2,
            "y": 12,
            "z": -3,
            "elements": [
                "botania:storage@2"
            ]
        },
        {
            "x": -2,
            "y": 19,
            "z": 2,
            "elements": [
                "minecraft:stone_slab@0"
            ]
        },
        {
            "x": 1,
            "y": 12,
            "z": -3,
            "elements": [
                "minecraft:glass@0"
            ]
        },
        {
            "x": -1,
            "y": 19,
            "z": 2,
            "elements": [
                "modularmachinery:blockcasing@0"
            ]
        },
        {
            "x": 0,
            "y": 12,
            "z": -3,
            "elements": [
                "minecraft:stained_glass@15"
            ]
        },
        {
            "x": -1,
            "y": 12,
            "z": -3,
            "elements": [
                "minecraft:glass@0"
            ]
        },
        {
            "x": 0,
            "y": 19,
            "z": 2,
            "elements": [
                "modularmachinery:blockcasing@5"
            ]
        },
        {
            "x": -2,
            "y": 15,
            "z": 0,
            "elements": [
                "botania:storage@4"
            ]
        },
        {
            "x": -1,
            "y": 15,
            "z": 0,
            "elements": [
                "botania:storage@4"
            ]
        },
        {
            "x": 0,
            "y": 16,
            "z": -1,
            "elements": [
                "botania:bifrostperm@0"
            ]
        },
        {
            "x": -4,
            "y": 8,
            "z": -5,
            "elements": [
                "appliedenergistics2:chiseled_quartz_block@0"
            ]
        },
        {
            "x": -2,
            "y": 12,
            "z": -3,
            "elements": [
                "botania:storage@2"
            ]
        },
        {
            "x": 1,
            "y": 19,
            "z": 2,
            "elements": [
                "modularmachinery:blockcasing@0"
            ]
        },
        {
            "x": -5,
            "y": 8,
            "z": -5,
            "elements": [
                "botania:bifrostperm@0"
            ]
        },
        {
            "x": 2,
            "y": 19,
            "z": 2,
            "elements": [
                "minecraft:stone_slab@0"
            ]
        },
        {
            "x": 1,
            "y": 15,
            "z": 0,
            "elements": [
                "botania:storage@4"
            ]
        },
        {
            "x": 2,
            "y": 15,
            "z": 0,
            "elements": [
                "botania:storage@4"
            ]
        },
        {
            "x": 5,
            "y": 19,
            "z": 2,
            "elements": [
                "thermalfoundation:storage_alloy@6"
            ]
        },
        {
            "x": 5,
            "y": 7,
            "z": -5,
            "elements": [
                "appliedenergistics2:quartz_slab@8"
            ]
        },
        {
            "x": -9,
            "y": 16,
            "z": 0,
            "elements": [
                "appliedenergistics2:chiseled_quartz_slab@8"
            ]
        },
        {
            "x": 4,
            "y": 7,
            "z": -5,
            "elements": [
                "appliedenergistics2:chiseled_quartz_stairs@6"
            ]
        },
        {
            "x": -8,
            "y": 16,
            "z": 0,
            "elements": [
                "appliedenergistics2:chiseled_quartz_slab@8"
            ]
        },
        {
            "x": 2,
            "y": 11,
            "z": -3,
            "elements": [
                "botania:storage@4"
            ]
        },
        {
            "x": 1,
            "y": 11,
            "z": -3,
            "elements": [
                "botania:storage@0"
            ]
        },
        {
            "x": 2,
            "y": 15,
            "z": -1,
            "elements": [
                "botania:storage@4"
            ]
        },
        {
            "x": -1,
            "y": 20,
            "z": 2,
            "elements": [
                "appliedenergistics2:chiseled_quartz_stairs@3"
            ]
        },
        {
            "x": 0,
            "y": 11,
            "z": -3,
            "elements": [
                "minecraft:glass@0"
            ]
        },
        {
            "x": -1,
            "y": 11,
            "z": -3,
            "elements": [
                "botania:storage@0"
            ]
        },
        {
            "x": 0,
            "y": 20,
            "z": 2,
            "elements": [
                "appliedenergistics2:chiseled_quartz_stairs@3"
            ]
        },
        {
            "x": 1,
            "y": 15,
            "z": -1,
            "elements": [
                "botania:storage@4"
            ]
        },
        {
            "x": -1,
            "y": 16,
            "z": 0,
            "elements": [
                "botania:bifrostperm@0"
            ]
        },
        {
            "x": 0,
            "y": 15,
            "z": -1,
            "elements": [
                "botania:storage@4"
            ]
        },
        {
            "x": -4,
            "y": 7,
            "z": -5,
            "elements": [
                "appliedenergistics2:chiseled_quartz_stairs@6"
            ]
        },
        {
            "x": -2,
            "y": 11,
            "z": -3,
            "elements": [
                "botania:storage@4"
            ]
        },
        {
            "x": 1,
            "y": 20,
            "z": 2,
            "elements": [
                "appliedenergistics2:chiseled_quartz_stairs@3"
            ]
        },
        {
            "x": -5,
            "y": 7,
            "z": -5,
            "elements": [
                "appliedenergistics2:quartz_slab@8"
            ]
        },
        {
            "x": -1,
            "y": 15,
            "z": -1,
            "elements": [
                "botania:storage@4"
            ]
        },
        {
            "x": -2,
            "y": 15,
            "z": -1,
            "elements": [
                "botania:storage@4"
            ]
        },
        {
            "x": 1,
            "y": 16,
            "z": 0,
            "elements": [
                "botania:bifrostperm@0"
            ]
        },
        {
            "x": 8,
            "y": 16,
            "z": 0,
            "elements": [
                "appliedenergistics2:chiseled_quartz_slab@8"
            ]
        },
        {
            "x": 9,
            "y": 16,
            "z": 0,
            "elements": [
                "appliedenergistics2:chiseled_quartz_slab@8"
            ]
        },
        {
            "x": -9,
            "y": 17,
            "z": 0,
            "elements": [
                "modularmachinery:blockfluidoutputhatch"
            ]
        },
        {
            "x": -8,
            "y": 17,
            "z": 0,
            "elements": [
                "draconicevolution:draconic_block@0"
            ]
        },
        {
            "x": 3,
            "y": 6,
            "z": -5,
            "elements": [
                "enderio:block_alloy_endergy@2"
            ]
        },
        {
            "x": -7,
            "y": 17,
            "z": 0,
            "elements": [
                "appliedenergistics2:chiseled_quartz_stairs@5"
            ]
        },
        {
            "x": 2,
            "y": 6,
            "z": -5,
            "elements": [
                "enderio:block_alloy_endergy@2"
            ]
        },
        {
            "x": 1,
            "y": 6,
            "z": -5,
            "elements": [
                "enderio:block_alloy_endergy@2"
            ]
        },
        {
            "x": 0,
            "y": 6,
            "z": -5,
            "elements": [
                "enderio:block_alloy_endergy@2"
            ]
        },
        {
            "x": -1,
            "y": 6,
            "z": -5,
            "elements": [
                "enderio:block_alloy_endergy@2"
            ]
        },
        {
            "x": 3,
            "y": 14,
            "z": -1,
            "elements": [
                "botania:storage@4"
            ]
        },
        {
            "x": 1,
            "y": 10,
            "z": -3,
            "elements": [
                "botania:storage@4"
            ]
        },
        {
            "x": -3,
            "y": 17,
            "z": 0,
            "elements": [
                "minecraft:stone_slab@8"
            ]
        },
        {
            "x": 2,
            "y": 14,
            "z": -1,
            "elements": [
                "avaritia:block_resource@2"
            ]
        },
        {
            "x": 0,
            "y": 10,
            "z": -3,
            "elements": [
                "botania:storage@1"
            ]
        },
        {
            "x": -2,
            "y": 6,
            "z": -5,
            "elements": [
                "enderio:block_alloy_endergy@2"
            ]
        },
        {
            "x": -3,
            "y": 6,
            "z": -5,
            "elements": [
                "enderio:block_alloy_endergy@2"
            ]
        },
        {
            "x": -1,
            "y": 10,
            "z": -3,
            "elements": [
                "botania:storage@4"
            ]
        },
        {
            "x": 1,
            "y": 14,
            "z": -1,
            "elements": [
                "avaritia:block_resource@0"
            ]
        },
        {
            "x": -1,
            "y": 17,
            "z": 0,
            "elements": [
                "botania:bifrostperm@0"
            ]
        },
        {
            "x": -1,
            "y": 14,
            "z": -1,
            "elements": [
                "avaritia:block_resource@0"
            ]
        },
        {
            "x": -2,
            "y": 14,
            "z": -1,
            "elements": [
                "avaritia:block_resource@2"
            ]
        },
        {
            "x": 1,
            "y": 17,
            "z": 0,
            "elements": [
                "botania:bifrostperm@0"
            ]
        },
        {
            "x": -3,
            "y": 14,
            "z": -1,
            "elements": [
                "botania:storage@4"
            ]
        },
        {
            "x": 3,
            "y": 17,
            "z": 0,
            "elements": [
                "minecraft:stone_slab@8"
            ]
        },
        {
            "x": 7,
            "y": 17,
            "z": 0,
            "elements": [
                "appliedenergistics2:chiseled_quartz_stairs@4"
            ]
        },
        {
            "x": 8,
            "y": 17,
            "z": 0,
            "elements": [
                "draconicevolution:draconic_block@0"
            ]
        },
        {
            "x": 9,
            "y": 17,
            "z": 0,
            "elements": [
                "casings_energy"
            ]
        },
        {
            "x": -9,
            "y": 18,
            "z": 0,
            "elements": [
                "appliedenergistics2:chiseled_quartz_slab@0"
            ]
        },
        {
            "x": -8,
            "y": 18,
            "z": 0,
            "elements": [
                "appliedenergistics2:chiseled_quartz_stairs@0"
            ]
        },
        {
            "x": -7,
            "y": 18,
            "z": 0,
            "elements": [
                "enderio:block_alloy_endergy@5"
            ]
        },
        {
            "x": 6,
            "y": 13,
            "z": -1,
            "elements": [
                "appliedenergistics2:chiseled_quartz_stairs@2"
            ]
        },
        {
            "x": -6,
            "y": 18,
            "z": 0,
            "elements": [
                "appliedenergistics2:chiseled_quartz_slab@8"
            ]
        },
        {
            "x": -5,
            "y": 18,
            "z": 0,
            "elements": [
                "appliedenergistics2:chiseled_quartz_slab@8"
            ]
        },
        {
            "x": -4,
            "y": 18,
            "z": 0,
            "elements": [
                "appliedenergistics2:chiseled_quartz_slab@8"
            ]
        },
        {
            "x": 3,
            "y": 13,
            "z": -1,
            "elements": [
                "botania:storage@0"
            ]
        },
        {
            "x": -3,
            "y": 18,
            "z": 0,
            "elements": [
                "minecraft:glass@0"
            ]
        },
        {
            "x": -2,
            "y": 18,
            "z": 0,
            "elements": [
                "modularmachinery:blockcasing@5"
            ]
        },
        {
            "x": 0,
            "y": 13,
            "z": -1,
            "elements": [
                "avaritia:block_resource@0"
            ]
        },
        {
            "x": -3,
            "y": 13,
            "z": -1,
            "elements": [
                "botania:storage@0"
            ]
        },
        {
            "x": 2,
            "y": 18,
            "z": 0,
            "elements": [
                "modularmachinery:blockcasing@5"
            ]
        },
        {
            "x": 3,
            "y": 18,
            "z": 0,
            "elements": [
                "minecraft:glass@0"
            ]
        },
        {
            "x": 4,
            "y": 18,
            "z": 0,
            "elements": [
                "appliedenergistics2:chiseled_quartz_slab@8"
            ]
        },
        {
            "x": -6,
            "y": 13,
            "z": -1,
            "elements": [
                "appliedenergistics2:chiseled_quartz_stairs@2"
            ]
        },
        {
            "x": 5,
            "y": 18,
            "z": 0,
            "elements": [
                "appliedenergistics2:chiseled_quartz_slab@8"
            ]
        },
        {
            "x": 6,
            "y": 18,
            "z": 0,
            "elements": [
                "appliedenergistics2:chiseled_quartz_slab@8"
            ]
        },
        {
            "x": 7,
            "y": 18,
            "z": 0,
            "elements": [
                "enderio:block_alloy_endergy@5"
            ]
        },
        {
            "x": 8,
            "y": 18,
            "z": 0,
            "elements": [
                "appliedenergistics2:chiseled_quartz_stairs@1"
            ]
        },
        {
            "x": 9,
            "y": 18,
            "z": 0,
            "elements": [
                "appliedenergistics2:chiseled_quartz_slab@0"
            ]
        },
        {
            "x": -8,
            "y": 19,
            "z": 0,
            "elements": [
                "minecraft:sea_lantern@0"
            ]
        },
        {
            "x": -7,
            "y": 19,
            "z": 0,
            "elements": [
                "modularmachinery:blockcasing@5"
            ]
        },
        {
            "x": 6,
            "y": 12,
            "z": -1,
            "elements": [
                "minecraft:diamond_block@0"
            ]
        },
        {
            "x": -6,
            "y": 19,
            "z": 0,
            "elements": [
                "modularmachinery:blockcasing@5"
            ]
        },
        {
            "x": -5,
            "y": 19,
            "z": 0,
            "elements": [
                "modularmachinery:blockcasing@5"
            ]
        },
        {
            "x": -4,
            "y": 19,
            "z": 0,
            "elements": [
                "modularmachinery:blockcasing@5"
            ]
        },
        {
            "x": 3,
            "y": 12,
            "z": -1,
            "elements": [
                "minecraft:glass@0"
            ]
        },
        {
            "x": -3,
            "y": 19,
            "z": 0,
            "elements": [
                "modularmachinery:blockcasing@5"
            ]
        },
        {
            "x": -2,
            "y": 19,
            "z": 0,
            "elements": [
                "modularmachinery:blockcasing@5"
            ]
        },
        {
            "x": -3,
            "y": 12,
            "z": -1,
            "elements": [
                "minecraft:glass@0"
            ]
        },
        {
            "x": 2,
            "y": 19,
            "z": 0,
            "elements": [
                "modularmachinery:blockcasing@5"
            ]
        },
        {
            "x": 3,
            "y": 19,
            "z": 0,
            "elements": [
                "modularmachinery:blockcasing@5"
            ]
        },
        {
            "x": 4,
            "y": 19,
            "z": 0,
            "elements": [
                "modularmachinery:blockcasing@5"
            ]
        },
        {
            "x": -6,
            "y": 12,
            "z": -1,
            "elements": [
                "minecraft:diamond_block@0"
            ]
        },
        {
            "x": 5,
            "y": 19,
            "z": 0,
            "elements": [
                "modularmachinery:blockcasing@5"
            ]
        },
        {
            "x": 6,
            "y": 19,
            "z": 0,
            "elements": [
                "modularmachinery:blockcasing@5"
            ]
        },
        {
            "x": 7,
            "y": 19,
            "z": 0,
            "elements": [
                "modularmachinery:blockcasing@5"
            ]
        },
        {
            "x": 8,
            "y": 19,
            "z": 0,
            "elements": [
                "minecraft:sea_lantern@0"
            ]
        },
        {
            "x": -9,
            "y": 20,
            "z": 0,
            "elements": [
                "appliedenergistics2:chiseled_quartz_slab@8"
            ]
        },
        {
            "x": -8,
            "y": 20,
            "z": 0,
            "elements": [
                "appliedenergistics2:chiseled_quartz_stairs@4"
            ]
        },
        {
            "x": -7,
            "y": 20,
            "z": 0,
            "elements": [
                "enderio:block_alloy_endergy@5"
            ]
        },
        {
            "x": 6,
            "y": 11,
            "z": -1,
            "elements": [
                "appliedenergistics2:chiseled_quartz_stairs@6"
            ]
        },
        {
            "x": 4,
            "y": 7,
            "z": -3,
            "elements": [
                "appliedenergistics2:chiseled_quartz_stairs@3"
            ]
        },
        {
            "x": -6,
            "y": 20,
            "z": 0,
            "elements": [
                "appliedenergistics2:chiseled_quartz_slab@0"
            ]
        },
        {
            "x": 3,
            "y": 7,
            "z": -3,
            "elements": [
                "appliedenergistics2:quartz_slab@0"
            ]
        },
        {
            "x": -5,
            "y": 20,
            "z": 0,
            "elements": [
                "appliedenergistics2:chiseled_quartz_slab@0"
            ]
        },
        {
            "x": 2,
            "y": 7,
            "z": -3,
            "elements": [
                "minecraft:stone_slab@0"
            ]
        },
        {
            "x": -4,
            "y": 20,
            "z": 0,
            "elements": [
                "appliedenergistics2:chiseled_quartz_slab@0"
            ]
        },
        {
            "x": 3,
            "y": 11,
            "z": -1,
            "elements": [
                "botania:storage@0"
            ]
        },
        {
            "x": 1,
            "y": 7,
            "z": -3,
            "elements": [
                "modularmachinery:blockcasing@0"
            ]
        },
        {
            "x": -3,
            "y": 20,
            "z": 0,
            "elements": [
                "appliedenergistics2:chiseled_quartz_slab@0"
            ]
        },
        {
            "x": 0,
            "y": 7,
            "z": -3,
            "elements": [
                "modularmachinery:blockcasing@0"
            ]
        },
        {
            "x": -1,
            "y": 7,
            "z": -3,
            "elements": [
                "modularmachinery:blockcasing@0"
            ]
        },
        {
            "x": -2,
            "y": 20,
            "z": 0,
            "elements": [
                "appliedenergistics2:chiseled_quartz_stairs@0"
            ]
        },
        {
            "x": -1,
            "y": 20,
            "z": 0,
            "elements": [
                "minecraft:gold_block@0"
            ]
        },
        {
            "x": 0,
            "y": 11,
            "z": -1,
            "elements": [
                "avaritia:block_resource@0"
            ]
        },
        {
            "x": -2,
            "y": 7,
            "z": -3,
            "elements": [
                "minecraft:stone_slab@0"
            ]
        },
        {
            "x": -3,
            "y": 7,
            "z": -3,
            "elements": [
                "appliedenergistics2:quartz_slab@0"
            ]
        },
        {
            "x": 0,
            "y": 20,
            "z": 0,
            "elements": [
                "minecraft:gold_block@0"
            ]
        },
        {
            "x": -4,
            "y": 7,
            "z": -3,
            "elements": [
                "appliedenergistics2:chiseled_quartz_stairs@3"
            ]
        },
        {
            "x": 1,
            "y": 20,
            "z": 0,
            "elements": [
                "minecraft:gold_block@0"
            ]
        },
        {
            "x": -3,
            "y": 11,
            "z": -1,
            "elements": [
                "botania:storage@0"
            ]
        },
        {
            "x": 2,
            "y": 20,
            "z": 0,
            "elements": [
                "appliedenergistics2:chiseled_quartz_stairs@1"
            ]
        },
        {
            "x": 3,
            "y": 20,
            "z": 0,
            "elements": [
                "appliedenergistics2:chiseled_quartz_slab@0"
            ]
        },
        {
            "x": 4,
            "y": 20,
            "z": 0,
            "elements": [
                "appliedenergistics2:chiseled_quartz_slab@0"
            ]
        },
        {
            "x": -6,
            "y": 11,
            "z": -1,
            "elements": [
                "appliedenergistics2:chiseled_quartz_stairs@6"
            ]
        },
        {
            "x": 5,
            "y": 20,
            "z": 0,
            "elements": [
                "appliedenergistics2:chiseled_quartz_slab@0"
            ]
        },
        {
            "x": 6,
            "y": 20,
            "z": 0,
            "elements": [
                "appliedenergistics2:chiseled_quartz_slab@0"
            ]
        },
        {
            "x": 7,
            "y": 20,
            "z": 0,
            "elements": [
                "enderio:block_alloy_endergy@5"
            ]
        },
        {
            "x": 8,
            "y": 20,
            "z": 0,
            "elements": [
                "appliedenergistics2:chiseled_quartz_stairs@5"
            ]
        },
        {
            "x": 9,
            "y": 20,
            "z": 0,
            "elements": [
                "appliedenergistics2:chiseled_quartz_slab@8"
            ]
        },
        {
            "x": -9,
            "y": 21,
            "z": 0,
            "elements": [
                "casings_energy"
            ]
        },
        {
            "x": 0,
            "y": 6,
            "z": 9,
            "elements": [
                "appliedenergistics2:chiseled_quartz_stairs@7"
            ]
        },
        {
            "x": -8,
            "y": 21,
            "z": 0,
            "elements": [
                "draconicevolution:draconic_block@0"
            ]
        },
        {
            "x": 5,
            "y": 6,
            "z": -3,
            "elements": [
                "enderio:block_alloy_endergy@2"
            ]
        },
        {
            "x": -7,
            "y": 21,
            "z": 0,
            "elements": [
                "appliedenergistics2:chiseled_quartz_stairs@1"
            ]
        },
        {
            "x": 4,
            "y": 6,
            "z": -3,
            "elements": [
                "enderio:block_alloy@6"
            ]
        },
        {
            "x": 3,
            "y": 6,
            "z": -3,
            "elements": [
                "enderio:block_alloy@0"
            ]
        },
        {
            "x": 2,
            "y": 6,
            "z": -3,
            "elements": [
                "enderio:block_alloy@0"
            ]
        },
        {
            "x": 3,
            "y": 10,
            "z": -1,
            "elements": [
                "botania:storage@4"
            ]
        },
        {
            "x": 2,
            "y": 10,
            "z": -1,
            "elements": [
                "avaritia:block_resource@2"
            ]
        },
        {
            "x": 1,
            "y": 10,
            "z": -1,
            "elements": [
                "avaritia:block_resource@0"
            ]
        },
        {
            "x": -1,
            "y": 21,
            "z": 0,
            "elements": [
                "thermalfoundation:storage_alloy@6"
            ]
        },
        {
            "x": -2,
            "y": 6,
            "z": -3,
            "elements": [
                "enderio:block_alloy@0"
            ]
        },
        {
            "x": -3,
            "y": 6,
            "z": -3,
            "elements": [
                "enderio:block_alloy@0"
            ]
        },
        {
            "x": -1,
            "y": 10,
            "z": -1,
            "elements": [
                "avaritia:block_resource@0"
            ]
        },
        {
            "x": 0,
            "y": 21,
            "z": 0,
            "elements": [
                "minecraft:beacon@0"
            ]
        },
        {
            "x": -4,
            "y": 6,
            "z": -3,
            "elements": [
                "enderio:block_alloy@6"
            ]
        },
        {
            "x": -2,
            "y": 10,
            "z": -1,
            "elements": [
                "avaritia:block_resource@2"
            ]
        },
        {
            "x": 1,
            "y": 21,
            "z": 0,
            "elements": [
                "thermalfoundation:storage_alloy@6"
            ]
        },
        {
            "x": -5,
            "y": 6,
            "z": -3,
            "elements": [
                "enderio:block_alloy_endergy@2"
            ]
        },
        {
            "x": -3,
            "y": 10,
            "z": -1,
            "elements": [
                "botania:storage@4"
            ]
        },
        {
            "x": 7,
            "y": 21,
            "z": 0,
            "elements": [
                "appliedenergistics2:chiseled_quartz_stairs@0"
            ]
        },
        {
            "x": 8,
            "y": 21,
            "z": 0,
            "elements": [
                "draconicevolution:draconic_block@0"
            ]
        },
        {
            "x": 9,
            "y": 21,
            "z": 0,
            "elements": [
                "casings_energy"
            ]
        },
        {
            "x": -5,
            "y": -1,
            "z": 5,
            "elements": [
                "appliedenergistics2:chiseled_quartz_stairs@3"
            ]
        },
        {
            "x": -9,
            "y": 22,
            "z": 0,
            "elements": [
                "appliedenergistics2:chiseled_quartz_slab@0"
            ]
        },
        {
            "x": 0,
            "y": 7,
            "z": 9,
            "elements": [
                "enderio:block_alloy_endergy@5"
            ]
        },
        {
            "x": -8,
            "y": 22,
            "z": 0,
            "elements": [
                "appliedenergistics2:chiseled_quartz_slab@0"
            ]
        },
        {
            "x": -4,
            "y": -1,
            "z": 5,
            "elements": [
                "appliedenergistics2:chiseled_quartz_stairs@3"
            ]
        },
        {
            "x": -3,
            "y": -1,
            "z": 5,
            "elements": [
                "appliedenergistics2:chiseled_quartz_stairs@1"
            ]
        },
        {
            "x": 2,
            "y": 5,
            "z": -3,
            "elements": [
                "enderio:block_alloy@0"
            ]
        },
        {
            "x": 2,
            "y": 9,
            "z": -1,
            "elements": [
                "botania:storage@4"
            ]
        },
        {
            "x": 1,
            "y": 9,
            "z": -1,
            "elements": [
                "botania:storage@4"
            ]
        },
        {
            "x": -1,
            "y": 22,
            "z": 0,
            "elements": [
                "appliedenergistics2:chiseled_quartz_stairs@0"
            ]
        },
        {
            "x": 0,
            "y": 9,
            "z": -1,
            "elements": [
                "botania:storage@4"
            ]
        },
        {
            "x": 3,
            "y": -1,
            "z": 5,
            "elements": [
                "appliedenergistics2:chiseled_quartz_stairs@0"
            ]
        },
        {
            "x": -2,
            "y": 5,
            "z": -3,
            "elements": [
                "enderio:block_alloy@0"
            ]
        },
        {
            "x": -1,
            "y": 9,
            "z": -1,
            "elements": [
                "botania:storage@4"
            ]
        },
        {
            "x": 0,
            "y": 22,
            "z": 0,
            "elements": [
                "minecraft:stained_glass@4"
            ]
        },
        {
            "x": 4,
            "y": -1,
            "z": 5,
            "elements": [
                "appliedenergistics2:chiseled_quartz_stairs@3"
            ]
        },
        {
            "x": 5,
            "y": -1,
            "z": 5,
            "elements": [
                "appliedenergistics2:chiseled_quartz_stairs@3"
            ]
        },
        {
            "x": -2,
            "y": 9,
            "z": -1,
            "elements": [
                "botania:storage@4"
            ]
        },
        {
            "x": 1,
            "y": 22,
            "z": 0,
            "elements": [
                "appliedenergistics2:chiseled_quartz_stairs@1"
            ]
        },
        {
            "x": 8,
            "y": 22,
            "z": 0,
            "elements": [
                "appliedenergistics2:chiseled_quartz_slab@0"
            ]
        },
        {
            "x": 9,
            "y": 22,
            "z": 0,
            "elements": [
                "appliedenergistics2:chiseled_quartz_slab@0"
            ]
        },
        {
            "x": 0,
            "y": 8,
            "z": 9,
            "elements": [
                "enderio:block_alloy_endergy@5"
            ]
        },
        {
            "x": 2,
            "y": 4,
            "z": -3,
            "elements": [
                "enderio:block_alloy@0"
            ]
        },
        {
            "x": 0,
            "y": 8,
            "z": -1,
            "elements": [
                "botania:bifrostperm@0"
            ]
        },
        {
            "x": -2,
            "y": 4,
            "z": -3,
            "elements": [
                "enderio:block_alloy@0"
            ]
        },
        {
            "x": 5,
            "y": -1,
            "z": -5,
            "elements": [
                "appliedenergistics2:chiseled_quartz_stairs@1"
            ]
        },
        {
            "x": 4,
            "y": -1,
            "z": -5,
            "elements": [
                "appliedenergistics2:chiseled_quartz_stairs@2"
            ]
        },
        {
            "x": 0,
            "y": 9,
            "z": 9,
            "elements": [
                "modularmachinery:blockfluidinputhatch"
            ]
        },
        {
            "x": 3,
            "y": -1,
            "z": -5,
            "elements": [
                "appliedenergistics2:chiseled_quartz_stairs@0"
            ]
        },
        {
            "x": 4,
            "y": 7,
            "z": -1,
            "elements": [
                "minecraft:stone_slab@0"
            ]
        },
        {
            "x": 3,
            "y": 7,
            "z": -1,
            "elements": [
                "modularmachinery:blockcasing@0"
            ]
        },
        {
            "x": -3,
            "y": -1,
            "z": -5,
            "elements": [
                "appliedenergistics2:chiseled_quartz_stairs@1"
            ]
        },
        {
            "x": 0,
            "y": 7,
            "z": -1,
            "elements": [
                "botania:bifrostperm@0"
            ]
        },
        {
            "x": -4,
            "y": -1,
            "z": -5,
            "elements": [
                "appliedenergistics2:chiseled_quartz_stairs@2"
            ]
        },
        {
            "x": -5,
            "y": -1,
            "z": -5,
            "elements": [
                "appliedenergistics2:chiseled_quartz_stairs@2"
            ]
        },
        {
            "x": -3,
            "y": 7,
            "z": -1,
            "elements": [
                "modularmachinery:blockcasing@0"
            ]
        },
        {
            "x": -4,
            "y": 7,
            "z": -1,
            "elements": [
                "minecraft:stone_slab@0"
            ]
        },
        {
            "x": 0,
            "y": 10,
            "z": 9,
            "elements": [
                "enderio:block_alloy_endergy@5"
            ]
        },
        {
            "x": 6,
            "y": 6,
            "z": -1,
            "elements": [
                "enderio:block_alloy@8"
            ]
        },
        {
            "x": 0,
            "y": 6,
            "z": 7,
            "elements": [
                "thermalfoundation:storage_alloy@6"
            ]
        },
        {
            "x": 5,
            "y": 6,
            "z": -1,
            "elements": [
                "enderio:block_alloy_endergy@2"
            ]
        },
        {
            "x": 4,
            "y": 6,
            "z": -1,
            "elements": [
                "enderio:block_alloy@6"
            ]
        },
        {
            "x": 0,
            "y": 6,
            "z": -1,
            "elements": [
                "botania:bifrostperm@0"
            ]
        },
        {
            "x": -4,
            "y": 6,
            "z": -1,
            "elements": [
                "enderio:block_alloy@6"
            ]
        },
        {
            "x": -5,
            "y": 6,
            "z": -1,
            "elements": [
                "enderio:block_alloy_endergy@2"
            ]
        },
        {
            "x": -6,
            "y": 6,
            "z": -1,
            "elements": [
                "enderio:block_alloy@8"
            ]
        },
        {
            "x": 0,
            "y": 11,
            "z": 9,
            "elements": [
                "enderio:block_alloy_endergy@5"
            ]
        },
        {
            "x": -5,
            "y": -1,
            "z": 3,
            "elements": [
                "appliedenergistics2:chiseled_quartz_stairs@2"
            ]
        },
        {
            "x": -4,
            "y": -1,
            "z": 3,
            "elements": [
                "appliedenergistics2:chiseled_quartz_stairs@0"
            ]
        },
        {
            "x": -3,
            "y": -1,
            "z": 3,
            "elements": [
                "appliedenergistics2:chiseled_quartz_slab@0"
            ]
        },
        {
            "x": -2,
            "y": -1,
            "z": 3,
            "elements": [
                "enderio:block_alloy@0"
            ]
        },
        {
            "x": -1,
            "y": -1,
            "z": 3,
            "elements": [
                "appliedenergistics2:chiseled_quartz_slab@0"
            ]
        },
        {
            "x": 0,
            "y": -1,
            "z": 3,
            "elements": [
                "modularmachinery:blockcasing@5"
            ]
        },
        {
            "x": 0,
            "y": 5,
            "z": -1,
            "elements": [
                "botania:bifrostperm@0"
            ]
        },
        {
            "x": 1,
            "y": -1,
            "z": 3,
            "elements": [
                "appliedenergistics2:chiseled_quartz_slab@0"
            ]
        },
        {
            "x": 2,
            "y": -1,
            "z": 3,
            "elements": [
                "enderio:block_alloy@0"
            ]
        },
        {
            "x": 3,
            "y": -1,
            "z": 3,
            "elements": [
                "appliedenergistics2:chiseled_quartz_slab@0"
            ]
        },
        {
            "x": 4,
            "y": -1,
            "z": 3,
            "elements": [
                "appliedenergistics2:chiseled_quartz_stairs@1"
            ]
        },
        {
            "x": 5,
            "y": -1,
            "z": 3,
            "elements": [
                "appliedenergistics2:chiseled_quartz_stairs@2"
            ]
        },
        {
            "x": 0,
            "y": 12,
            "z": 9,
            "elements": [
                "appliedenergistics2:chiseled_quartz_stairs@3"
            ]
        },
        {
            "x": 0,
            "y": 4,
            "z": -1,
            "elements": [
                "botania:bifrostperm@0"
            ]
        },
        {
            "x": 5,
            "y": -1,
            "z": -3,
            "elements": [
                "appliedenergistics2:chiseled_quartz_stairs@1"
            ]
        },
        {
            "x": 0,
            "y": 22,
            "z": -8,
            "elements": [
                "appliedenergistics2:chiseled_quartz_slab@0"
            ]
        },
        {
            "x": 4,
            "y": -1,
            "z": -3,
            "elements": [
                "appliedenergistics2:chiseled_quartz_stairs@3"
            ]
        },
        {
            "x": 3,
            "y": -1,
            "z": -3,
            "elements": [
                "appliedenergistics2:chiseled_quartz_slab@0"
            ]
        },
        {
            "x": 2,
            "y": -1,
            "z": -3,
            "elements": [
                "enderio:block_alloy@0"
            ]
        },
        {
            "x": 1,
            "y": -1,
            "z": -3,
            "elements": [
                "appliedenergistics2:chiseled_quartz_slab@0"
            ]
        },
        {
            "x": 0,
            "y": -1,
            "z": -3,
            "elements": [
                "modularmachinery:blockcasing@5"
            ]
        },
        {
            "x": -1,
            "y": -1,
            "z": -3,
            "elements": [
                "appliedenergistics2:chiseled_quartz_slab@0"
            ]
        },
        {
            "x": 0,
            "y": 3,
            "z": -1,
            "elements": [
                "botania:bifrostperm@0"
            ]
        },
        {
            "x": -2,
            "y": -1,
            "z": -3,
            "elements": [
                "enderio:block_alloy@0"
            ]
        },
        {
            "x": -3,
            "y": -1,
            "z": -3,
            "elements": [
                "appliedenergistics2:chiseled_quartz_slab@0"
            ]
        },
        {
            "x": -4,
            "y": -1,
            "z": -3,
            "elements": [
                "appliedenergistics2:chiseled_quartz_stairs@3"
            ]
        },
        {
            "x": -5,
            "y": -1,
            "z": -3,
            "elements": [
                "appliedenergistics2:chiseled_quartz_stairs@0"
            ]
        },
        {
            "x": -3,
            "y": 6,
            "z": 5,
            "elements": [
                "enderio:block_alloy_endergy@2"
            ]
        },
        {
            "x": 0,
            "y": 21,
            "z": -8,
            "elements": [
                "draconicevolution:draconic_block@0"
            ]
        },
        {
            "x": -2,
            "y": 6,
            "z": 5,
            "elements": [
                "enderio:block_alloy_endergy@2"
            ]
        },
        {
            "x": -1,
            "y": 6,
            "z": 5,
            "elements": [
                "enderio:block_alloy_endergy@2"
            ]
        },
        {
            "x": 0,
            "y": 6,
            "z": 5,
            "elements": [
                "enderio:block_alloy_endergy@2"
            ]
        },
        {
            "x": 1,
            "y": 6,
            "z": 5,
            "elements": [
                "enderio:block_alloy_endergy@2"
            ]
        },
        {
            "x": 2,
            "y": 2,
            "z": -1,
            "elements": [
                "appliedenergistics2:chiseled_quartz_slab@8"
            ]
        },
        {
            "x": 2,
            "y": 6,
            "z": 5,
            "elements": [
                "enderio:block_alloy_endergy@2"
            ]
        },
        {
            "x": 1,
            "y": 2,
            "z": -1,
            "elements": [
                "appliedenergistics2:chiseled_quartz_stairs@5"
            ]
        },
        {
            "x": 0,
            "y": 2,
            "z": -1,
            "elements": [
                "modularmachinery:blockcasing@5"
            ]
        },
        {
            "x": 3,
            "y": 6,
            "z": 5,
            "elements": [
                "enderio:block_alloy_endergy@2"
            ]
        },
        {
            "x": -1,
            "y": 2,
            "z": -1,
            "elements": [
                "appliedenergistics2:chiseled_quartz_stairs@6"
            ]
        },
        {
            "x": -2,
            "y": 2,
            "z": -1,
            "elements": [
                "appliedenergistics2:chiseled_quartz_slab@8"
            ]
        },
        {
            "x": -5,
            "y": 7,
            "z": 5,
            "elements": [
                "appliedenergistics2:quartz_slab@8"
            ]
        },
        {
            "x": -4,
            "y": 7,
            "z": 5,
            "elements": [
                "appliedenergistics2:chiseled_quartz_stairs@7"
            ]
        },
        {
            "x": 0,
            "y": 20,
            "z": -8,
            "elements": [
                "appliedenergistics2:chiseled_quartz_stairs@6"
            ]
        },
        {
            "x": -4,
            "y": -1,
            "z": 1,
            "elements": [
                "appliedenergistics2:chiseled_quartz_stairs@0"
            ]
        },
        {
            "x": -3,
            "y": -1,
            "z": 1,
            "elements": [
                "appliedenergistics2:chiseled_quartz_slab@0"
            ]
        },
        {
            "x": -2,
            "y": -1,
            "z": 1,
            "elements": [
                "enderio:block_alloy@0"
            ]
        },
        {
            "x": 0,
            "y": 1,
            "z": -1,
            "elements": [
                "appliedenergistics2:chiseled_quartz_stairs@6"
            ]
        },
        {
            "x": -1,
            "y": -1,
            "z": 1,
            "elements": [
                "appliedenergistics2:chiseled_quartz_slab@0"
            ]
        },
        {
            "x": 0,
            "y": -1,
            "z": 1,
            "elements": [
                "modularmachinery:blockcasing@5"
            ]
        },
        {
            "x": 4,
            "y": 7,
            "z": 5,
            "elements": [
                "appliedenergistics2:chiseled_quartz_stairs@7"
            ]
        },
        {
            "x": 5,
            "y": 7,
            "z": 5,
            "elements": [
                "appliedenergistics2:quartz_slab@8"
            ]
        },
        {
            "x": 1,
            "y": -1,
            "z": 1,
            "elements": [
                "appliedenergistics2:chiseled_quartz_slab@0"
            ]
        },
        {
            "x": 2,
            "y": -1,
            "z": 1,
            "elements": [
                "enderio:block_alloy@0"
            ]
        },
        {
            "x": 3,
            "y": -1,
            "z": 1,
            "elements": [
                "appliedenergistics2:chiseled_quartz_slab@0"
            ]
        },
        {
            "x": 4,
            "y": -1,
            "z": 1,
            "elements": [
                "appliedenergistics2:chiseled_quartz_stairs@1"
            ]
        },
        {
            "x": -5,
            "y": 8,
            "z": 5,
            "elements": [
                "botania:bifrostperm@0"
            ]
        },
        {
            "x": 0,
            "y": 16,
            "z": 9,
            "elements": [
                "appliedenergistics2:chiseled_quartz_slab@8"
            ]
        },
        {
            "x": -4,
            "y": 8,
            "z": 5,
            "elements": [
                "appliedenergistics2:chiseled_quartz_block@0"
            ]
        },
        {
            "x": 0,
            "y": 19,
            "z": -8,
            "elements": [
                "minecraft:sea_lantern@0"
            ]
        },
        {
            "x": 0,
            "y": 12,
            "z": 7,
            "elements": [
                "modularmachinery:blockcasing@5"
            ]
        },
        {
            "x": -2,
            "y": 4,
            "z": 3,
            "elements": [
                "enderio:block_alloy@0"
            ]
        },
        {
            "x": 4,
            "y": 8,
            "z": 5,
            "elements": [
                "appliedenergistics2:chiseled_quartz_block@0"
            ]
        },
        {
            "x": 2,
            "y": 4,
            "z": 3,
            "elements": [
                "enderio:block_alloy@0"
            ]
        },
        {
            "x": 5,
            "y": 8,
            "z": 5,
            "elements": [
                "botania:bifrostperm@0"
            ]
        },
        {
            "x": -5,
            "y": 9,
            "z": 5,
            "elements": [
                "botania:bifrostperm@0"
            ]
        },
        {
            "x": 0,
            "y": 17,
            "z": 9,
            "elements": [
                "casings_energy"
            ]
        },
        {
            "x": -4,
            "y": 9,
            "z": 5,
            "elements": [
                "appliedenergistics2:chiseled_quartz_stairs@1"
            ]
        },
        {
            "x": 0,
            "y": 18,
            "z": -8,
            "elements": [
                "appliedenergistics2:chiseled_quartz_stairs@2"
            ]
        },
        {
            "x": 4,
            "y": -1,
            "z": -1,
            "elements": [
                "appliedenergistics2:chiseled_quartz_stairs@1"
            ]
        },
        {
            "x": 3,
            "y": -1,
            "z": -1,
            "elements": [
                "appliedenergistics2:chiseled_quartz_slab@0"
            ]
        },
        {
            "x": -2,
            "y": 5,
            "z": 3,
            "elements": [
                "enderio:block_alloy@0"
            ]
        },
        {
            "x": 2,
            "y": -1,
            "z": -1,
            "elements": [
                "enderio:block_alloy@0"
            ]
        },
        {
            "x": 1,
            "y": -1,
            "z": -1,
            "elements": [
                "appliedenergistics2:chiseled_quartz_slab@0"
            ]
        },
        {
            "x": 0,
            "y": -1,
            "z": -1,
            "elements": [
                "modularmachinery:blockcasing@5"
            ]
        },
        {
            "x": 4,
            "y": 9,
            "z": 5,
            "elements": [
                "appliedenergistics2:chiseled_quartz_stairs@0"
            ]
        },
        {
            "x": 2,
            "y": 5,
            "z": 3,
            "elements": [
                "enderio:block_alloy@0"
            ]
        },
        {
            "x": 0,
            "y": 1,
            "z": 1,
            "elements": [
                "appliedenergistics2:chiseled_quartz_stairs@7"
            ]
        },
        {
            "x": -1,
            "y": -1,
            "z": -1,
            "elements": [
                "appliedenergistics2:chiseled_quartz_slab@0"
            ]
        },
        {
            "x": 5,
            "y": 9,
            "z": 5,
            "elements": [
                "botania:bifrostperm@0"
            ]
        },
        {
            "x": -2,
            "y": -1,
            "z": -1,
            "elements": [
                "enderio:block_alloy@0"
            ]
        },
        {
            "x": -3,
            "y": -1,
            "z": -1,
            "elements": [
                "appliedenergistics2:chiseled_quartz_slab@0"
            ]
        },
        {
            "x": -4,
            "y": -1,
            "z": -1,
            "elements": [
